Workbook

Sheet 2026_Fantasy_Hitters
A1: Name | B1: Team | C1: Position | D1: AB | E1: PA | F1: H | G1: 1B | H1: 2B | I1: 3B | J1: HR | K1: R | L1: RBI | M1: BB | N1: IBB | O1: SO | P1: HBP | Q1: SF | R1: SH | S1: SB | T1: CS | U1: NSB | V1: AVG | W1: OBP | X1: SLG | Y1: OPS | Z1: BABIP | AA1: K% | AB1: BB% | AD1: HIP | AE1: HR% | AF1: 1B% | AG1: 2B% | AH1: 3B% | AI1: R% | AJ1: RBI% | AK1: IBB% | AL1: HBP% | AM1: SF% | AN1: SH% | AO1: SB% | AP1: CS% | AQ1: NSB%
A2: Aaron Judge | B2: NYY | C2: OF | D2: 512 | E2: 637 | F2: =J2+AD2 -> 148.48627 | G2: =$AD2*AF2 -> 72.679745 | H2: =$AD2*AG2 -> 25.691119 | I2: =$AD2*AH2 -> 0.97219781 | J2: =$E2*AE2 -> 49.770753 | K2: =$E2*AI2 -> 105.16509 | L2: =$E2*AJ2 -> 112 | M2: =$E2*AB2 -> 110.0099 | N2: =$E2*AK2 -> 21.508592 | O2: =$E2*AA2 -> 158.2308 | P2: =$E2*AL2 -> 6.0084898 | Q2: =$E2*AM2 -> 4.0062905 | R2: =$E2*AN2 -> 0.89999819 | S2: =$E2*AO2 -> 9.470107 | T2: =$E2*AP2 -> 2.7531586 | U2: =S2-T2 -> 6.7169484 | V2: =F2/D2 -> 0.29001225 | W2: =(F2+M2+N2+P2)/(D2+M2+N2+Q2) -> 0.4417024 | X2: =(G2+H2*2+I2*3+J2*4)/D2 -> 0.63683904 | Y2: =W2+X2 -> 1.0785414 | Z2: 0.3205 | AA2: 0.2484 | AB2: 0.1727 | AD2: =(D2-J2-O2+Q2)*Z2 -> 98.715518 | AE2: 0.07813305 | AF2: 0.7362545 | AG2: 0.2602541 | AH2: 0.00984848 | AI2: 0.16509434 | AJ2: 0.17582418 | AK2: 0.03376545 | AL2: 0.00943248 | AM2: 0.00628931 | AN2: 0.00141287 | AO2: 0.01486673 | AP2: 0.00432207 | AQ2: 0.01054466
A3: Shohei Ohtani | B3: LAD | C3: Util | D3: 559 | E3: 659 | F3: =J3+AD3 -> 158.44482 | G3: =$AD3*AF3 -> 77.438557 | H3: =$AD3*AG3 -> 30.034507 | I3: =$AD3*AH3 -> 5.4178334 | J3: =$E3*AE3 -> 47.093445 | K3: =$E3*AI3 -> 121.55335 | L3: =$E3*AJ3 -> 109 | M3: =$E3*AB3 -> 90.6784 | N3: =$E3*AK3 -> 14.605457 | O3: =$E3*AA3 -> 158.45655 | P3: =$E3*AL3 -> 5.0205783 | Q3: =$E3*AM3 -> 4.018292 | R3: =$E3*AN3 -> 0.90000289 | S3: =$E3*AO3 -> 24.065909 | T3: =$E3*AP3 -> 6.7522788 | U3: =S3-T3 -> 17.31363 | V3: =F3/D3 -> 0.28344333 | W3: =(F3+M3+N3+P3)/(D3+M3+N3+Q3) -> 0.40213735 | X3: =(G3+H3*2+I3*3+J3*4)/D3 -> 0.61204804 | Y3: =W3+X3 -> 1.0141854 | Z3: 0.3115 | AA3: 0.24045 | AB3: 0.1376 | AD3: =(D3-J3-O3+Q3)*Z3 -> 111.35137 | AE3: 0.07146198 | AF3: 0.69544321 | AG3: 0.26972732 | AH3: 0.04865529 | AI3: 0.18445122 | AJ3: 0.16540212 | AK3: 0.02216306 | AL3: 0.00761848 | AM3: 0.00609756 | AN3: 0.00136571 | AO3: 0.03651883 | AP3: 0.01024625 | AQ3: 0.026272574
A4: Bobby Witt Jr. | B4: KC | C4: SS | D4: 598 | E4: 660 | F4: =J4+AD4 -> 174.39368 | G4: =$AD4*AF4 -> 102.20537 | H4: =$AD4*AG4 -> 35.439209 | I4: =$AD4*AH4 -> 5.7236924 | J4: =$E4*AE4 -> 30.870121 | K4: =$E4*AI4 -> 104.63415 | L4: =$E4*AJ4 -> 92 | M4: =$E4*AB4 -> 48.18 | N4: =$E4*AK4 -> 5.7286548 | O4: =$E4*AA4 -> 112.86 | P4: =$E4*AL4 -> 6.1329246 | Q4: =$E4*AM4 -> 6.0365844 | R4: =$E4*AN4 -> 0.9000024 | S4: =$E4*AO4 -> 34.005154 | T4: =$E4*AP4 -> 9.3525237 | U4: =S4-T4 -> 24.65263 | V4: =F4/D4 -> 0.29162822 | W4: =(F4+M4+N4+P4)/(D4+M4+N4+Q4) -> 0.35631424 | X4: =(G4+H4*2+I4*3+J4*4)/D4 -> 0.52464104 | Y4: =W4+X4 -> 0.88095528 | Z4: 0.3118 | AA4: 0.171 | AB4: 0.073 | AD4: =(D4-J4-O4+Q4)*Z4 -> 143.52356 | AE4: 0.04677291 | AF4: 0.71211562 | AG4: 0.2469226 | AH4: 0.039879812 | AI4: 0.15853659 | AJ4: 0.13939394 | AK4: 0.00867978 | AL4: 0.00929231 | AM4: 0.00914634 | AN4: 0.00136364 | AO4: 0.05152296 | AP4: 0.01417049 | AQ4: 0.03735247
A5: Juan Soto | B5: NYM | C5: OF | D5: 542 | E5: 675 | F5: =J5+AD5 -> 147.19717 | G5: =$AD5*AF5 -> 82.257492 | H5: =$AD5*AG5 -> 25.715702 | I5: =$AD5*AH5 -> 1.0166264 | J5: =$E5*AE5 -> 38.101634 | K5: =$E5*AI5 -> 107.31798 | L5: =$E5*AJ5 -> 99 | M5: =$E5*AB5 -> 121.8375 | N5: =$E5*AK5 -> 8.8957757 | O5: =$E5*AA5 -> 120.015 | P5: =$E5*AL5 -> 4.0107015 | Q5: =$E5*AM5 -> 4.0118895 | R5: =$E5*AN5 -> 0.99839925 | S5: =$E5*AO5 -> 21.16181 | T5: =$E5*AP5 -> 5.3804318 | U5: =S5-T5 -> 15.781379 | V5: =F5/D5 -> 0.2715815 | W5: =(F5+M5+N5+P5)/(D5+M5+N5+Q5) -> 0.41661347 | X5: =(G5+H5*2+I5*3+J5*4)/D5 -> 0.53347844 | Y5: =W5+X5 -> 0.95009191 | Z5: 0.28125 | AA5: 0.1778 | AB5: 0.1805 | AD5: =(D5-J5-O5+Q5)*Z5 -> 109.09554 | AE5: 0.056446866 | AF5: 0.753995 | AG5: 0.23571726 | AH5: 0.00931868 | AI5: 0.1589896 | AJ5: 0.14666667 | AK5: 0.013178927 | AL5: 0.00594178 | AM5: 0.00594354 | AN5: 0.00147911 | AO5: 0.03135083 | AP5: 0.00797101 | AQ5: 0.023379812
A6: Jose Ramirez | B6: CLE | C6: 3B | D6: 575 | E6: 649 | F6: =J6+AD6 -> 155.28164 | G6: =$AD6*AF6 -> 94.374098 | H6: =$AD6*AG6 -> 31.648065 | I6: =$AD6*AH6 -> 2.7801085 | J6: =$E6*AE6 -> 26.41835 | K6: =$E6*AI6 -> 90.839813 | L6: =$E6*AJ6 -> 89 | M6: =$E6*AB6 -> 62.6934 | N6: =$E6*AK6 -> 17.608259 | O6: =$E6*AA6 -> 75.4138 | P6: =$E6*AL6 -> 4.0335934 | Q6: =$E6*AM6 -> 6.0559877 | R6: =$E6*AN6 -> 0 | S6: =$E6*AO6 -> 33.830267 | T6: =$E6*AP6 -> 7.8803808 | U6: =S6-T6 -> 25.949886 | V6: =F6/D6 -> 0.27005503 | W6: =(F6+M6+N6+P6)/(D6+M6+N6+Q6) -> 0.36231061 | X6: =(G6+H6*2+I6*3+J6*4)/D6 -> 0.47249383 | Y6: =W6+X6 -> 0.83480444 | Z6: 0.2689 | AA6: 0.1162 | AB6: 0.0966 | AD6: =(D6-J6-O6+Q6)*Z6 -> 128.86329 | AE6: 0.04070624 | AF6: 0.73235828 | AG6: 0.24559411 | AH6: 0.021574092 | AI6: 0.1399689 | AJ6: 0.13713405 | AK6: 0.02713137 | AL6: 0.00621509 | AM6: 0.00933126 | AN6: 0 | AO6: 0.05212676 | AP6: 0.012142343 | AQ6: 0.03998441
A7: Elly De La Cruz | B7: CIN | C7: SS | D7: 568 | E7: 636 | F7: =J7+AD7 -> 147.99414 | G7: =$AD7*AF7 -> 92.320983 | H7: =$AD7*AG7 -> 30.774897 | I7: =$AD7*AH7 -> 5.1324971 | J7: =$E7*AE7 -> 21.310331 | K7: =$E7*AI7 -> 91.00159 | L7: =$E7*AJ7 -> 77 | M7: =$E7*AB7 -> 58.194 | N7: =$E7*AK7 -> 5.5172746 | O7: =$E7*AA7 -> 166.0278 | P7: =$E7*AL7 -> 3.0300503 | Q7: =$E7*AM7 -> 4.0445148 | R7: =$E7*AN7 -> 0.9946404 | S7: =$E7*AO7 -> 39.700894 | T7: =$E7*AP7 -> 10.334684 | U7: =S7-T7 -> 29.36621 | V7: =F7/D7 -> 0.26055307 | W7: =(F7+M7+N7+P7)/(D7+M7+N7+Q7) -> 0.33776408 | X7: =(G7+H7*2+I7*3+J7*4)/D7 -> 0.44808027 | Y7: =W7+X7 -> 0.78584435 | Z7: 0.3293 | AA7: 0.26105 | AB7: 0.0915 | AD7: =(D7-J7-O7+Q7)*Z7 -> 126.68381 | AE7: 0.03350681 | AF7: 0.72875122 | AG7: 0.24292683 | AH7: 0.04051423 | AI7: 0.14308426 | AJ7: 0.12106918 | AK7: 0.00867496 | AL7: 0.00476423 | AM7: 0.0063593 | AN7: 0.0015639 | AO7: 0.06242279 | AP7: 0.016249503 | AQ7: 0.04617328
A8: Ronald Acuna Jr. | B8: ATL | C8: OF | D8: 533 | E8: 629 | F8: =J8+AD8 -> 150.43351 | G8: =$AD8*AF8 -> 93.634355 | H8: =$AD8*AG8 -> 24.765241 | I8: =$AD8*AH8 -> 1.9731801 | J8: =$E8*AE8 -> 29.151364 | K8: =$E8*AI8 -> 101.97271 | L8: =$E8*AJ8 -> 78 | M8: =$E8*AB8 -> 83.3425 | N8: =$E8*AK8 -> 3.7529537 | O8: =$E8*AA8 -> 129.8256 | P8: =$E8*AL8 -> 7.9693419 | Q8: =$E8*AM8 -> 4.0385259 | R8: =$E8*AN8 -> 0.89999836 | S8: =$E8*AO8 -> 24.788789 | T8: =$E8*AP8 -> 6.6457101 | U8: =S8-T8 -> 18.143079 | V8: =F8/D8 -> 0.28223924 | W8: =(F8+M8+N8+P8)/(D8+M8+N8+Q8) -> 0.39334232 | X8: =(G8+H8*2+I8*3+J8*4)/D8 -> 0.49847998 | Y8: =W8+X8 -> 0.8918223 | Z8: 0.3208 | AA8: 0.2064 | AB8: 0.1325 | AD8: =(D8-J8-O8+Q8)*Z8 -> 121.28215 | AE8: 0.04634557 | AF8: 0.7720374 | AG8: 0.20419527 | AH8: 0.016269337 | AI8: 0.16211878 | AJ8: 0.12400636 | AK8: 0.00596654 | AL8: 0.01266986 | AM8: 0.00642055 | AN8: 0.00143084 | AO8: 0.03940984 | AP8: 0.010565517 | AQ8: 0.028844319
A9: Julio Rodriguez | B9: SEA | C9: OF | D9: 599 | E9: 659 | F9: =J9+AD9 -> 163.72049 | G9: =$AD9*AF9 -> 104.06217 | H9: =$AD9*AG9 -> 26.835561 | I9: =$AD9*AH9 -> 2.9853303 | J9: =$E9*AE9 -> 28.292662 | K9: =$E9*AI9 -> 95.7263 | L9: =$E9*AJ9 -> 91 | M9: =$E9*AB9 -> 47.448 | N9: =$E9*AK9 -> 4.6069899 | O9: =$E9*AA9 -> 145.01295 | P9: =$E9*AL9 -> 9.0619288 | Q9: =$E9*AM9 -> 4.0305824 | R9: =$E9*AN9 -> 0 | S9: =$E9*AO9 -> 27.964652 | T9: =$E9*AP9 -> 6.8495142 | U9: =S9-T9 -> 21.115138 | V9: =F9/D9 -> 0.27332302 | W9: =(F9+M9+N9+P9)/(D9+M9+N9+Q9) -> 0.34321837 | X9: =(G9+H9*2+I9*3+J9*4)/D9 -> 0.46721191 | Y9: =W9+X9 -> 0.81043028 | Z9: 0.31515 | AA9: 0.22005 | AB9: 0.072 | AD9: =(D9-J9-O9+Q9)*Z9 -> 135.42782 | AE9: 0.04293272 | AF9: 0.7683958 | AG9: 0.19815397 | AH9: 0.0220437 | AI9: 0.14525994 | AJ9: 0.13808801 | AK9: 0.00699088 | AL9: 0.01375103 | AM9: 0.00611621 | AN9: 0 | AO9: 0.04243498 | AP9: 0.0103938 | AQ9: 0.032041177
A10: Kyle Tucker | B10: LAD | C10: OF | D10: 528 | E10: 620 | F10: =J10+AD10 -> 141.54999 | G10: =$AD10*AF10 -> 82.185199 | H10: =$AD10*AG10 -> 28.088262 | I10: =$AD10*AH10 -> 2.0720206 | J10: =$E10*AE10 -> 28.446251 | K10: =$E10*AI10 -> 95.928339 | L10: =$E10*AJ10 -> 88 | M10: =$E10*AB10 -> 81.716 | N10: =$E10*AK10 -> 5.7945076 | O10: =$E10*AA10 -> 90.985 | P10: =$E10*AL10 -> 3.9351772 | Q10: =$E10*AM10 -> 5.0488584 | R10: =$E10*AN10 -> 0.9952364 | S10: =$E10*AO10 -> 22.964286 | T10: =$E10*AP10 -> 4.853205 | U10: =S10-T10 -> 18.111081 | V10: =F10/D10 -> 0.26808709 | W10: =(F10+M10+N10+P10)/(D10+M10+N10+Q10) -> 0.37546073 | X10: =(G10+H10*2+I10*3+J10*4)/D10 -> 0.48932346 | Y10: =W10+X10 -> 0.86478419 | Z10: 0.27345 | AA10: 0.14675 | AB10: 0.1318 | AD10: =(D10-J10-O10+Q10)*Z10 -> 113.10373 | AE10: 0.04588105 | AF10: 0.72663559 | AG10: 0.24834071 | AH10: 0.018319648 | AI10: 0.15472313 | AJ10: 0.14193548 | AK10: 0.00934598 | AL10: 0.00634706 | AM10: 0.00814332 | AN10: 0.00160522 | AO10: 0.037039171 | AP10: 0.00782775 | AQ10: 0.029211424
A11: Cal Raleigh | B11: SEA | C11: C | D11: 540 | E11: 626 | F11: =J11+AD11 -> 122.62811 | G11: =$AD11*AF11 -> 60.102107 | H11: =$AD11*AG11 -> 22.494845 | I11: =$AD11*AH11 -> 0 | J11: =$E11*AE11 -> 39.212502 | K11: =$E11*AI11 -> 82.262821 | L11: =$E11*AJ11 -> 102 | M11: =$E11*AB11 -> 74.8696 | N11: =$E11*AK11 -> 9.8152168 | O11: =$E11*AA11 -> 168.9887 | P11: =$E11*AL11 -> 6.0173061 | Q11: =$E11*AM11 -> 4.0128228 | R11: =$E11*AN11 -> 0.9000002 | S11: =$E11*AO11 -> 8.211146 | T11: =$E11*AP11 -> 2.2634157 | U11: =S11-T11 -> 5.9477303 | V11: =F11/D11 -> 0.22708909 | W11: =(F11+M11+N11+P11)/(D11+M11+N11+Q11) -> 0.33932087 | X11: =(G11+H11*2+I11*3+J11*4)/D11 -> 0.48507742 | Y11: =W11+X11 -> 0.82439829 | Z11: 0.2484 | AA11: 0.26995 | AB11: 0.1196 | AD11: =(D11-J11-O11+Q11)*Z11 -> 83.415607 | AE11: 0.06263978 | AF11: 0.72051394 | AG11: 0.26967189 | AH11: 0 | AI11: 0.13141026 | AJ11: 0.1629393 | AK11: 0.01567926 | AL11: 0.00961231 | AM11: 0.00641026 | AN11: 0.0014377 | AO11: 0.013116847 | AP11: 0.00361568 | AQ11: 0.00950117
A12: Corbin Carroll | B12: AZ | C12: OF | D12: 525 | E12: 604 | F12: =J12+AD12 -> 136.23298 | G12: =$AD12*AF12 -> 73.97221 | H12: =$AD12*AG12 -> 28.292155 | I12: =$AD12*AH12 -> 9.8881412 | J12: =$E12*AE12 -> 25.769836 | K12: =$E12*AI12 -> 96.045902 | L12: =$E12*AJ12 -> 77 | M12: =$E12*AB12 -> 62.9972 | N12: =$E12*AK12 -> 2.8790143 | O12: =$E12*AA12 -> 126.0548 | P12: =$E12*AL12 -> 7.9291791 | Q12: =$E12*AM12 -> 3.9606575 | R12: =$E12*AN12 -> 1.9896364 | S12: =$E12*AO12 -> 32.296703 | T12: =$E12*AP12 -> 7.2401178 | U12: =S12-T12 -> 25.056585 | V12: =F12/D12 -> 0.25949138 | W12: =(F12+M12+N12+P12)/(D12+M12+N12+Q12) -> 0.35310247 | X12: =(G12+H12*2+I12*3+J12*4)/D12 -> 0.50152436 | Y12: =W12+X12 -> 0.85462683 | Z12: 0.2929 | AA12: 0.2087 | AB12: 0.1043 | AD12: =(D12-J12-O12+Q12)*Z12 -> 110.46314 | AE12: 0.042665291 | AF12: 0.66965514 | AG12: 0.25612303 | AH12: 0.0895153 | AI12: 0.15901639 | AJ12: 0.12748344 | AK12: 0.00476658 | AL12: 0.01312778 | AM12: 0.00655738 | AN12: 0.0032941 | AO12: 0.053471363 | AP12: 0.01198695 | AQ12: 0.041484417
A13: Junior Caminero | B13: TB | C13: 3B | D13: 579 | E13: 631 | F13: =J13+AD13 -> 156.40467 | G13: =$AD13*AF13 -> 92.608172 | H13: =$AD13*AG13 -> 27.320608 | I13: =$AD13*AH13 -> 1.0556017 | J13: =$E13*AE13 -> 36.258787 | K13: =$E13*AI13 -> 81.646965 | L13: =$E13*AJ13 -> 103 | M13: =$E13*AB13 -> 41.5829 | N13: =$E13*AK13 -> 1.2140503 | O13: =$E13*AA13 -> 121.2782 | P13: =$E13*AL13 -> 4.9359407 | Q13: =$E13*AM13 -> 5.0399358 | R13: =$E13*AN13 -> 0 | S13: =$E13*AO13 -> 5.6860924 | T13: =$E13*AP13 -> 2.1044039 | U13: =S13-T13 -> 3.5816885 | V13: =F13/D13 -> 0.27012896 | W13: =(F13+M13+N13+P13)/(D13+M13+N13+Q13) -> 0.32566296 | X13: =(G13+H13*2+I13*3+J13*4)/D13 -> 0.51027865 | Y13: =W13+X13 -> 0.83594162 | Z13: 0.2817 | AA13: 0.1922 | AB13: 0.0659 | AD13: =(D13-J13-O13+Q13)*Z13 -> 120.14588 | AE13: 0.05746242 | AF13: 0.77079773 | AG13: 0.22739529 | AH13: 0.008786 | AI13: 0.12939297 | AJ13: 0.16323296 | AK13: 0.00192401 | AL13: 0.00782241 | AM13: 0.00798722 | AN13: 0 | AO13: 0.00901124 | AP13: 0.00333503 | AQ13: 0.0056762
... A220: Jordan Walker | B220: STL | C220: OF | D220: 462 | E220: 508 | F220: =J220+AD220 -> 110.7157 | G220: =$AD220*AF220 -> 68.282623 | H220: =$AD220*AG220 -> 23.511239 | I220: =$AD220*AH220 -> 1.0272218 | J220: =$E220*AE220 -> 16.944802 | K220: =$E220*AI220 -> 58.928 | L220: =$E220*AJ220 -> 55.000002 | M220: =$E220*AB220 -> 36.0172 | N220: =$E220*AK220 -> 0.95322136 | O220: =$E220*AA220 -> 134.6454 | P220: =$E220*AL220 -> 5.071999 | Q220: =$E220*AM220 -> 3.048 | R220: =$E220*AN220 -> 0 | S220: =$E220*AO220 -> 9.0760073 | T220: =$E220*AP220 -> 3.1100471 | U220: =S220-T220 -> 5.9659602 | V220: =F220/D220 -> 0.23964438 | W220: =(F220+M220+N220+P220)/(D220+M220+N220+Q220) -> 0.30428788 | X220: =(G220+H220*2+I220*3+J220*4)/D220 -> 0.40295666 | Y220: =W220+X220 -> 0.70724454 | Z220: 0.29915 | AA220: 0.26505 | AB220: 0.0709 | AD220: =(D220-J220-O220+Q220)*Z220 -> 93.7709 | AE220: 0.03335591 | AF220: 0.72818564 | AG220: 0.25073065 | AH220: 0.01095459 | AI220: 0.116 | AJ220: 0.10826772 | AK220: 0.00187642 | AL220: 0.00998425 | AM220: 0.006 | AN220: 0 | AO220: 0.017866156 | AP220: 0.00612214 | AQ220: 0.01174402

Sheet CKBT_Rank
A1: Name | B1: Team | C1: Position | D1: AB | E1: PA | F1: Total | G1: R+ | H1: H+ | I1: HR+ | J1: RBI+ | K1: BB+ | L1: HBP+ | M1: AVG+ | N1: OPS+ | O1: NSB+ | P1: HR%+ | R1: R | S1: H | T1: HR | U1: RBI | V1: BB | W1: HBP | X1: AVG | Y1: OPS | Z1: NSB | AA1: HR% | AC1: ='2026_Fantasy_Hitters'!F1 -> H | AD1: ='2026_Fantasy_Hitters'!G1 -> 1B | AE1: ='2026_Fantasy_Hitters'!H1 -> 2B | AF1: ='2026_Fantasy_Hitters'!I1 -> 3B | AG1: ='2026_Fantasy_Hitters'!J1 -> HR | AH1: ='2026_Fantasy_Hitters'!K1 -> R | AI1: ='2026_Fantasy_Hitters'!L1 -> RBI | AJ1: ='2026_Fantasy_Hitters'!M1 -> BB | ... AY1: ='2026_Fantasy_Hitters'!AB1 -> BB% | AZ1: HR%
A2: Aaron Judge | B2: NYY | C2: OF | D2: 512 | E2: 637 | F2: =G2+H2+I2+J2+K2+L2+M2+N2+O2+P2 -> 23.966243 | G2: =(R2-R$221)/R$222 -> 2.4063399 | H2: =(S2-S$221)/S$222 -> 1.1215523 | I2: =(T2-T$221)/T$222 -> 3.7140844 | J2: =(U2-U$221)/U$222 -> 2.7428494 | K2: =(V2-V$221)/V$222 -> 3.708899 | L2: =(W2-W$221)/W$222 -> 0.090645635 | M2: =(X2-X$221)/X$222 -> 2.3357655 | N2: =(Y2-Y$221)/Y$222 -> 4.5449506 | ... P2: =(AA2-AA$221)/AA$222 -> 3.471661 | R2: =(AH2-AVERAGE(AH$2:AH$220))/AVERAGE(AH$2:AH$220)*100+100 -> 156.88804 | S2: =(AC2-AVERAGE(AC$2:AC$220))/AVERAGE(AC$2:AC$220)*100+100 -> 122.83737 | T2: =(AG2-AVERAGE(AG$2:AG$220))/AVERAGE(AG$2:AG$220)*100+100 -> 264.29562 | U2: =(AI2-AVERAGE(AI$2:AI$220))/AVERAGE(AI$2:AI$220)*100+100 -> 170.57099 | V2: =(AJ2-AVERAGE(AJ$2:AJ$220))/AVERAGE(AJ$2:AJ$220)*100+100 -> 234.22922 | W2: =(AM2-AVERAGE(AM$2:AM$220))/AVERAGE(AM$2:AM$220)*100+100 -> 104.40723 | X2: =(AS2-AVERAGE(AS$2:AS$220))/AVERAGE(AS$2:AS$220)*100+100 -> 115.41569 | Y2: =(AU2-AVERAGE(AU$2:AU$220))/AVERAGE(AU$2:AU$220)*100+100 -> 149.97092 | Z2: =(AR2-AVERAGE(AR$2:AR$220))/AVERAGE(AR$2:AR$220)*100+100 -> 84.322251 | AA2: =(AZ2-AVERAGE(AZ$2:AZ$220))/AVERAGE(AZ$2:AZ$220)*100+100 -> 226.08903 | AC2: ='2026_Fantasy_Hitters'!F2 -> 148.48627 | AD2: ='2026_Fantasy_Hitters'!G2 -> 72.679745 | AE2: ='2026_Fantasy_Hitters'!H2 -> 25.691119 | AF2: ='2026_Fantasy_Hitters'!I2 -> 0.97219781 | AG2: ='2026_Fantasy_Hitters'!J2 -> 49.770753 | AH2: ='2026_Fantasy_Hitters'!K2 -> 105.16509 | AI2: ='2026_Fantasy_Hitters'!L2 -> 112 | AJ2: ='2026_Fantasy_Hitters'!M2 -> 110.0099 | ... AY2: ='2026_Fantasy_Hitters'!AB2 -> 0.1727 | AZ2: =AG2/$E2 -> 0.07813305
A3: Shohei Ohtani | B3: LAD | C3: Util | D3: 559 | E3: 659 | F3: =G3+H3+I3+J3+K3+L3+M3+N3+O3+P3 -> 23.40381 | G3: =(R3-R$221)/R$222 -> 3.4404982 | H3: =(S3-S$221)/S$222 -> 1.526141 | I3: =(T3-T$221)/T$222 -> 3.3926888 | J3: =(U3-U$221)/U$222 -> 2.5652733 | K3: =(V3-V$221)/V$222 -> 2.5716049 | L3: =(W3-W$221)/W$222 -> -0.26242722 | M3: =(X3-X$221)/X$222 -> 1.9396618 | N3: =(Y3-Y$221)/Y$222 -> 4.0139644 | ... P3: =(AA3-AA$221)/AA$222 -> 2.9401648 | R3: =(AH3-AVERAGE(AH$2:AH$220))/AVERAGE(AH$2:AH$220)*100+100 -> 181.33648 | S3: =(AC3-AVERAGE(AC$2:AC$220))/AVERAGE(AC$2:AC$220)*100+100 -> 131.07572 | T3: =(AG3-AVERAGE(AG$2:AG$220))/AVERAGE(AG$2:AG$220)*100+100 -> 250.07842 | U3: =(AI3-AVERAGE(AI$2:AI$220))/AVERAGE(AI$2:AI$220)*100+100 -> 166.00212 | V3: =(AJ3-AVERAGE(AJ$2:AJ$220))/AVERAGE(AJ$2:AJ$220)*100+100 -> 193.06927 | W3: =(AM3-AVERAGE(AM$2:AM$220))/AVERAGE(AM$2:AM$220)*100+100 -> 87.240671 | X3: =(AS3-AVERAGE(AS$2:AS$220))/AVERAGE(AS$2:AS$220)*100+100 -> 112.80147 | Y3: =(AU3-AVERAGE(AU$2:AU$220))/AVERAGE(AU$2:AU$220)*100+100 -> 144.13282 | Z3: =(AR3-AVERAGE(AR$2:AR$220))/AVERAGE(AR$2:AR$220)*100+100 -> 217.34934 | AA3: =(AZ3-AVERAGE(AZ$2:AZ$220))/AVERAGE(AZ$2:AZ$220)*100+100 -> 206.78535 | AC3: ='2026_Fantasy_Hitters'!F3 -> 158.44482 | AD3: ='2026_Fantasy_Hitters'!G3 -> 77.438557 | AE3: ='2026_Fantasy_Hitters'!H3 -> 30.034507 | AF3: ='2026_Fantasy_Hitters'!I3 -> 5.4178334 | AG3: ='2026_Fantasy_Hitters'!J3 -> 47.093445 | AH3: ='2026_Fantasy_Hitters'!K3 -> 121.55335 | AI3: ='2026_Fantasy_Hitters'!L3 -> 109 | AJ3: ='2026_Fantasy_Hitters'!M3 -> 90.6784 | ... AY3: ='2026_Fantasy_Hitters'!AB3 -> 0.1376 | AZ3: =AG3/$E3 -> 0.07146198
A4: Juan Soto | B4: NYM | C4: OF | D4: 542 | E4: 675 | F4: =G4+H4+I4+J4+K4+L4+M4+N4+O4+P4 -> 18.045828 | G4: =(R4-R$221)/R$222 -> 2.5421947 | H4: =(S4-S$221)/S$222 -> 1.0691799 | I4: =(T4-T$221)/T$222 -> 2.3132733 | J4: =(U4-U$221)/U$222 -> 1.9733536 | K4: =(V4-V$221)/V$222 -> 4.4047302 | L4: =(W4-W$221)/W$222 -> -0.62335036 | M4: =(X4-X$221)/X$222 -> 1.224398 | N4: =(Y4-Y$221)/Y$222 -> 2.3311208 | ... P4: =(AA4-AA$221)/AA$222 -> 1.7438833 | R4: =(AH4-AVERAGE(AH$2:AH$220))/AVERAGE(AH$2:AH$220)*100+100 -> 160.09977 | S4: =(AC4-AVERAGE(AC$2:AC$220))/AVERAGE(AC$2:AC$220)*100+100 -> 121.77095 | T4: =(AG4-AVERAGE(AG$2:AG$220))/AVERAGE(AG$2:AG$220)*100+100 -> 202.32957 | U4: =(AI4-AVERAGE(AI$2:AI$220))/AVERAGE(AI$2:AI$220)*100+100 -> 150.77257 | V4: =(AJ4-AVERAGE(AJ$2:AJ$220))/AVERAGE(AJ$2:AJ$220)*100+100 -> 259.41213 | W4: =(AM4-AVERAGE(AM$2:AM$220))/AVERAGE(AM$2:AM$220)*100+100 -> 69.692428 | X4: =(AS4-AVERAGE(AS$2:AS$220))/AVERAGE(AS$2:AS$220)*100+100 -> 108.08084 | Y4: =(AU4-AVERAGE(AU$2:AU$220))/AVERAGE(AU$2:AU$220)*100+100 -> 125.63025 | Z4: =(AR4-AVERAGE(AR$2:AR$220))/AVERAGE(AR$2:AR$220)*100+100 -> 198.11398 | AA4: =(AZ4-AVERAGE(AZ$2:AZ$220))/AVERAGE(AZ$2:AZ$220)*100+100 -> 163.33699 | AC4: ='2026_Fantasy_Hitters'!F5 -> 147.19717 | AD4: ='2026_Fantasy_Hitters'!G5 -> 82.257492 | AE4: ='2026_Fantasy_Hitters'!H5 -> 25.715702 | AF4: ='2026_Fantasy_Hitters'!I5 -> 1.0166264 | AG4: ='2026_Fantasy_Hitters'!J5 -> 38.101634 | AH4: ='2026_Fantasy_Hitters'!K5 -> 107.31798 | AI4: ='2026_Fantasy_Hitters'!L5 -> 99 | AJ4: ='2026_Fantasy_Hitters'!M5 -> 121.8375 | ... AY4: ='2026_Fantasy_Hitters'!AB5 -> 0.1805 | AZ4: =AG4/$E4 -> 0.056446866
A5: Bobby Witt Jr. | B5: KC | C5: SS | D5: 598 | E5: 660 | F5: =G5+H5+I5+J5+K5+L5+M5+N5+O5+P5 -> 15.584015 | G5: =(R5-R$221)/R$222 -> 2.3728351 | H5: =(S5-S$221)/S$222 -> 2.1740996 | I5: =(T5-T$221)/T$222 -> 1.4451712 | J5: =(U5-U$221)/U$222 -> 1.5590097 | K5: =(V5-V$221)/V$222 -> 0.071375656 | L5: =(W5-W$221)/W$222 -> 0.1351178 | M5: =(X5-X$221)/X$222 -> 2.433208 | N5: =(Y5-Y$221)/Y$222 -> 2.1418369 | ... P5: =(AA5-AA$221)/AA$222 -> 0.97314169 | R5: =(AH5-AVERAGE(AH$2:AH$220))/AVERAGE(AH$2:AH$220)*100+100 -> 156.09596 | S5: =(AC5-AVERAGE(AC$2:AC$220))/AVERAGE(AC$2:AC$220)*100+100 -> 144.26964 | T5: =(AG5-AVERAGE(AG$2:AG$220))/AVERAGE(AG$2:AG$220)*100+100 -> 163.92835 | U5: =(AI5-AVERAGE(AI$2:AI$220))/AVERAGE(AI$2:AI$220)*100+100 -> 140.11188 | V5: =(AJ5-AVERAGE(AJ$2:AJ$220))/AVERAGE(AJ$2:AJ$220)*100+100 -> 102.58317 | W5: =(AM5-AVERAGE(AM$2:AM$220))/AVERAGE(AM$2:AM$220)*100+100 -> 106.56949 | X5: =(AS5-AVERAGE(AS$2:AS$220))/AVERAGE(AS$2:AS$220)*100+100 -> 116.05879 | Y5: =(AU5-AVERAGE(AU$2:AU$220))/AVERAGE(AU$2:AU$220)*100+100 -> 123.54911 | Z5: =(AR5-AVERAGE(AR$2:AR$220))/AVERAGE(AR$2:AR$220)*100+100 -> 309.4806 | AA5: =(AZ5-AVERAGE(AZ$2:AZ$220))/AVERAGE(AZ$2:AZ$220)*100+100 -> 135.34403 | AC5: ='2026_Fantasy_Hitters'!F4 -> 174.39368 | AD5: ='2026_Fantasy_Hitters'!G4 -> 102.20537 | AE5: ='2026_Fantasy_Hitters'!H4 -> 35.439209 | AF5: ='2026_Fantasy_Hitters'!I4 -> 5.7236924 | AG5: ='2026_Fantasy_Hitters'!J4 -> 30.870121 | AH5: ='2026_Fantasy_Hitters'!K4 -> 104.63415 | AI5: ='2026_Fantasy_Hitters'!L4 -> 92 | AJ5: ='2026_Fantasy_Hitters'!M4 -> 48.18 | ... AY5: ='2026_Fantasy_Hitters'!AB4 -> 0.073 | AZ5: =AG5/$E5 -> 0.04677291
A6: Vladimir Guerrero Jr. | B6: TOR | C6: 1B | D6: 577 | E6: 663 | F6: =G6+H6+I6+J6+K6+L6+M6+N6+O6+P6 -> 14.409273 | G6: =(R6-R$221)/R$222 -> 1.8910929 | H6: =(S6-S$221)/S$222 -> 2.0691576 | I6: =(T6-T$221)/T$222 -> 1.5447934 | J6: =(U6-U$221)/U$222 -> 1.7365855 | K6: =(V6-V$221)/V$222 -> 1.5352473 | L6: =(W6-W$221)/W$222 -> 0.4092654 | M6: =(X6-X$221)/X$222 -> 2.8032777 | N6: =(Y6-Y$221)/Y$222 -> 2.0152999 | ... P6: =(AA6-AA$221)/AA$222 -> 1.0560052 | R6: =(AH6-AVERAGE(AH$2:AH$220))/AVERAGE(AH$2:AH$220)*100+100 -> 144.70714 | S6: =(AC6-AVERAGE(AC$2:AC$220))/AVERAGE(AC$2:AC$220)*100+100 -> 142.13278 | T6: =(AG6-AVERAGE(AG$2:AG$220))/AVERAGE(AG$2:AG$220)*100+100 -> 168.33522 | U6: =(AI6-AVERAGE(AI$2:AI$220))/AVERAGE(AI$2:AI$220)*100+100 -> 144.68074 | V6: =(AJ6-AVERAGE(AJ$2:AJ$220))/AVERAGE(AJ$2:AJ$220)*100+100 -> 155.56232 | W6: =(AM6-AVERAGE(AM$2:AM$220))/AVERAGE(AM$2:AM$220)*100+100 -> 119.89867 | X6: =(AS6-AVERAGE(AS$2:AS$220))/AVERAGE(AS$2:AS$220)*100+100 -> 118.5012 | Y6: =(AU6-AVERAGE(AU$2:AU$220))/AVERAGE(AU$2:AU$220)*100+100 -> 122.15786 | Z6: =(AR6-AVERAGE(AR$2:AR$220))/AVERAGE(AR$2:AR$220)*100+100 -> 40.099484 | AA6: =(AZ6-AVERAGE(AZ$2:AZ$220))/AVERAGE(AZ$2:AZ$220)*100+100 -> 138.35359 | AC6: ='2026_Fantasy_Hitters'!F16 -> 171.81063 | AD6: ='2026_Fantasy_Hitters'!G16 -> 109.15712 | AE6: ='2026_Fantasy_Hitters'!H16 -> 31.052889 | AF6: ='2026_Fantasy_Hitters'!I16 -> 0.41539021 | AG6: ='2026_Fantasy_Hitters'!J16 -> 31.699999 | AH6: ='2026_Fantasy_Hitters'!K16 -> 97 | AI6: ='2026_Fantasy_Hitters'!L16 -> 94.999997 | AJ6: ='2026_Fantasy_Hitters'!M16 -> 73.0626 | ... AY6: ='2026_Fantasy_Hitters'!AB16 -> 0.1102 | AZ6: =AG6/$E6 -> 0.04781297
A7: Ronald Acuna Jr. | B7: ATL | C7: OF | D7: 533 | E7: 629 | F7: =G7+H7+I7+J7+K7+L7+M7+N7+O7+P7 -> 14.083324 | G7: =(R7-R$221)/R$222 -> 2.204889 | H7: =(S7-S$221)/S$222 -> 1.2006634 | I7: =(T7-T$221)/T$222 -> 1.2388442 | J7: =(U7-U$221)/U$222 -> 0.7303219 | K7: =(V7-V$221)/V$222 -> 2.1400255 | L7: =(W7-W$221)/W$222 -> 0.79144092 | M7: =(X7-X$221)/X$222 -> 1.8670555 | N7: =(Y7-Y$221)/Y$222 -> 1.581506 | ... P7: =(AA7-AA$221)/AA$222 -> 0.93909474 | R7: =(AH7-AVERAGE(AH$2:AH$220))/AVERAGE(AH$2:AH$220)*100+100 -> 152.12556 | S7: =(AC7-AVERAGE(AC$2:AC$220))/AVERAGE(AC$2:AC$220)*100+100 -> 124.44825 | T7: =(AG7-AVERAGE(AG$2:AG$220))/AVERAGE(AG$2:AG$220)*100+100 -> 154.80131 | U7: =(AI7-AVERAGE(AI$2:AI$220))/AVERAGE(AI$2:AI$220)*100+100 -> 118.79051 | V7: =(AJ7-AVERAGE(AJ$2:AJ$220))/AVERAGE(AJ$2:AJ$220)*100+100 -> 177.44993 | W7: =(AM7-AVERAGE(AM$2:AM$220))/AVERAGE(AM$2:AM$220)*100+100 -> 138.48021 | X7: =(AS7-AVERAGE(AS$2:AS$220))/AVERAGE(AS$2:AS$220)*100+100 -> 112.32228 | Y7: =(AU7-AVERAGE(AU$2:AU$220))/AVERAGE(AU$2:AU$220)*100+100 -> 117.38837 | Z7: =(AR7-AVERAGE(AR$2:AR$220))/AVERAGE(AR$2:AR$220)*100+100 -> 227.76195 | AA7: =(AZ7-AVERAGE(AZ$2:AZ$220))/AVERAGE(AZ$2:AZ$220)*100+100 -> 134.10746 | AC7: ='2026_Fantasy_Hitters'!F8 -> 150.43351 | AD7: ='2026_Fantasy_Hitters'!G8 -> 93.634355 | AE7: ='2026_Fantasy_Hitters'!H8 -> 24.765241 | AF7: ='2026_Fantasy_Hitters'!I8 -> 1.9731801 | AG7: ='2026_Fantasy_Hitters'!J8 -> 29.151364 | AH7: ='2026_Fantasy_Hitters'!K8 -> 101.97271 | AI7: ='2026_Fantasy_Hitters'!L8 -> 78 | AJ7: ='2026_Fantasy_Hitters'!M8 -> 83.3425 | ... AY7: ='2026_Fantasy_Hitters'!AB8 -> 0.1325 | AZ7: =AG7/$E7 -> 0.04634557
A8: 3 Yordan Alvarez | B8: HOU | C8: OF | D8: 469 | E8: 553 | F8: =G8+H8+I8+J8+K8+L8+M8+N8+O8+P8 -> 13.328847 | G8: =(R8-R$221)/R$222 -> 1.0108785 | H8: =(S8-S$221)/S$222 -> 0.6519946 | I8: =(T8-T$221)/T$222 -> 1.6985426 | J8: =(U8-U$221)/U$222 -> 1.0854738 | K8: =(V8-V$221)/V$222 -> 1.3133539 | L8: =(W8-W$221)/W$222 -> 0.79964952 | M8: =(X8-X$221)/X$222 -> 2.4531286 | N8: =(Y8-Y$221)/Y$222 -> 3.0660537 | ... P8: =(AA8-AA$221)/AA$222 -> 1.9982644 | R8: =(AH8-AVERAGE(AH$2:AH$220))/AVERAGE(AH$2:AH$220)*100+100 -> 123.89808 | S8: =(AC8-AVERAGE(AC$2:AC$220))/AVERAGE(AC$2:AC$220)*100+100 -> 113.2761 | T8: =(AG8-AVERAGE(AG$2:AG$220))/AVERAGE(AG$2:AG$220)*100+100 -> 175.13645 | U8: =(AI8-AVERAGE(AI$2:AI$220))/AVERAGE(AI$2:AI$220)*100+100 -> 127.92824 | V8: =(AJ8-AVERAGE(AJ$2:AJ$220))/AVERAGE(AJ$2:AJ$220)*100+100 -> 147.53175 | W8: =(AM8-AVERAGE(AM$2:AM$220))/AVERAGE(AM$2:AM$220)*100+100 -> 138.87932 | X8: =(AS8-AVERAGE(AS$2:AS$220))/AVERAGE(AS$2:AS$220)*100+100 -> 116.19027 | Y8: =(AU8-AVERAGE(AU$2:AU$220))/AVERAGE(AU$2:AU$220)*100+100 -> 133.71071 | Z8: =(AR8-AVERAGE(AR$2:AR$220))/AVERAGE(AR$2:AR$220)*100+100 -> 31.176596 | AA8: =(AZ8-AVERAGE(AZ$2:AZ$220))/AVERAGE(AZ$2:AZ$220)*100+100 -> 172.57599 | AC8: ='2026_Fantasy_Hitters'!F27 -> 136.92857 | AD8: ='2026_Fantasy_Hitters'!G27 -> 76.517134 | AE8: ='2026_Fantasy_Hitters'!H27 -> 27.133434 | AF8: ='2026_Fantasy_Hitters'!I27 -> 1.1956991 | AG8: ='2026_Fantasy_Hitters'!J27 -> 32.980769 | AH8: ='2026_Fantasy_Hitters'!K27 -> 83.051282 | AI8: ='2026_Fantasy_Hitters'!L27 -> 84 | AJ8: ='2026_Fantasy_Hitters'!M27 -> 69.2909 | ... AY8: ='2026_Fantasy_Hitters'!AB27 -> 0.1253 | AZ8: =AG8/$E8 -> 0.059639727
A9: Pete Alonso | B9: BAL | C9: 1B | D9: 575 | E9: 655 | F9: =G9+H9+I9+J9+K9+L9+M9+N9+O9+P9 -> 12.719293 | G9: =(R9-R$221)/R$222 -> 1.3022877 | H9: =(S9-S$221)/S$222 -> 0.99273608 | I9: =(T9-T$221)/T$222 -> 2.1997735 | J9: =(U9-U$221)/U$222 -> 2.2101215 | K9: =(V9-V$221)/V$222 -> 0.86297803 | L9: =(W9-W$221)/W$222 -> 2.6215294 | M9: =(X9-X$221)/X$222 -> 0.087222391 | N9: =(Y9-Y$221)/Y$222 -> 1.5976532 | ... P9: =(AA9-AA$221)/AA$222 -> 1.7661981 | R9: =(AH9-AVERAGE(AH$2:AH$220))/AVERAGE(AH$2:AH$220)*100+100 -> 130.78726 | S9: =(AC9-AVERAGE(AC$2:AC$220))/AVERAGE(AC$2:AC$220)*100+100 -> 120.21438 | T9: =(AG9-AVERAGE(AG$2:AG$220))/AVERAGE(AG$2:AG$220)*100+100 -> 197.30881 | U9: =(AI9-AVERAGE(AI$2:AI$220))/AVERAGE(AI$2:AI$220)*100+100 -> 156.86439 | V9: =(AJ9-AVERAGE(AJ$2:AJ$220))/AVERAGE(AJ$2:AJ$220)*100+100 -> 131.23214 | W9: =(AM9-AVERAGE(AM$2:AM$220))/AVERAGE(AM$2:AM$220)*100+100 -> 227.45993 | X9: =(AS9-AVERAGE(AS$2:AS$220))/AVERAGE(AS$2:AS$220)*100+100 -> 100.57565 | Y9: =(AU9-AVERAGE(AU$2:AU$220))/AVERAGE(AU$2:AU$220)*100+100 -> 117.56591 | Z9: =(AR9-AVERAGE(AR$2:AR$220))/AVERAGE(AR$2:AR$220)*100+100 -> 15.29568 | AA9: =(AZ9-AVERAGE(AZ$2:AZ$220))/AVERAGE(AZ$2:AZ$220)*100+100 -> 164.14745 | AC9: ='2026_Fantasy_Hitters'!F19 -> 145.31559 | AD9: ='2026_Fantasy_Hitters'!G19 -> 81.292759 | AE9: ='2026_Fantasy_Hitters'!H19 -> 26.843273 | AF9: ='2026_Fantasy_Hitters'!I19 -> 1.1518537 | AG9: ='2026_Fantasy_Hitters'!J19 -> 37.156152 | AH9: ='2026_Fantasy_Hitters'!K19 -> 87.669231 | AI9: ='2026_Fantasy_Hitters'!L19 -> 103 | AJ9: ='2026_Fantasy_Hitters'!M19 -> 61.6355 | ... AY9: ='2026_Fantasy_Hitters'!AB19 -> 0.0941 | AZ9: =AG9/$E9 -> 0.05672695
A10: 1 Julio Rodriguez | B10: SEA | C10: OF | D10: 599 | E10: 659 | F10: =G10+H10+I10+J10+K10+L10+M10+N10+O10+P10 -> 12.10065 | G10: =(R10-R$221)/R$222 -> 1.8107178 | H10: =(S10-S$221)/S$222 -> 1.740477 | I10: =(T10-T$221)/T$222 -> 1.1357621 | J10: =(U10-U$221)/U$222 -> 1.4998177 | K10: =(V10-V$221)/V$222 -> 0.028311263 | L10: =(W10-W$221)/W$222 -> 1.1819241 | M10: =(X10-X$221)/X$222 -> 1.3294106 | N10: =(Y10-Y$221)/Y$222 -> 0.91179054 | ... P10: =(AA10-AA$221)/AA$222 -> 0.66718678 | R10: =(AH10-AVERAGE(AH$2:AH$220))/AVERAGE(AH$2:AH$220)*100+100 -> 142.807 | S10: =(AC10-AVERAGE(AC$2:AC$220))/AVERAGE(AC$2:AC$220)*100+100 -> 135.44009 | T10: =(AG10-AVERAGE(AG$2:AG$220))/AVERAGE(AG$2:AG$220)*100+100 -> 150.24138 | U10: =(AI10-AVERAGE(AI$2:AI$220))/AVERAGE(AI$2:AI$220)*100+100 -> 138.58893 | V10: =(AJ10-AVERAGE(AJ$2:AJ$220))/AVERAGE(AJ$2:AJ$220)*100+100 -> 101.02462 | W10: =(AM10-AVERAGE(AM$2:AM$220))/AVERAGE(AM$2:AM$220)*100+100 -> 157.46567 | X10: =(AS10-AVERAGE(AS$2:AS$220))/AVERAGE(AS$2:AS$220)*100+100 -> 108.7739 | Y10: =(AU10-AVERAGE(AU$2:AU$220))/AVERAGE(AU$2:AU$220)*100+100 -> 110.02497 | Z10: =(AR10-AVERAGE(AR$2:AR$220))/AVERAGE(AR$2:AR$220)*100+100 -> 265.07215 | AA10: =(AZ10-AVERAGE(AZ$2:AZ$220))/AVERAGE(AZ$2:AZ$220)*100+100 -> 124.2319 | AC10: ='2026_Fantasy_Hitters'!F9 -> 163.72049 | AD10: ='2026_Fantasy_Hitters'!G9 -> 104.06217 | AE10: ='2026_Fantasy_Hitters'!H9 -> 26.835561 | AF10: ='2026_Fantasy_Hitters'!I9 -> 2.9853303 | AG10: ='2026_Fantasy_Hitters'!J9 -> 28.292662 | AH10: ='2026_Fantasy_Hitters'!K9 -> 95.7263 | AI10: ='2026_Fantasy_Hitters'!L9 -> 91 | AJ10: ='2026_Fantasy_Hitters'!M9 -> 47.448 | ... AY10: ='2026_Fantasy_Hitters'!AB9 -> 0.072 | AZ10: =AG10/$E10 -> 0.04293272
A11: Kyle Schwarber | B11: PHI | C11: OF | D11: 549 | E11: 657 | F11: =G11+H11+I11+J11+K11+L11+M11+N11+O11+P11 -> 11.944103 | G11: =(R11-R$221)/R$222 -> 1.7472709 | H11: =(S11-S$221)/S$222 -> 0.18891883 | I11: =(T11-T$221)/T$222 -> 2.5983113 | J11: =(U11-U$221)/U$222 -> 2.3285055 | K11: =(V11-V$221)/V$222 -> 2.9844524 | L11: =(W11-W$221)/W$222 -> 0.46227138 | M11: =(X11-X$221)/X$222 -> -1.3641838 | N11: =(Y11-Y$221)/Y$222 -> 1.3970053 | ... P11: =(AA11-AA$221)/AA$222 -> 2.1550341 | R11: =(AH11-AVERAGE(AH$2:AH$220))/AVERAGE(AH$2:AH$220)*100+100 -> 141.30706 | S11: =(AC11-AVERAGE(AC$2:AC$220))/AVERAGE(AC$2:AC$220)*100+100 -> 103.84682 | T11: =(AG11-AVERAGE(AG$2:AG$220))/AVERAGE(AG$2:AG$220)*100+100 -> 214.93846 | U11: =(AI11-AVERAGE(AI$2:AI$220))/AVERAGE(AI$2:AI$220)*100+100 -> 159.9103 | V11: =(AJ11-AVERAGE(AJ$2:AJ$220))/AVERAGE(AJ$2:AJ$220)*100+100 -> 208.01068 | W11: =(AM11-AVERAGE(AM$2:AM$220))/AVERAGE(AM$2:AM$220)*100+100 -> 122.47584 | X11: =(AS11-AVERAGE(AS$2:AS$220))/AVERAGE(AS$2:AS$220)*100+100 -> 90.996599 | Y11: =(AU11-AVERAGE(AU$2:AU$220))/AVERAGE(AU$2:AU$220)*100+100 -> 115.35982 | Z11: =(AR11-AVERAGE(AR$2:AR$220))/AVERAGE(AR$2:AR$220)*100+100 -> 49.107688 | AA11: =(AZ11-AVERAGE(AZ$2:AZ$220))/AVERAGE(AZ$2:AZ$220)*100+100 -> 178.26978 | AC11: ='2026_Fantasy_Hitters'!F15 -> 125.53042 | AD11: ='2026_Fantasy_Hitters'!G15 -> 62.681665 | AE11: ='2026_Fantasy_Hitters'!H15 -> 20.639573 | AF11: ='2026_Fantasy_Hitters'!I15 -> 1.0237572 | AG11: ='2026_Fantasy_Hitters'!J15 -> 40.476075 | AH11: ='2026_Fantasy_Hitters'!K15 -> 94.720859 | AI11: ='2026_Fantasy_Hitters'!L15 -> 105 | AJ11: ='2026_Fantasy_Hitters'!M15 -> 97.6959 | ... AY11: ='2026_Fantasy_Hitters'!AB15 -> 0.1487 | AZ11: =AG11/$E11 -> 0.06160742
A12: 1 Fernando Tatis Jr. | B12: SD | C12: OF | D12: 565 | E12: 646 | F12: =G12+H12+I12+J12+K12+L12+M12+N12+O12+P12 -> 11.799253 | G12: =(R12-R$221)/R$222 -> 1.973402 | H12: =(S12-S$221)/S$222 -> 1.348878 | I12: =(T12-T$221)/T$222 -> 1.2184001 | J12: =(U12-U$221)/U$222 -> 0.90789785 | K12: =(V12-V$221)/V$222 -> 1.3262203 | L12: =(W12-W$221)/W$222 -> 0.093605987 | M12: =(X12-X$221)/X$222 -> 1.2925011 | N12: =(Y12-Y$221)/Y$222 -> 1.1943728 | ... P12: =(AA12-AA$221)/AA$222 -> 0.82092151 | R12: =(AH12-AVERAGE(AH$2:AH$220))/AVERAGE(AH$2:AH$220)*100+100 -> 146.653 | S12: =(AC12-AVERAGE(AC$2:AC$220))/AVERAGE(AC$2:AC$220)*100+100 -> 127.46624 | T12: =(AG12-AVERAGE(AG$2:AG$220))/AVERAGE(AG$2:AG$220)*100+100 -> 153.89694 | U12: =(AI12-AVERAGE(AI$2:AI$220))/AVERAGE(AI$2:AI$220)*100+100 -> 123.35938 | V12: =(AJ12-AVERAGE(AJ$2:AJ$220))/AVERAGE(AJ$2:AJ$220)*100+100 -> 147.9974 | W12: =(AM12-AVERAGE(AM$2:AM$220))/AVERAGE(AM$2:AM$220)*100+100 -> 104.55116 | X12: =(AS12-AVERAGE(AS$2:AS$220))/AVERAGE(AS$2:AS$220)*100+100 -> 108.53031 | Y12: =(AU12-AVERAGE(AU$2:AU$220))/AVERAGE(AU$2:AU$220)*100+100 -> 113.13191 | Z12: =(AR12-AVERAGE(AR$2:AR$220))/AVERAGE(AR$2:AR$220)*100+100 -> 249.23857 | AA12: =(AZ12-AVERAGE(AZ$2:AZ$220))/AVERAGE(AZ$2:AZ$220)*100+100 -> 129.81547 | AC12: ='2026_Fantasy_Hitters'!F17 -> 154.08167 | AD12: ='2026_Fantasy_Hitters'!G17 -> 93.825456 | AE12: ='2026_Fantasy_Hitters'!H17 -> 27.491867 | AF12: ='2026_Fantasy_Hitters'!I17 -> 2.2318524 | AG12: ='2026_Fantasy_Hitters'!J17 -> 28.981059 | AH12: ='2026_Fantasy_Hitters'!K17 -> 98.304348 | AI12: ='2026_Fantasy_Hitters'!L17 -> 81 | AJ12: ='2026_Fantasy_Hitters'!M17 -> 69.5096 | ... AY12: ='2026_Fantasy_Hitters'!AB17 -> 0.1076 | AZ12: =AG12/$E12 -> 0.04486232
A13: Brent Rooker | B13: ATH | C13: OF | D13: 569 | E13: 640 | F13: =G13+H13+I13+J13+K13+L13+M13+N13+O13+P13 -> 11.46869 | G13: =(R13-R$221)/R$222 -> 1.4304863 | H13: =(S13-S$221)/S$222 -> 1.2312912 | I13: =(T13-T$221)/T$222 -> 1.8378153 | J13: =(U13-U$221)/U$222 -> 1.7957776 | K13: =(V13-V$221)/V$222 -> 0.74981634 | L13: =(W13-W$221)/W$222 -> 0.75118092 | M13: =(X13-X$221)/X$222 -> 0.87017827 | N13: =(Y13-Y$221)/Y$222 -> 1.8252611 | ... P13: =(AA13-AA$221)/AA$222 -> 1.4967704 | R13: =(AH13-AVERAGE(AH$2:AH$220))/AVERAGE(AH$2:AH$220)*100+100 -> 133.81798 | S13: =(AC13-AVERAGE(AC$2:AC$220))/AVERAGE(AC$2:AC$220)*100+100 -> 125.0719 | T13: =(AG13-AVERAGE(AG$2:AG$220))/AVERAGE(AG$2:AG$220)*100+100 -> 181.29729 | U13: =(AI13-AVERAGE(AI$2:AI$220))/AVERAGE(AI$2:AI$220)*100+100 -> 146.2037 | V13: =(AJ13-AVERAGE(AJ$2:AJ$220))/AVERAGE(AJ$2:AJ$220)*100+100 -> 127.13669 | W13: =(AM13-AVERAGE(AM$2:AM$220))/AVERAGE(AM$2:AM$220)*100+100 -> 136.52275 | X13: =(AS13-AVERAGE(AS$2:AS$220))/AVERAGE(AS$2:AS$220)*100+100 -> 105.74304 | Y13: =(AU13-AVERAGE(AU$2:AU$220))/AVERAGE(AU$2:AU$220)*100+100 -> 120.06842 | Z13: =(AR13-AVERAGE(AR$2:AR$220))/AVERAGE(AR$2:AR$220)*100+100 -> 52.196771 | AA13: =(AZ13-AVERAGE(AZ$2:AZ$220))/AVERAGE(AZ$2:AZ$220)*100+100 -> 154.36197 | AC13: ='2026_Fantasy_Hitters'!F30 -> 151.18738 | AD13: ='2026_Fantasy_Hitters'!G30 -> 83.941493 | AE13: ='2026_Fantasy_Hitters'!H30 -> 31.96958 | AF13: ='2026_Fantasy_Hitters'!I30 -> 1.8887397 | AG13: ='2026_Fantasy_Hitters'!J30 -> 34.140947 | AH13: ='2026_Fantasy_Hitters'!K30 -> 89.700787 | AI13: ='2026_Fantasy_Hitters'!L30 -> 96 | AJ13: ='2026_Fantasy_Hitters'!M30 -> 59.712 | ... AY13: ='2026_Fantasy_Hitters'!AB30 -> 0.0933 | AZ13: =AG13/$E13 -> 0.05334523
A14: Kyle Tucker | B14: LAD | C14: OF | D14: 528 | E14: 620 | F14: =G14+H14+I14+J14+K14+L14+M14+N14+O14+P14 -> 11.219926 | G14: =(R14-R$221)/R$222 -> 1.8234672 | H14: =(S14-S$221)/S$222 -> 0.83974995 | I14: =(T14-T$221)/T$222 -> 1.1541995 | J14: =(U14-U$221)/U$222 -> 1.3222417 | K14: =(V14-V$221)/V$222 -> 2.0443367 | L14: =(W14-W$221)/W$222 -> -0.65034223 | M14: =(X14-X$221)/X$222 -> 1.0136863 | N14: =(Y14-Y$221)/Y$222 -> 1.385387 | ... P14: =(AA14-AA$221)/AA$222 -> 0.90208558 | R14: =(AH14-AVERAGE(AH$2:AH$220))/AVERAGE(AH$2:AH$220)*100+100 -> 143.10841 | S14: =(AC14-AVERAGE(AC$2:AC$220))/AVERAGE(AC$2:AC$220)*100+100 -> 117.09923 | T14: =(AG14-AVERAGE(AG$2:AG$220))/AVERAGE(AG$2:AG$220)*100+100 -> 151.05698 | U14: =(AI14-AVERAGE(AI$2:AI$220))/AVERAGE(AI$2:AI$220)*100+100 -> 134.02006 | V14: =(AJ14-AVERAGE(AJ$2:AJ$220))/AVERAGE(AJ$2:AJ$220)*100+100 -> 173.98684 | W14: =(AM14-AVERAGE(AM$2:AM$220))/AVERAGE(AM$2:AM$220)*100+100 -> 68.380071 | X14: =(AS14-AVERAGE(AS$2:AS$220))/AVERAGE(AS$2:AS$220)*100+100 -> 106.69017 | Y14: =(AU14-AVERAGE(AU$2:AU$220))/AVERAGE(AU$2:AU$220)*100+100 -> 115.23208 | Z14: =(AR14-AVERAGE(AR$2:AR$220))/AVERAGE(AR$2:AR$220)*100+100 -> 227.36025 | AA14: =(AZ14-AVERAGE(AZ$2:AZ$220))/AVERAGE(AZ$2:AZ$220)*100+100 -> 132.76331 | AC14: ='2026_Fantasy_Hitters'!F10 -> 141.54999 | AD14: ='2026_Fantasy_Hitters'!G10 -> 82.185199 | AE14: ='2026_Fantasy_Hitters'!H10 -> 28.088262 | AF14: ='2026_Fantasy_Hitters'!I10 -> 2.0720206 | AG14: ='2026_Fantasy_Hitters'!J10 -> 28.446251 | AH14: ='2026_Fantasy_Hitters'!K10 -> 95.928339 | AI14: ='2026_Fantasy_Hitters'!L10 -> 88 | AJ14: ='2026_Fantasy_Hitters'!M10 -> 81.716 | ... AY14: ='2026_Fantasy_Hitters'!AB10 -> 0.1318 | AZ14: =AG14/$E14 -> 0.04588105
A15: Corbin Carroll | B15: AZ | C15: OF | D15: 525 | E15: 604 | F15: =G15+H15+I15+J15+K15+L15+M15+N15+O15+P15 -> 10.800167 | G15: =(R15-R$221)/R$222 -> 1.8308859 | H15: =(S15-S$221)/S$222 -> 0.62373436 | I15: =(T15-T$221)/T$222 -> 0.83291115 | J15: =(U15-U$221)/U$222 -> 0.67112991 | K15: =(V15-V$221)/V$222 -> 0.94308839 | L15: =(W15-W$221)/W$222 -> 0.777087 | M15: =(X15-X$221)/X$222 -> 0.49536802 | N15: =(Y15-Y$221)/Y$222 -> 1.646712 | ... P15: =(AA15-AA$221)/AA$222 -> 0.64588026 | R15: =(AH15-AVERAGE(AH$2:AH$220))/AVERAGE(AH$2:AH$220)*100+100 -> 143.28379 | S15: =(AC15-AVERAGE(AC$2:AC$220))/AVERAGE(AC$2:AC$220)*100+100 -> 112.70066 | T15: =(AG15-AVERAGE(AG$2:AG$220))/AVERAGE(AG$2:AG$220)*100+100 -> 136.84452 | U15: =(AI15-AVERAGE(AI$2:AI$220))/AVERAGE(AI$2:AI$220)*100+100 -> 117.26755 | V15: =(AJ15-AVERAGE(AJ$2:AJ$220))/AVERAGE(AJ$2:AJ$220)*100+100 -> 134.13143 | W15: =(AM15-AVERAGE(AM$2:AM$220))/AVERAGE(AM$2:AM$220)*100+100 -> 137.78232 | X15: =(AS15-AVERAGE(AS$2:AS$220))/AVERAGE(AS$2:AS$220)*100+100 -> 103.26935 | Y15: =(AU15-AVERAGE(AU$2:AU$220))/AVERAGE(AU$2:AU$220)*100+100 -> 118.1053 | Z15: =(AR15-AVERAGE(AR$2:AR$220))/AVERAGE(AR$2:AR$220)*100+100 -> 314.55172 | AA15: =(AZ15-AVERAGE(AZ$2:AZ$220))/AVERAGE(AZ$2:AZ$220)*100+100 -> 123.45806 | AC15: ='2026_Fantasy_Hitters'!F12 -> 136.23298 | AD15: ='2026_Fantasy_Hitters'!G12 -> 73.97221 | AE15: ='2026_Fantasy_Hitters'!H12 -> 28.292155 | AF15: ='2026_Fantasy_Hitters'!I12 -> 9.8881412 | AG15: ='2026_Fantasy_Hitters'!J12 -> 25.769836 | AH15: ='2026_Fantasy_Hitters'!K12 -> 96.045902 | AI15: ='2026_Fantasy_Hitters'!L12 -> 77 | AJ15: ='2026_Fantasy_Hitters'!M12 -> 62.9972 | ... AY15: ='2026_Fantasy_Hitters'!AB12 -> 0.1043 | AZ15: =AG15/$E15 -> 0.042665291
A16: Jose Ramirez | B16: CLE | C16: 3B | D16: 575 | E16: 649 | F16: =G16+H16+I16+J16+K16+L16+M16+N16+O16+P16 -> 10.604638 | G16: =(R16-R$221)/R$222 -> 1.5023629 | H16: =(S16-S$221)/S$222 -> 1.3976296 | I16: =(T16-T$221)/T$222 -> 0.91076152 | J16: =(U16-U$221)/U$222 -> 1.3814337 | K16: =(V16-V$221)/V$222 -> 0.92521549 | L16: =(W16-W$221)/W$222 -> -0.61516894 | M16: =(X16-X$221)/X$222 -> 1.1323519 | N16: =(Y16-Y$221)/Y$222 -> 1.0249214 | ... P16: =(AA16-AA$221)/AA$222 -> 0.48979907 | R16: =(AH16-AVERAGE(AH$2:AH$220))/AVERAGE(AH$2:AH$220)*100+100 -> 135.51721 | S16: =(AC16-AVERAGE(AC$2:AC$220))/AVERAGE(AC$2:AC$220)*100+100 -> 128.45893 | T16: =(AG16-AVERAGE(AG$2:AG$220))/AVERAGE(AG$2:AG$220)*100+100 -> 140.28829 | U16: =(AI16-AVERAGE(AI$2:AI$220))/AVERAGE(AI$2:AI$220)*100+100 -> 135.54302 | V16: =(AJ16-AVERAGE(AJ$2:AJ$220))/AVERAGE(AJ$2:AJ$220)*100+100 -> 133.48459 | W16: =(AM16-AVERAGE(AM$2:AM$220))/AVERAGE(AM$2:AM$220)*100+100 -> 70.090212 | X16: =(AS16-AVERAGE(AS$2:AS$220))/AVERAGE(AS$2:AS$220)*100+100 -> 107.47335 | Y16: =(AU16-AVERAGE(AU$2:AU$220))/AVERAGE(AU$2:AU$220)*100+100 -> 111.26883 | Z16: =(AR16-AVERAGE(AR$2:AR$220))/AVERAGE(AR$2:AR$220)*100+100 -> 325.76591 | AA16: =(AZ16-AVERAGE(AZ$2:AZ$220))/AVERAGE(AZ$2:AZ$220)*100+100 -> 117.78926 | AC16: ='2026_Fantasy_Hitters'!F6 -> 155.28164 | AD16: ='2026_Fantasy_Hitters'!G6 -> 94.374098 | AE16: ='2026_Fantasy_Hitters'!H6 -> 31.648065 | AF16: ='2026_Fantasy_Hitters'!I6 -> 2.7801085 | AG16: ='2026_Fantasy_Hitters'!J6 -> 26.41835 | AH16: ='2026_Fantasy_Hitters'!K6 -> 90.839813 | AI16: ='2026_Fantasy_Hitters'!L6 -> 89 | AJ16: ='2026_Fantasy_Hitters'!M6 -> 62.6934 | ... AY16: ='2026_Fantasy_Hitters'!AB6 -> 0.0966 | AZ16: =AG16/$E16 -> 0.04070624
A17: Junior Caminero | B17: TB | C17: 3B | D17: 579 | E17: 631 | F17: =G17+H17+I17+J17+K17+L17+M17+N17+O17+P17 -> 10.255538 | G17: =(R17-R$221)/R$222 -> 0.922261 | H17: =(S17-S$221)/S$222 -> 1.4432552 | I17: =(T17-T$221)/T$222 -> 2.0920499 | J17: =(U17-U$221)/U$222 -> 2.2101215 | K17: =(V17-V$221)/V$222 -> -0.31673924 | L17: =(W17-W$221)/W$222 -> -0.29267613 | M17: =(X17-X$221)/X$222 -> 1.1368101 | N17: =(Y17-Y$221)/Y$222 -> 1.834216 | ... P17: =(AA17-AA$221)/AA$222 -> 1.8247944 | R17: =(AH17-AVERAGE(AH$2:AH$220))/AVERAGE(AH$2:AH$220)*100+100 -> 121.80308 | S17: =(AC17-AVERAGE(AC$2:AC$220))/AVERAGE(AC$2:AC$220)*100+100 -> 129.38797 | T17: =(AG17-AVERAGE(AG$2:AG$220))/AVERAGE(AG$2:AG$220)*100+100 -> 192.54357 | U17: =(AI17-AVERAGE(AI$2:AI$220))/AVERAGE(AI$2:AI$220)*100+100 -> 156.86439 | V17: =(AJ17-AVERAGE(AJ$2:AJ$220))/AVERAGE(AJ$2:AJ$220)*100+100 -> 88.536851 | W17: =(AM17-AVERAGE(AM$2:AM$220))/AVERAGE(AM$2:AM$220)*100+100 -> 85.769956 | X17: =(AS17-AVERAGE(AS$2:AS$220))/AVERAGE(AS$2:AS$220)*100+100 -> 107.50277 | Y17: =(AU17-AVERAGE(AU$2:AU$220))/AVERAGE(AU$2:AU$220)*100+100 -> 120.16688 | Z17: =(AR17-AVERAGE(AR$2:AR$220))/AVERAGE(AR$2:AR$220)*100+100 -> 44.963281 | AA17: =(AZ17-AVERAGE(AZ$2:AZ$220))/AVERAGE(AZ$2:AZ$220)*100+100 -> 166.27564 | AC17: ='2026_Fantasy_Hitters'!F13 -> 156.40467 | AD17: ='2026_Fantasy_Hitters'!G13 -> 92.608172 | AE17: ='2026_Fantasy_Hitters'!H13 -> 27.320608 | AF17: ='2026_Fantasy_Hitters'!I13 -> 1.0556017 | AG17: ='2026_Fantasy_Hitters'!J13 -> 36.258787 | AH17: ='2026_Fantasy_Hitters'!K13 -> 81.646965 | AI17: ='2026_Fantasy_Hitters'!L13 -> 103 | AJ17: ='2026_Fantasy_Hitters'!M13 -> 41.5829 | ... AY17: ='2026_Fantasy_Hitters'!AB13 -> 0.0659 | AZ17: =AG17/$E17 -> 0.05746242
A18: Gunnar Henderson | B18: BAL | C18: SS | D18: 579 | E18: 657 | F18: =G18+H18+I18+J18+K18+L18+M18+N18+O18+P18 -> 9.9496266 | G18: =(R18-R$221)/R$222 -> 1.656598 | H18: =(S18-S$221)/S$222 -> 1.4251767 | I18: =(T18-T$221)/T$222 -> 0.76074847 | J18: =(U18-U$221)/U$222 -> 1.0262818 | K18: =(V18-V$221)/V$222 -> 1.098232 | L18: =(W18-W$221)/W$222 -> 0.093505095 | M18: =(X18-X$221)/X$222 -> 1.0904674 | N18: =(Y18-Y$221)/Y$222 -> 1.0549049 | ... P18: =(AA18-AA$221)/AA$222 -> 0.29876892 | R18: =(AH18-AVERAGE(AH$2:AH$220))/AVERAGE(AH$2:AH$220)*100+100 -> 139.16347 | S18: =(AC18-AVERAGE(AC$2:AC$220))/AVERAGE(AC$2:AC$220)*100+100 -> 129.01985 | T18: =(AG18-AVERAGE(AG$2:AG$220))/AVERAGE(AG$2:AG$220)*100+100 -> 133.65234 | U18: =(AI18-AVERAGE(AI$2:AI$220))/AVERAGE(AI$2:AI$220)*100+100 -> 126.40529 | V18: =(AJ18-AVERAGE(AJ$2:AJ$220))/AVERAGE(AJ$2:AJ$220)*100+100 -> 139.74625 | W18: =(AM18-AVERAGE(AM$2:AM$220))/AVERAGE(AM$2:AM$220)*100+100 -> 104.54626 | X18: =(AS18-AVERAGE(AS$2:AS$220))/AVERAGE(AS$2:AS$220)*100+100 -> 107.19692 | Y18: =(AU18-AVERAGE(AU$2:AU$220))/AVERAGE(AU$2:AU$220)*100+100 -> 111.59849 | Z18: =(AR18-AVERAGE(AR$2:AR$220))/AVERAGE(AR$2:AR$220)*100+100 -> 232.86149 | AA18: =(AZ18-AVERAGE(AZ$2:AZ$220))/AVERAGE(AZ$2:AZ$220)*100+100 -> 110.85114 | AC18: ='2026_Fantasy_Hitters'!F14 -> 155.95968 | AD18: ='2026_Fantasy_Hitters'!G14 -> 93.565855 | AE18: ='2026_Fantasy_Hitters'!H14 -> 33.955351 | AF18: ='2026_Fantasy_Hitters'!I14 -> 4.0776992 | AG18: ='2026_Fantasy_Hitters'!J14 -> 25.168702 | AH18: ='2026_Fantasy_Hitters'!K14 -> 93.283969 | AI18: ='2026_Fantasy_Hitters'!L14 -> 83 | AJ18: ='2026_Fantasy_Hitters'!M14 -> 65.6343 | ... AY18: ='2026_Fantasy_Hitters'!AB14 -> 0.0999 | AZ18: =AG18/$E18 -> 0.038308527
A19: Ketel Marte | B19: AZ | C19: 2B | D19: 536 | E19: 616 | F19: =G19+H19+I19+J19+K19+L19+M19+N19+O19+P19 -> 9.6688269 | G19: =(R19-R$221)/R$222 -> 1.2413633 | H19: =(S19-S$221)/S$222 -> 1.0853252 | I19: =(T19-T$221)/T$222 -> 1.2343089 | J19: =(U19-U$221)/U$222 -> 1.2630498 | K19: =(V19-V$221)/V$222 -> 1.1979213 | L19: =(W19-W$221)/W$222 -> 0.13914301 | M19: =(X19-X$221)/X$222 -> 1.452422 | N19: =(Y19-Y$221)/Y$222 -> 1.6954553 | ... P19: =(AA19-AA$221)/AA$222 -> 1.0121331 | R19: =(AH19-AVERAGE(AH$2:AH$220))/AVERAGE(AH$2:AH$220)*100+100 -> 129.34695 | S19: =(AC19-AVERAGE(AC$2:AC$220))/AVERAGE(AC$2:AC$220)*100+100 -> 122.0997 | T19: =(AG19-AVERAGE(AG$2:AG$220))/AVERAGE(AG$2:AG$220)*100+100 -> 154.60068 | U19: =(AI19-AVERAGE(AI$2:AI$220))/AVERAGE(AI$2:AI$220)*100+100 -> 132.49711 | V19: =(AJ19-AVERAGE(AJ$2:AJ$220))/AVERAGE(AJ$2:AJ$220)*100+100 -> 143.35412 | W19: =(AM19-AVERAGE(AM$2:AM$220))/AVERAGE(AM$2:AM$220)*100+100 -> 106.7652 | X19: =(AS19-AVERAGE(AS$2:AS$220))/AVERAGE(AS$2:AS$220)*100+100 -> 109.58576 | Y19: =(AU19-AVERAGE(AU$2:AU$220))/AVERAGE(AU$2:AU$220)*100+100 -> 118.64123 | Z19: =(AR19-AVERAGE(AR$2:AR$220))/AVERAGE(AR$2:AR$220)*100+100 -> 40.021943 | AA19: =(AZ19-AVERAGE(AZ$2:AZ$220))/AVERAGE(AZ$2:AZ$220)*100+100 -> 136.76018 | AC19: ='2026_Fantasy_Hitters'!F23 -> 147.59458 | AD19: ='2026_Fantasy_Hitters'!G23 -> 85.537591 | AE19: ='2026_Fantasy_Hitters'!H23 -> 30.812062 | AF19: ='2026_Fantasy_Hitters'!I23 -> 2.1402714 | AG19: ='2026_Fantasy_Hitters'!J23 -> 29.113583 | AH19: ='2026_Fantasy_Hitters'!K23 -> 86.703764 | AI19: ='2026_Fantasy_Hitters'!L23 -> 87 | AJ19: ='2026_Fantasy_Hitters'!M23 -> 67.3288 | ... AY19: ='2026_Fantasy_Hitters'!AB23 -> 0.1093 | AZ19: =AG19/$E19 -> 0.04726231
A20: Zach Neto | B20: LAA | C20: SS | D20: 567 | E20: 634 | F20: =G20+H20+I20+J20+K20+L20+M20+N20+O20+P20 -> 9.584782 | G20: =(R20-R$221)/R$222 -> 1.1299245 | H20: =(S20-S$221)/S$222 -> 0.88365838 | I20: =(T20-T$221)/T$222 -> 0.90390636 | J20: =(U20-U$221)/U$222 -> 0.55274594 | K20: =(V20-V$221)/V$222 -> -0.17829193 | L20: =(W20-W$221)/W$222 -> 3.719001 | M20: =(X20-X$221)/X$222 -> 0.016707178 | N20: =(Y20-Y$221)/Y$222 -> 0.4525926 | ... P20: =(AA20-AA$221)/AA$222 -> 0.55935336 | R20: =(AH20-AVERAGE(AH$2:AH$220))/AVERAGE(AH$2:AH$220)*100+100 -> 126.71243 | S20: =(AC20-AVERAGE(AC$2:AC$220))/AVERAGE(AC$2:AC$220)*100+100 -> 117.9933 | T20: =(AG20-AVERAGE(AG$2:AG$220))/AVERAGE(AG$2:AG$220)*100+100 -> 139.98505 | U20: =(AI20-AVERAGE(AI$2:AI$220))/AVERAGE(AI$2:AI$220)*100+100 -> 114.22164 | V20: =(AJ20-AVERAGE(AJ$2:AJ$220))/AVERAGE(AJ$2:AJ$220)*100+100 -> 93.547415 | W20: =(AM20-AVERAGE(AM$2:AM$220))/AVERAGE(AM$2:AM$220)*100+100 -> 280.81949 | X20: =(AS20-AVERAGE(AS$2:AS$220))/AVERAGE(AS$2:AS$220)*100+100 -> 100.11026 | Y20: =(AU20-AVERAGE(AU$2:AU$220))/AVERAGE(AU$2:AU$220)*100+100 -> 104.97617 | Z20: =(AR20-AVERAGE(AR$2:AR$220))/AVERAGE(AR$2:AR$220)*100+100 -> 242.0786 | AA20: =(AZ20-AVERAGE(AZ$2:AZ$220))/AVERAGE(AZ$2:AZ$220)*100+100 -> 120.31544 | AC20: ='2026_Fantasy_Hitters'!F29 -> 142.63075 | AD20: ='2026_Fantasy_Hitters'!G29 -> 84.693598 | AE20: ='2026_Fantasy_Hitters'!H29 -> 29.765791 | AF20: ='2026_Fantasy_Hitters'!I29 -> 1.0276364 | AG20: ='2026_Fantasy_Hitters'!J29 -> 26.361244 | AH20: ='2026_Fantasy_Hitters'!K29 -> 84.937799 | AI20: ='2026_Fantasy_Hitters'!L29 -> 75 | AJ20: ='2026_Fantasy_Hitters'!M29 -> 43.9362 | ... AY20: ='2026_Fantasy_Hitters'!AB29 -> 0.0693 | AZ20: =AG20/$E20 -> 0.04157925
A21: Nick Kurtz | B21: ATH | C21: 1B | D21: 514 | E21: 576 | F21: =G21+H21+I21+J21+K21+L21+M21+N21+O21+P21 -> 9.3861861 | G21: =(R21-R$221)/R$222 -> 1.062775 | H21: =(S21-S$221)/S$222 -> 0.56142097 | I21: =(T21-T$221)/T$222 -> 1.7984032 | J21: =(U21-U$221)/U$222 -> 1.7365856 | K21: =(V21-V$221)/V$222 -> 1.1101453 | L21: =(W21-W$221)/W$222 -> -0.61363249 | M21: =(X21-X$221)/X$222 -> 0.65029624 | N21: =(Y21-Y$221)/Y$222 -> 1.9834946 | ... P21: =(AA21-AA$221)/AA$222 -> 1.923593 | R21: =(AH21-AVERAGE(AH$2:AH$220))/AVERAGE(AH$2:AH$220)*100+100 -> 125.12496 | S21: =(AC21-AVERAGE(AC$2:AC$220))/AVERAGE(AC$2:AC$220)*100+100 -> 111.43181 | T21: =(AG21-AVERAGE(AG$2:AG$220))/AVERAGE(AG$2:AG$220)*100+100 -> 179.55386 | U21: =(AI21-AVERAGE(AI$2:AI$220))/AVERAGE(AI$2:AI$220)*100+100 -> 144.68075 | V21: =(AJ21-AVERAGE(AJ$2:AJ$220))/AVERAGE(AJ$2:AJ$220)*100+100 -> 140.1774 | W21: =(AM21-AVERAGE(AM$2:AM$220))/AVERAGE(AM$2:AM$220)*100+100 -> 70.164915 | X21: =(AS21-AVERAGE(AS$2:AS$220))/AVERAGE(AS$2:AS$220)*100+100 -> 104.29185 | Y21: =(AU21-AVERAGE(AU$2:AU$220))/AVERAGE(AU$2:AU$220)*100+100 -> 121.80817 | Z21: =(AR21-AVERAGE(AR$2:AR$220))/AVERAGE(AR$2:AR$220)*100+100 -> 23.967558 | AA21: =(AZ21-AVERAGE(AZ$2:AZ$220))/AVERAGE(AZ$2:AZ$220)*100+100 -> 169.86396 | AC21: ='2026_Fantasy_Hitters'!F18 -> 134.69919 | AD21: ='2026_Fantasy_Hitters'!G18 -> 72.697838 | AE21: ='2026_Fantasy_Hitters'!H18 -> 26.09703 | AF21: ='2026_Fantasy_Hitters'!I18 -> 1.9077241 | AG21: ='2026_Fantasy_Hitters'!J18 -> 33.812634 | AH21: ='2026_Fantasy_Hitters'!K18 -> 83.873684 | AI21: ='2026_Fantasy_Hitters'!L18 -> 95 | AJ21: ='2026_Fantasy_Hitters'!M18 -> 65.8368 | ... AY21: ='2026_Fantasy_Hitters'!AB18 -> 0.1143 | AZ21: =AG21/$E21 -> 0.05870249
A22: Cal Raleigh | B22: SEA | C22: C | D22: 540 | E22: 626 | F22: =G22+H22+I22+J22+K22+L22+M22+N22+O22+P22 -> 9.1627612 | G22: =(R22-R$221)/R$222 -> 0.96112372 | H22: =(S22-S$221)/S$222 -> 0.071005663 | I22: =(T22-T$221)/T$222 -> 2.4466266 | J22: =(U22-U$221)/U$222 -> 2.1509295 | K22: =(V22-V$221)/V$222 -> 1.6415552 | L22: =(W22-W$221)/W$222 -> 0.093796521 | M22: =(X22-X$221)/X$222 -> -1.458479 | N22: =(Y22-Y$221)/Y$222 -> 1.2944431 | ... P22: =(AA22-AA$221)/AA$222 -> 2.2372841 | R22: =(AH22-AVERAGE(AH$2:AH$220))/AVERAGE(AH$2:AH$220)*100+100 -> 122.72183 | S22: =(AC22-AVERAGE(AC$2:AC$220))/AVERAGE(AC$2:AC$220)*100+100 -> 101.44584 | T22: =(AG22-AVERAGE(AG$2:AG$220))/AVERAGE(AG$2:AG$220)*100+100 -> 208.22857 | U22: =(AI22-AVERAGE(AI$2:AI$220))/AVERAGE(AI$2:AI$220)*100+100 -> 155.34144 | V22: =(AJ22-AVERAGE(AJ$2:AJ$220))/AVERAGE(AJ$2:AJ$220)*100+100 -> 159.40972 | W22: =(AM22-AVERAGE(AM$2:AM$220))/AVERAGE(AM$2:AM$220)*100+100 -> 104.56043 | X22: =(AS22-AVERAGE(AS$2:AS$220))/AVERAGE(AS$2:AS$220)*100+100 -> 90.374265 | Y22: =(AU22-AVERAGE(AU$2:AU$220))/AVERAGE(AU$2:AU$220)*100+100 -> 114.23217 | Z22: =(AR22-AVERAGE(AR$2:AR$220))/AVERAGE(AR$2:AR$220)*100+100 -> 74.665753 | AA22: =(AZ22-AVERAGE(AZ$2:AZ$220))/AVERAGE(AZ$2:AZ$220)*100+100 -> 181.25706 | AC22: ='2026_Fantasy_Hitters'!F11 -> 122.62811 | AD22: ='2026_Fantasy_Hitters'!G11 -> 60.102107 | AE22: ='2026_Fantasy_Hitters'!H11 -> 22.494845 | AF22: ='2026_Fantasy_Hitters'!I11 -> 0 | AG22: ='2026_Fantasy_Hitters'!J11 -> 39.212502 | AH22: ='2026_Fantasy_Hitters'!K11 -> 82.262821 | AI22: ='2026_Fantasy_Hitters'!L11 -> 102 | AJ22: ='2026_Fantasy_Hitters'!M11 -> 74.8696 | ... AY22: ='2026_Fantasy_Hitters'!AB11 -> 0.1196 | AZ22: =AG22/$E22 -> 0.06263978
A23: Rafael Devers | B23: SF | C23: 1B | D23: 562 | E23: 656 | F23: =G23+H23+I23+J23+K23+L23+M23+N23+O23+P23 -> 8.7863895 | G23: =(R23-R$221)/R$222 -> 1.1833617 | H23: =(S23-S$221)/S$222 -> 0.8450582 | I23: =(T23-T$221)/T$222 -> 1.6007155 | J23: =(U23-U$221)/U$222 -> 1.5590097 | K23: =(V23-V$221)/V$222 -> 2.0842007 | L23: =(W23-W$221)/W$222 -> 0.10542696 | M23: =(X23-X$221)/X$222 -> 0.049717658 | N23: =(Y23-Y$221)/Y$222 -> 1.1287347 | ... P23: =(AA23-AA$221)/AA$222 -> 1.1532311 | R23: =(AH23-AVERAGE(AH$2:AH$220))/AVERAGE(AH$2:AH$220)*100+100 -> 127.97574 | S23: =(AC23-AVERAGE(AC$2:AC$220))/AVERAGE(AC$2:AC$220)*100+100 -> 117.20732 | T23: =(AG23-AVERAGE(AG$2:AG$220))/AVERAGE(AG$2:AG$220)*100+100 -> 170.80899 | U23: =(AI23-AVERAGE(AI$2:AI$220))/AVERAGE(AI$2:AI$220)*100+100 -> 140.11188 | V23: =(AJ23-AVERAGE(AJ$2:AJ$220))/AVERAGE(AJ$2:AJ$220)*100+100 -> 175.42956 | W23: =(AM23-AVERAGE(AM$2:AM$220))/AVERAGE(AM$2:AM$220)*100+100 -> 105.12591 | X23: =(AS23-AVERAGE(AS$2:AS$220))/AVERAGE(AS$2:AS$220)*100+100 -> 100.32813 | Y23: =(AU23-AVERAGE(AU$2:AU$220))/AVERAGE(AU$2:AU$220)*100+100 -> 112.41024 | Z23: =(AR23-AVERAGE(AR$2:AR$220))/AVERAGE(AR$2:AR$220)*100+100 -> 15.124681 | AA23: =(AZ23-AVERAGE(AZ$2:AZ$220))/AVERAGE(AZ$2:AZ$220)*100+100 -> 141.88479 | AC23: ='2026_Fantasy_Hitters'!F33 -> 141.68064 | AD23: ='2026_Fantasy_Hitters'!G33 -> 81.842755 | AE23: ='2026_Fantasy_Hitters'!H33 -> 27.3787 | AF23: ='2026_Fantasy_Hitters'!I33 -> 1.000652 | AG23: ='2026_Fantasy_Hitters'!J33 -> 32.165845 | AH23: ='2026_Fantasy_Hitters'!K33 -> 85.784615 | AI23: ='2026_Fantasy_Hitters'!L33 -> 92 | AJ23: ='2026_Fantasy_Hitters'!M33 -> 82.3936 | ... AY23: ='2026_Fantasy_Hitters'!AB33 -> 0.1256 | AZ23: =AG23/$E23 -> 0.0490333
A24: Bryce Harper | B24: PHI | C24: 1B | D24: 523 | E24: 606 | F24: =G24+H24+I24+J24+K24+L24+M24+N24+O24+P24 -> 8.2977114 | G24: =(R24-R$221)/R$222 -> 1.0777106 | H24: =(S24-S$221)/S$222 -> 0.86940225 | I24: =(T24-T$221)/T$222 -> 0.89812011 | J24: =(U24-U$221)/U$222 -> 1.0854738 | K24: =(V24-V$221)/V$222 -> 1.6220468 | L24: =(W24-W$221)/W$222 -> -0.24826562 | M24: =(X24-X$221)/X$222 -> 1.2523827 | N24: =(Y24-Y$221)/Y$222 -> 1.2695672 | ... P24: =(AA24-AA$221)/AA$222 -> 0.70607808 | R24: =(AH24-AVERAGE(AH$2:AH$220))/AVERAGE(AH$2:AH$220)*100+100 -> 125.47805 | S24: =(AC24-AVERAGE(AC$2:AC$220))/AVERAGE(AC$2:AC$220)*100+100 -> 117.70302 | T24: =(AG24-AVERAGE(AG$2:AG$220))/AVERAGE(AG$2:AG$220)*100+100 -> 139.72909 | U24: =(AI24-AVERAGE(AI$2:AI$220))/AVERAGE(AI$2:AI$220)*100+100 -> 127.92824 | V24: =(AJ24-AVERAGE(AJ$2:AJ$220))/AVERAGE(AJ$2:AJ$220)*100+100 -> 158.70369 | W24: =(AM24-AVERAGE(AM$2:AM$220))/AVERAGE(AM$2:AM$220)*100+100 -> 87.929215 | X24: =(AS24-AVERAGE(AS$2:AS$220))/AVERAGE(AS$2:AS$220)*100+100 -> 108.26553 | Y24: =(AU24-AVERAGE(AU$2:AU$220))/AVERAGE(AU$2:AU$220)*100+100 -> 113.95866 | Z24: =(AR24-AVERAGE(AR$2:AR$220))/AVERAGE(AR$2:AR$220)*100+100 -> 78.409894 | AA24: =(AZ24-AVERAGE(AZ$2:AZ$220))/AVERAGE(AZ$2:AZ$220)*100+100 -> 125.64441 | AC24: ='2026_Fantasy_Hitters'!F26 -> 142.27985 | AD24: ='2026_Fantasy_Hitters'!G26 -> 86.0929 | AE24: ='2026_Fantasy_Hitters'!H26 -> 29.360017 | AF24: ='2026_Fantasy_Hitters'!I26 -> 1.007653 | AG24: ='2026_Fantasy_Hitters'!J26 -> 26.313043 | AH24: ='2026_Fantasy_Hitters'!K26 -> 84.110368 | AI24: ='2026_Fantasy_Hitters'!L26 -> 84 | AJ24: ='2026_Fantasy_Hitters'!M26 -> 74.538 | ... AY24: ='2026_Fantasy_Hitters'!AB26 -> 0.123 | AZ24: =AG24/$E24 -> 0.043420864
A25: Randy Arozarena | B25: SEA | C25: OF | D25: 565 | E25: 654 | F25: =G25+H25+I25+J25+K25+L25+M25+N25+O25+P25 -> 7.9725424 | G25: =(R25-R$221)/R$222 -> 1.3023528 | H25: =(S25-S$221)/S$222 -> 0.4165686 | I25: =(T25-T$221)/T$222 -> 0.6284244 | J25: =(U25-U$221)/U$222 -> 0.43436197 | K25: =(V25-V$221)/V$222 -> 1.0882954 | L25: =(W25-W$221)/W$222 -> 4.132543 | M25: =(X25-X$221)/X$222 -> -1.1566114 | N25: =(Y25-Y$221)/Y$222 -> -0.27930404 | ... P25: =(AA25-AA$221)/AA$222 -> 0.17848543 | R25: =(AH25-AVERAGE(AH$2:AH$220))/AVERAGE(AH$2:AH$220)*100+100 -> 130.78879 | S25: =(AC25-AVERAGE(AC$2:AC$220))/AVERAGE(AC$2:AC$220)*100+100 -> 108.48229 | T25: =(AG25-AVERAGE(AG$2:AG$220))/AVERAGE(AG$2:AG$220)*100+100 -> 127.79888 | U25: =(AI25-AVERAGE(AI$2:AI$220))/AVERAGE(AI$2:AI$220)*100+100 -> 111.17573 | V25: =(AJ25-AVERAGE(AJ$2:AJ$220))/AVERAGE(AJ$2:AJ$220)*100+100 -> 139.38663 | W25: =(AM25-AVERAGE(AM$2:AM$220))/AVERAGE(AM$2:AM$220)*100+100 -> 300.92608 | X25: =(AS25-AVERAGE(AS$2:AS$220))/AVERAGE(AS$2:AS$220)*100+100 -> 92.366545 | Y25: =(AU25-AVERAGE(AU$2:AU$220))/AVERAGE(AU$2:AU$220)*100+100 -> 96.929102 | Z25: =(AR25-AVERAGE(AR$2:AR$220))/AVERAGE(AR$2:AR$220)*100+100 -> 212.86094 | AA25: =(AZ25-AVERAGE(AZ$2:AZ$220))/AVERAGE(AZ$2:AZ$220)*100+100 -> 106.4825 | AC25: ='2026_Fantasy_Hitters'!F51 -> 131.1338 | AD25: ='2026_Fantasy_Hitters'!G51 -> 79.871262 | AE25: ='2026_Fantasy_Hitters'!H51 -> 25.382678 | AF25: ='2026_Fantasy_Hitters'!I51 -> 1.8841764 | AG25: ='2026_Fantasy_Hitters'!J51 -> 24.066409 | AH25: ='2026_Fantasy_Hitters'!K51 -> 87.670262 | AI25: ='2026_Fantasy_Hitters'!L51 -> 73 | AJ25: ='2026_Fantasy_Hitters'!M51 -> 65.4654 | ... AY25: ='2026_Fantasy_Hitters'!AB51 -> 0.1001 | AZ25: =AG25/$E25 -> 0.03679879
A26: Francisco Lindor | B26: NYM | C26: SS | D26: 547 | E26: 618 | F26: =G26+H26+I26+J26+K26+L26+M26+N26+O26+P26 -> 7.6621276 | G26: =(R26-R$221)/R$222 -> 1.1251843 | H26: =(S26-S$221)/S$222 -> 0.82906829 | I26: =(T26-T$221)/T$222 -> 0.73613324 | J26: =(U26-U$221)/U$222 -> 0.61193792 | K26: =(V26-V$221)/V$222 -> 0.39637063 | L26: =(W26-W$221)/W$222 -> 1.1908526 | M26: =(X26-X$221)/X$222 -> 0.42319364 | N26: =(Y26-Y$221)/Y$222 -> 0.49877343 | ... P26: =(AA26-AA$221)/AA$222 -> 0.46494285 | R26: =(AH26-AVERAGE(AH$2:AH$220))/AVERAGE(AH$2:AH$220)*100+100 -> 126.60037 | S26: =(AC26-AVERAGE(AC$2:AC$220))/AVERAGE(AC$2:AC$220)*100+100 -> 116.88172 | T26: =(AG26-AVERAGE(AG$2:AG$220))/AVERAGE(AG$2:AG$220)*100+100 -> 132.56347 | U26: =(AI26-AVERAGE(AI$2:AI$220))/AVERAGE(AI$2:AI$220)*100+100 -> 115.7446 | V26: =(AJ26-AVERAGE(AJ$2:AJ$220))/AVERAGE(AJ$2:AJ$220)*100+100 -> 114.3451 | W26: =(AM26-AVERAGE(AM$2:AM$220))/AVERAGE(AM$2:AM$220)*100+100 -> 157.89979 | X26: =(AS26-AVERAGE(AS$2:AS$220))/AVERAGE(AS$2:AS$220)*100+100 -> 102.79301 | Y26: =(AU26-AVERAGE(AU$2:AU$220))/AVERAGE(AU$2:AU$220)*100+100 -> 105.48392 | Z26: =(AR26-AVERAGE(AR$2:AR$220))/AVERAGE(AR$2:AR$220)*100+100 -> 227.41141 | AA26: =(AZ26-AVERAGE(AZ$2:AZ$220))/AVERAGE(AZ$2:AZ$220)*100+100 -> 116.8865 | AC26: ='2026_Fantasy_Hitters'!F20 -> 141.28707 | AD26: ='2026_Fantasy_Hitters'!G20 -> 87.178035 | AE26: ='2026_Fantasy_Hitters'!H20 -> 27.251856 | AF26: ='2026_Fantasy_Hitters'!I20 -> 1.1602202 | AG26: ='2026_Fantasy_Hitters'!J20 -> 24.963651 | AH26: ='2026_Fantasy_Hitters'!K20 -> 84.862682 | AI26: ='2026_Fantasy_Hitters'!L20 -> 76 | AJ26: ='2026_Fantasy_Hitters'!M20 -> 53.7042 | ... AY26: ='2026_Fantasy_Hitters'!AB20 -> 0.0869 | AZ26: =AG26/$E26 -> 0.040394257
A27: Elly De La Cruz | B27: CIN | C27: SS | D27: 568 | E27: 636 | F27: =G27+H27+I27+J27+K27+L27+M27+N27+O27+P27 -> 7.1688843 | G27: =(R27-R$221)/R$222 -> 1.5125716 | H27: =(S27-S$221)/S$222 -> 1.1015585 | I27: =(T27-T$221)/T$222 -> 0.29757301 | J27: =(U27-U$221)/U$222 -> 0.67112991 | K27: =(V27-V$221)/V$222 -> 0.66051067 | L27: =(W27-W$221)/W$222 -> -0.97382846 | M27: =(X27-X$221)/X$222 -> 0.55938725 | N27: =(Y27-Y$221)/Y$222 -> 0.5020193 | ... P27: =(AA27-AA$221)/AA$222 -> -0.083792599 | R27: =(AH27-AVERAGE(AH$2:AH$220))/AVERAGE(AH$2:AH$220)*100+100 -> 135.75856 | S27: =(AC27-AVERAGE(AC$2:AC$220))/AVERAGE(AC$2:AC$220)*100+100 -> 122.43025 | T27: =(AG27-AVERAGE(AG$2:AG$220))/AVERAGE(AG$2:AG$220)*100+100 -> 113.16339 | U27: =(AI27-AVERAGE(AI$2:AI$220))/AVERAGE(AI$2:AI$220)*100+100 -> 117.26755 | V27: =(AJ27-AVERAGE(AJ$2:AJ$220))/AVERAGE(AJ$2:AJ$220)*100+100 -> 123.90462 | W27: =(AM27-AVERAGE(AM$2:AM$220))/AVERAGE(AM$2:AM$220)*100+100 -> 52.652026 | X27: =(AS27-AVERAGE(AS$2:AS$220))/AVERAGE(AS$2:AS$220)*100+100 -> 103.69187 | Y27: =(AU27-AVERAGE(AU$2:AU$220))/AVERAGE(AU$2:AU$220)*100+100 -> 105.51961 | Z27: =(AR27-AVERAGE(AR$2:AR$220))/AVERAGE(AR$2:AR$220)*100+100 -> 368.65327 | AA27: =(AZ27-AVERAGE(AZ$2:AZ$220))/AVERAGE(AZ$2:AZ$220)*100+100 -> 96.956694 | AC27: ='2026_Fantasy_Hitters'!F7 -> 147.99414 | AD27: ='2026_Fantasy_Hitters'!G7 -> 92.320983 | AE27: ='2026_Fantasy_Hitters'!H7 -> 30.774897 | AF27: ='2026_Fantasy_Hitters'!I7 -> 5.1324971 | AG27: ='2026_Fantasy_Hitters'!J7 -> 21.310331 | AH27: ='2026_Fantasy_Hitters'!K7 -> 91.00159 | AI27: ='2026_Fantasy_Hitters'!L7 -> 77 | AJ27: ='2026_Fantasy_Hitters'!M7 -> 58.194 | ... AY27: ='2026_Fantasy_Hitters'!AB7 -> 0.0915 | AZ27: =AG27/$E27 -> 0.03350681
