Workbook

Sheet 2025_Fantasy_Hitters_modified
A1: Team | B1: Name | C1: Position | D1: AB | E1: PA | F1: H | G1: 1B | H1: 2B | I1: 3B | J1: HR | K1: R | L1: RBI | M1: BB | N1: IBB | O1: SO | P1: HBP | Q1: SF | R1: SH | S1: SB | T1: CS | U1: NSB | V1: AVG | W1: OBP | X1: SLG | Y1: OPS | Z1: BABIP | AA1: K% | AB1: BB% | AD1: HIP | AE1: H% | AF1: 1B% | AG1: 2B% | AH1: 3B% | AI1: HR% | AJ1: R% | AK1: RBI% | AL1: IBB% | AM1: HBP% | AN1: SF% | AO1: SB% | AP1: CS% | AQ1: SH%
A2: ARI | B2: Alek Thomas | C2: OF | D2: 278 | E2: 303 | F2: =AD2+J2 -> 71.072895 | G2: =$AD2*AF2 -> 47.126306 | H2: =$AD2*AG2 -> 15.110835 | I2: =$AD2*AH2 -> 2.0665659 | J2: =$E2*AI2 -> 6.6 | K2: =$E2*AJ2 -> 36.641758 | L2: =$E2*AK2 -> 34 | M2: =$E2*(AB2/100) -> 19.997802 | N2: =$E2*AL2 -> 0.9 | O2: =$E2*(AA2/100) -> 56.604396 | P2: =$E2*AM2 -> 2.0029018 | Q2: =$E2*AN2 -> 2 | R2: =$E2*AQ2 -> 1.2116071 | S2: =$E2*AO2 -> 6.9659341 | T2: =$E2*AP2 -> 2.021978 | U2: =S2-T2 -> 4.943956 | V2: =F2/D2 -> 0.25565789 | W2: =(F2+M2+N2+P2)/(D2+M2+N2+Q2) -> 0.31231069 | X2: =(G2+H2*2+I2*3+J2*4)/D2 -> 0.39549523 | Y2: =W2+X2 -> 0.70780591 | Z2: 0.29739023 | AA2: 18.681319 | AB2: 6.5999347 | AD2: =(D2-O2-J2+Q2)*Z2 -> 64.472895 | AE2: 0.22915804 | AF2: 0.73094758 | AG2: 0.234375 | AH2: 0.032053251 | AI2: 0.021782178 | AJ2: 0.1209299 | AK2: 0.11221122 | AL2: 0.002970297 | AM2: 0.0066102369 | AN2: 0.0066006601 | AO2: 0.022989881 | AP2: 0.0066731948 | AQ2: 0.0039987034
A3: ARI | B3: Corbin Carroll | C3: OF | D3: 567 | E3: 653 | F3: =AD3+J3 -> 146.76344 | G3: =$AD3*AF3 -> 87.133857 | H3: =$AD3*AG3 -> 30.990933 | I3: =$AD3*AH3 -> 9.6947246 | J3: =$E3*AI3 -> 21.8 | K3: =$E3*AJ3 -> 102.16786 | L3: =$E3*AK3 -> 75 | M3: =$E3*(AB3/100) -> 67.102083 | N3: =$E3*AL3 -> 1.3971726 | O3: =$E3*(AA3/100) -> 126.3244 | P3: =$E3*AM3 -> 9.2908815 | Q3: =$E3*AN3 -> 4.4 | R3: =$E3*AQ3 -> 2.9863222 | S3: =$E3*AO3 -> 38.79256 | T3: =$E3*AP3 -> 6.9802083 | U3: =S3-T3 -> 31.812351 | V3: =F3/D3 -> 0.25884204 | W3: =(F3+M3+N3+P3)/(D3+M3+N3+Q3) -> 0.3509202 | X3: =(G3+H3*2+I3*3+J3*4)/D3 -> 0.46807742 | Y3: =W3+X3 -> 0.81899762 | Z3: 0.29522949 | AA3: 19.345238 | AB3: 10.27597 | AD3: =(D3-O3-J3+Q3)*Z3 -> 124.96344 | AE3: 0.22435441 | AF3: 0.6972748 | AG3: 0.248 | AH3: 0.077580488 | AI3: 0.03338438 | AJ3: 0.1564592 | AK3: 0.11485452 | AL3: 0.0021396212 | AM3: 0.014227996 | AN3: 0.0067381317 | AO3: 0.059406676 | AP3: 0.010689446 | AQ3: 0.0045732346
A4: ARI | B4: Eugenio Suarez | D4: 533 | E4: 603 | F4: =AD4+J4 -> 123.91839 | G4: =$AD4*AF4 -> 73.897903 | H4: =$AD4*AG4 -> 25.824536 | I4: =$AD4*AH4 -> 0.99722439 | J4: =$E4*AI4 -> 23.6 | K4: =$E4*AJ4 -> 69.186207 | L4: =$E4*AK4 -> 83 | M4: =$E4*(AB4/100) -> 54.144828 | N4: =$E4*AL4 -> 0.4 | O4: =$E4*(AA4/100) -> 173.27586 | P4: =$E4*AM4 -> 9.1016611 | Q4: =$E4*AN4 -> 5.4 | R4: =$E4*AQ4 -> 0 | S4: =$E4*AO4 -> 1.9980296 | T4: =$E4*AP4 -> 0.99901478 | U4: =S4-T4 -> 0.99901478 | V4: =F4/D4 -> 0.23249229 | W4: =(F4+M4+N4+P4)/(D4+M4+N4+Q4) -> 0.31632771 | X4: =(G4+H4*2+I4*3+J4*4)/D4 -> 0.41827139 | Y4: =W4+X4 -> 0.7345991 | Z4: 0.29373734 | AA4: 28.735632 | AB4: 8.9792417 | AD4: =(D4-O4-J4+Q4)*Z4 -> 100.31839 | AE4: 0.20871015 | AF4: 0.73663366 | AG4: 0.25742574 | AH4: 0.0099405941 | AI4: 0.039137645 | AJ4: 0.11473666 | AK4: 0.13764511 | AL4: 0.00066334992 | AM4: 0.015093965 | AN4: 0.0089552239 | AO4: 0.0033134819 | AP4: 0.0016567409 | AQ4: 0
A5: ARI | B5: Gabriel Moreno | C5: C | D5: 400 | E5: 450 | F5: =AD5+J5 -> 111.25304 | G5: =$AD5*AF5 -> 78.734648 | H5: =$AD5*AG5 -> 21.840456 | I5: =$AD5*AH5 -> 1.4034731 | J5: =$E5*AI5 -> 9 | K5: =$E5*AJ5 -> 52.487574 | L5: =$E5*AK5 -> 53 | M5: =$E5*(AB5/100) -> 38.549112 | N5: =$E5*AL5 -> 0.9887574 | O5: =$E5*(AA5/100) -> 73.668639 | P5: =$E5*AM5 -> 4.8629032 | Q5: =$E5*AN5 -> 3.4 | R5: =$E5*AQ5 -> 0 | S5: =$E5*AO5 -> 5.0325444 | T5: =$E5*AP5 -> 1.0775148 | U5: =S5-T5 -> 3.9550296 | V5: =F5/D5 -> 0.27813261 | W5: =(F5+M5+N5+P5)/(D5+M5+N5+Q5) -> 0.3514123 | X5: =(G5+H5*2+I5*3+J5*4)/D5 -> 0.40656495 | Y5: =W5+X5 -> 0.75797725 | Z5: 0.31881211 | AA5: 16.370809 | AB5: 8.5664694 | AD5: =(D5-O5-J5+Q5)*Z5 -> 102.25304 | AE5: 0.24761383 | AF5: 0.7699981 | AG5: 0.21359223 | AH5: 0.01372549 | AI5: 0.02 | AJ5: 0.11663905 | AK5: 0.11777778 | AL5: 0.0021972387 | AM5: 0.010806452 | AN5: 0.0075555556 | AO5: 0.011183432 | AP5: 0.0023944773 | AQ5: 0
A6: ARI | B6: Jake McCarthy | C6: OF | D6: 465 | E6: 517 | F6: =AD6+J6 -> 121.18633 | G6: =$AD6*AF6 -> 88.125083 | H6: =$AD6*AG6 -> 20.814895 | I6: =$AD6*AH6 -> 5.6170255 | J6: =$E6*AI6 -> 7.2 | K6: =$E6*AJ6 -> 65.432967 | L6: =$E6*AK6 -> 51 | M6: =$E6*(AB6/100) -> 35.192857 | N6: =$E6*AL6 -> 0.9 | O6: =$E6*(AA6/100) -> 92.794872 | P6: =$E6*AM6 -> 8.2237624 | Q6: =$E6*AN6 -> 3 | R6: =$E6*AQ6 -> 4.0570297 | S6: =$E6*AO6 -> 27.851282 | T6: =$E6*AP6 -> 6.0628205 | U6: =S6-T6 -> 21.788462 | V6: =F6/D6 -> 0.26061576 | W6: =(F6+M6+N6+P6)/(D6+M6+N6+Q6) -> 0.32831838 | X6: =(G6+H6*2+I6*3+J6*4)/D6 -> 0.3772171 | Y6: =W6+X6 -> 0.70553547 | Z6: 0.30974114 | AA6: 17.948718 | AB6: 6.807129 | AD6: =(D6-O6-J6+Q6)*Z6 -> 113.98633 | AE6: 0.23652641 | AF6: 0.77311976 | AG6: 0.1826087 | AH6: 0.049278062 | AI6: 0.013926499 | AJ6: 0.1265628 | AK6: 0.098646035 | AL6: 0.0017408124 | AM6: 0.015906697 | AN6: 0.0058027079 | AO6: 0.053870952 | AP6: 0.011726926 | AQ6: 0.0078472528
A7: ARI | B7: Jordan Lawlar | D7: 235 | E7: 262 | F7: =AD7+J7 -> 58.769788 | G7: =$AD7*AF7 -> 40.324083 | H7: =$AD7*AG7 -> 10.95222 | I7: =$AD7*AH7 -> 1.4054073 | J7: =$E7*AI7 -> 6 | K7: =$E7*AJ7 -> 32.015444 | L7: =$E7*AK7 -> 27 | M7: =$E7*(AB7/100) -> 19.224324 | N7: =$E7*AL7 -> 0 | O7: =$E7*(AA7/100) -> 63.72973 | P7: =$E7*AM7 -> 3.221393 | Q7: =$E7*AN7 -> 2 | R7: =$E7*AQ7 -> 0.79104478 | S7: =$E7*AO7 -> 10.709266 | T7: =$E7*AP7 -> 2.0023166 | U7: =S7-T7 -> 8.7069498 | V7: =F7/D7 -> 0.2500842 | W7: =(F7+M7+N7+P7)/(D7+M7+N7+Q7) -> 0.31697032 | X7: =(G7+H7*2+I7*3+J7*4)/D7 -> 0.38487125 | Y7: =W7+X7 -> 0.70184157 | Z7: 0.31547619 | AA7: 24.324324 | AB7: 7.3375284 | AD7: =(D7-O7-J7+Q7)*Z7 -> 52.769788 | AE7: 0.2242978 | AF7: 0.76415094 | AG7: 0.20754717 | AH7: 0.026632801 | AI7: 0.022900763 | AJ7: 0.12219635 | AK7: 0.10305344 | AL7: 0 | AM7: 0.012295393 | AN7: 0.0076335878 | AO7: 0.040875063 | AP7: 0.0076424298 | AQ7: 0.0030192549
A8: ARI | B8: Josh Naylor | D8: 535 | E8: 596 | F8: =AD8+J8 -> 140.30072 | G8: =$AD8*AF8 -> 89.528254 | H8: =$AD8*AG8 -> 28.261188 | I8: =$AD8*AH8 -> 0.3970024 | J8: =$E8*AI8 -> 21.2 | K8: =$E8*AJ8 -> 70.677833 | L8: =$E8*AK8 -> 91 | M8: =$E8*(AB8/100) -> 49.893268 | N8: =$E8*AL8 -> 5.6850575 | O8: =$E8*(AA8/100) -> 92.972085 | P8: =$E8*AM8 -> 6.914433 | Q8: =$E8*AN8 -> 5 | R8: =$E8*AQ8 -> 0 | S8: =$E8*AO8 -> 6.9850575 | T8: =$E8*AP8 -> 1.9957307 | U8: =S8-T8 -> 4.9893268 | V8: =F8/D8 -> 0.26224434 | W8: =(F8+M8+N8+P8)/(D8+M8+N8+Q8) -> 0.34049842 | X8: =(G8+H8*2+I8*3+J8*4)/D8 -> 0.43372269 | Y8: =W8+X8 -> 0.7742211 | Z8: 0.27969214 | AA8: 15.599343 | AB8: 8.3713536 | AD8: =(D8-O8-J8+Q8)*Z8 -> 119.10072 | AE8: 0.2352251 | AF8: 0.75170204 | AG8: 0.23728814 | AH8: 0.0033333333 | AI8: 0.03557047 | AJ8: 0.11858697 | AK8: 0.15268456 | AL8: 0.009538687 | AM8: 0.011601398 | AN8: 0.0083892617 | AO8: 0.011719895 | AP8: 0.0033485415 | AQ8: 0
A9: ARI | B9: Ketel Marte | D9: 537 | E9: 614 | F9: =AD9+J9 -> 147.50059 | G9: =$AD9*AF9 -> 86.550684 | H9: =$AD9*AG9 -> 31.554252 | I9: =$AD9*AH9 -> 3.0176239 | J9: =$E9*AI9 -> 27.2 | K9: =$E9*AJ9 -> 86.806907 | L9: =$E9*AK9 -> 89 | M9: =$E9*(AB9/100) -> 64.958085 | N9: =$E9*AL9 -> 4.0819466 | O9: =$E9*(AA9/100) -> 110.84772 | P9: =$E9*AM9 -> 5.9348432 | Q9: =$E9*AN9 -> 4.4 | R9: =$E9*AQ9 -> 0 | S9: =$E9*AO9 -> 6.9747253 | T9: =$E9*AP9 -> 1.9927786 | U9: =S9-T9 -> 4.9819466 | V9: =F9/D9 -> 0.27467521 | W9: =(F9+M9+N9+P9)/(D9+M9+N9+Q9) -> 0.36445097 | X9: =(G9+H9*2+I9*3+J9*4)/D9 -> 0.49816026 | Y9: =W9+X9 -> 0.86261123 | Z9: 0.29825191 | AA9: 18.053375 | AB9: 10.579493 | AD9: =(D9-O9-J9+Q9)*Z9 -> 120.30059 | AE9: 0.24208525 | AF9: 0.71945355 | AG9: 0.26229508 | AH9: 0.025084034 | AI9: 0.044299674 | AJ9: 0.14137933 | AK9: 0.14495114 | AL9: 0.0066481215 | AM9: 0.0096658684 | AN9: 0.0071661238 | AO9: 0.011359487 | AP9: 0.0032455678 | AQ9: 0
A10: ARI | B10: Lourdes Gurriel Jr. | D10: 518 | E10: 560 | F10: =AD10+J10 -> 140.2344 | G10: =$AD10*AF10 -> 94.919312 | H10: =$AD10*AG10 -> 26.920393 | I10: =$AD10*AH10 -> 1.9941032 | J10: =$E10*AI10 -> 16.6 | K10: =$E10*AJ10 -> 64.8 | L10: =$E10*AK10 -> 73 | M10: =$E10*(AB10/100) -> 32 | N10: =$E10*AL10 -> 0.6 | O10: =$E10*(AA10/100) -> 102 | P10: =$E10*AM10 -> 5.0343511 | Q10: =$E10*AN10 -> 4.6 | R10: =$E10*AQ10 -> 0 | S10: =$E10*AO10 -> 5.9 | T10: =$E10*AP10 -> 1.9 | U10: =S10-T10 -> 4 | V10: =F10/D10 -> 0.27072278 | W10: =(F10+M10+N10+P10)/(D10+M10+N10+Q10) -> 0.32036878 | X10: =(G10+H10*2+I10*3+J10*4)/D10 -> 0.42691585 | Y10: =W10+X10 -> 0.74728463 | Z10: 0.30602574 | AA10: 18.214286 | AB10: 5.7142857 | AD10: =(D10-O10-J10+Q10)*Z10 -> 123.6344 | AE10: 0.2523001 | AF10: 0.76774194 | AG10: 0.21774194 | AH10: 0.016129032 | AI10: 0.029642857 | AJ10: 0.11571429 | AK10: 0.13035714 | AL10: 0.0010714286 | AM10: 0.0089899128 | AN10: 0.0082142857 | AO10: 0.010535714 | AP10: 0.0033928571 | AQ10: 0
A11: ARI | B11: Pavin Smith | D11: 263 | E11: 300 | F11: =AD11+J11 -> 62.88815 | G11: =$AD11*AF11 -> 39.072922 | H11: =$AD11*AG11 -> 12.732332 | I11: =$AD11*AH11 -> 0.99049784 | J11: =$E11*AI11 -> 10 | K11: =$E11*AJ11 -> 35.085714 | L11: =$E11*AK11 -> 39 | M11: =$E11*(AB11/100) -> 30.342857 | N11: =$E11*AL11 -> 0.98571429 | O11: =$E11*(AA11/100) -> 63.428571 | P11: =$E11*AM11 -> 1.9348315 | Q11: =$E11*AN11 -> 2 | R11: =$E11*AQ11 -> 0 | S11: =$E11*AO11 -> 1.9714286 | T11: =$E11*AP11 -> 0.085714286 | U11: =S11-T11 -> 1.8857143 | V11: =F11/D11 -> 0.23911844 | W11: =(F11+M11+N11+P11)/(D11+M11+N11+Q11) -> 0.32447615 | X11: =(G11+H11*2+I11*3+J11*4)/D11 -> 0.40877977 | Y11: =W11+X11 -> 0.73325592 | Z11: 0.27607535 | AA11: 21.142857 | AB11: 10.114286 | AD11: =(D11-O11-J11+Q11)*Z11 -> 52.88815 | AE11: 0.21231818 | AF11: 0.73878407 | AG11: 0.24074074 | AH11: 0.018728162 | AI11: 0.033333333 | AJ11: 0.11695238 | AK11: 0.13 | AL11: 0.0032857143 | AM11: 0.0064494382 | AN11: 0.0066666667 | AO11: 0.0065714286 | AP11: 0.00028571429 | AQ11: 0
A12: ATH | B12: Brent Rooker | D12: 533 | E12: 603 | F12: =AD12+J12 -> 133.27806 | G12: =$AD12*AF12 -> 71.811174 | H12: =$AD12*AG12 -> 25.070933 | I12: =$AD12*AH12 -> 1.584607 | J12: =$E12*AI12 -> 35 | K12: =$E12*AJ12 -> 81.514907 | L12: =$E12*AK12 -> 92 | M12: =$E12*(AB12/100) -> 55.398913 | N12: =$E12*AL12 -> 3.3809006 | O12: =$E12*(AA12/100) -> 177.90373 | P12: =$E12*AM12 -> 9.7154237 | Q12: =$E12*AN12 -> 4 | R12: =$E12*AQ12 -> 0 | S12: =$E12*AO12 -> 7.9490683 | T12: =$E12*AP12 -> 1.9872671 | U12: =S12-T12 -> 5.9618012 | V12: =F12/D12 -> 0.25005264 | W12: =(F12+M12+N12+P12)/(D12+M12+N12+Q12) -> 0.33867091 | X12: =(G12+H12*2+I12*3+J12*4)/D12 -> 0.50038811 | Y12: =W12+X12 -> 0.83905902 | Z12: 0.30323723 | AA12: 29.503106 | AB12: 9.1872161 | AD12: =(D12-O12-J12+Q12)*Z12 -> 98.278056 | AE12: 0.2214069 | AF12: 0.73069388 | AG12: 0.25510204 | AH12: 0.016123711 | AI12: 0.058043118 | AJ12: 0.13518227 | AK12: 0.15257048 | AL12: 0.0056068004 | AM12: 0.016111814 | AN12: 0.0066334992 | AO12: 0.013182535 | AP12: 0.0032956336 | AQ12: 0
A13: ATH | B13: Jacob Wilson | D13: 450 | E13: 489 | F13: =AD13+J13 -> 123.35153 | G13: =$AD13*AF13 -> 90.640509 | H13: =$AD13*AG13 -> 23.267975 | I13: =$AD13*AH13 -> 2.0097638 | J13: =$E13*AI13 -> 6 | K13: =$E13*AJ13 -> 58.015385 | L13: =$E13*AK13 -> 45 | M13: =$E13*(AB13/100) -> 24.465934 | N13: =$E13*AL13 -> 0.9 | O13: =$E13*(AA13/100) -> 48.362637 | P13: =$E13*AM13 -> 5.2640625 | Q13: =$E13*AN13 -> 3.4 | R13: =$E13*AQ13 -> 3.03375 | S13: =$E13*AO13 -> 3.9582418 | T13: =$E13*AP13 -> 1.0791209 | U13: =S13-T13 -> 2.8791209 | V13: =F13/D13 -> 0.27411451 | W13: =(F13+M13+N13+P13)/(D13+M13+N13+Q13) -> 0.32162172 | X13: =(G13+H13*2+I13*3+J13*4)/D13 -> 0.37156834 | Y13: =W13+X13 -> 0.69319006 | Z13: 0.29408657 | AA13: 9.8901099 | AB13: 5.0032585 | AD13: =(D13-O13-J13+Q13)*Z13 -> 117.35153 | AE13: 0.25453689 | AF13: 0.77238457 | AG13: 0.19827586 | AH13: 0.017126013 | AI13: 0.012269939 | AJ13: 0.11864087 | AK13: 0.09202454 | AL13: 0.0018404908 | AM13: 0.010764954 | AN13: 0.0069529652 | AO13: 0.0080945639 | AP13: 0.0022067912 | AQ13: 0.0062039877
A14: ATH | B14: JJ Bleday | D14: 522 | E14: 597 | F14: =AD14+J14 -> 117.8466 | G14: =$AD14*AF14 -> 66.18205 | H14: =$AD14*AG14 -> 27.556171 | I14: =$AD14*AH14 -> 2.5314747 | J14: =$E14*AI14 -> 21.4 | K14: =$E14*AJ14 -> 71.005775 | L14: =$E14*AK14 -> 66 | M14: =$E14*(AB14/100) -> 65.48617 | N14: =$E14*AL14 -> 0.99072948 | O14: =$E14*(AA14/100) -> 127.92857 | P14: =$E14*AM14 -> 3.9035593 | Q14: =$E14*AN14 -> 4.2 | R14: =$E14*AQ14 -> 1.0071186 | S14: =$E14*AO14 -> 4.0536474 | T14: =$E14*AP14 -> 1.981459 | U14: =S14-T14 -> 2.0721884 | V14: =F14/D14 -> 0.22575977 | W14: =(F14+M14+N14+P14)/(D14+M14+N14+Q14) -> 0.31758798 | X14: =(G14+H14*2+I14*3+J14*4)/D14 -> 0.41089812 | Y14: =W14+X14 -> 0.7284861 | Z14: 0.2559138 | AA14: 21.428571 | AB14: 10.969208 | AD14: =(D14-O14-J14+Q14)*Z14 -> 96.4466 | AE14: 0.20187876 | AF14: 0.68620408 | AG14: 0.28571429 | AH14: 0.026247423 | AI14: 0.035845896 | AJ14: 0.11893765 | AK14: 0.11055276 | AL14: 0.0016595134 | AM14: 0.0065386253 | AN14: 0.0070351759 | AO14: 0.0067900292 | AP14: 0.0033190267 | AQ14: 0.0016869659
A15: ATH | B15: Lawrence Butler | D15: 534 | E15: 585 | F15: =AD15+J15 -> 132.40162 | G15: =$AD15*AF15 -> 79.22761 | H15: =$AD15*AG15 -> 26.743258 | I15: =$AD15*AH15 -> 2.5986195 | J15: =$E15*AI15 -> 24.4 | K15: =$E15*AJ15 -> 77.417702 | L15: =$E15*AK15 -> 69 | M15: =$E15*(AB15/100) -> 46.032764 | N15: =$E15*AL15 -> 1.3908385 | O15: =$E15*(AA15/100) -> 139.8913 | P15: =$E15*AM15 -> 1.9073394 | Q15: =$E15*AN15 -> 4 | R15: =$E15*AQ15 -> 0.4 | S15: =$E15*AO15 -> 18.91677 | T15: =$E15*AP15 -> 2.9725155 | U15: =S15-T15 -> 15.944255 | V15: =F15/D15 -> 0.24794311 | W15: =(F15+M15+N15+P15)/(D15+M15+N15+Q15) -> 0.31042917 | X15: =(G15+H15*2+I15*3+J15*4)/D15 -> 0.44589885 | Y15: =W15+X15 -> 0.75632802 | Z15: 0.28899948 | AA15: 23.913043 | AB15: 7.8688485 | AD15: =(D15-O15-J15+Q15)*Z15 -> 108.00162 | AE15: 0.22826485 | AF15: 0.73357798 | AG15: 0.24761905 | AH15: 0.024060931 | AI15: 0.041709402 | AJ15: 0.13233795 | AK15: 0.11794872 | AL15: 0.0023775017 | AM15: 0.0032604093 | AN15: 0.0068376068 | AO15: 0.032336359 | AP15: 0.0050812231 | AQ15: 0.00068376068
A16: ATH | B16: Shea Langeliers | D16: 454 | E16: 500 | F16: =AD16+J16 -> 104.27055 | G16: =$AD16*AF16 -> 56.48616 | H16: =$AD16*AG16 -> 21.072841 | I16: =$AD16*AH16 -> 2.0225757 | J16: =$E16*AI16 -> 26 | K16: =$E16*AJ16 -> 60.566008 | L16: =$E16*AK16 -> 70 | M16: =$E16*(AB16/100) -> 37.153755 | N16: =$E16*AL16 -> 1.0976285 | O16: =$E16*(AA16/100) -> 135.37549 | P16: =$E16*AM16 -> 4.983559 | Q16: =$E16*AN16 -> 4 | R16: =$E16*AQ16 -> 0 | S16: =$E16*AO16 -> 3.0952569 | T16: =$E16*AP16 -> 1.0976285 | U16: =S16-T16 -> 1.9976285 | V16: =F16/D16 -> 0.22967082 | W16: =(F16+M16+N16+P16)/(D16+M16+N16+Q16) -> 0.29723946 | X16: =(G16+H16*2+I16*3+J16*4)/D16 -> 0.45969068 | Y16: =W16+X16 -> 0.75693014 | Z16: 0.26387082 | AA16: 27.075099 | AB16: 7.430751 | AD16: =(D16-O16-J16+Q16)*Z16 -> 78.270552 | AE16: 0.20737774 | AF16: 0.72167832 | AG16: 0.26923077 | AH16: 0.025840826 | AI16: 0.052 | AJ16: 0.12113202 | AK16: 0.14 | AL16: 0.0021952569 | AM16: 0.009967118 | AN16: 0.008 | AO16: 0.0061905138 | AP16: 0.0021952569 | AQ16: 0
A17: ATH | B17: Tyler Soderstrom | D17: 463 | E17: 511 | F17: =AD17+J17 -> 107.6487 | G17: =$AD17*AF17 -> 63.983622 | H17: =$AD17*AG17 -> 20.963055 | I17: =$AD17*AH17 -> 1.6451799 | J17: =$E17*AI17 -> 21.8 | K17: =$E17*AJ17 -> 56.226316 | L17: =$E17*AK17 -> 65 | M17: =$E17*(AB17/100) -> 39.938158 | N17: =$E17*AL17 -> 1.9921053 | O17: =$E17*(AA17/100) -> 136.39474 | P17: =$E17*AM17 -> 5.060307 | Q17: =$E17*AN17 -> 4 | R17: =$E17*AQ17 -> 0 | S17: =$E17*AO17 -> 0.99605263 | T17: =$E17*AP17 -> 0.99605263 | U17: =S17-T17 -> 0 | V17: =F17/D17 -> 0.2325026 | W17: =(F17+M17+N17+P17)/(D17+M17+N17+Q17) -> 0.30385159 | X17: =(G17+H17*2+I17*3+J17*4)/D17 -> 0.42774357 | Y17: =W17+X17 -> 0.73159516 | Z17: 0.27800272 | AA17: 26.691729 | AB17: 7.8156865 | AD17: =(D17-O17-J17+Q17)*Z17 -> 85.848702 | AE17: 0.20821053 | AF17: 0.74530681 | AG17: 0.24418605 | AH17: 0.019163714 | AI17: 0.042661448 | AJ17: 0.11003193 | AK17: 0.12720157 | AL17: 0.0038984447 | AM17: 0.0099027535 | AN17: 0.0078277886 | AO17: 0.0019492224 | AP17: 0.0019492224 | AQ17: 0
A18: ATH | B18: Zack Gelof | D18: 528 | E18: 582 | F18: =AD18+J18 -> 118.7838 | G18: =$AD18*AF18 -> 72.428095 | H18: =$AD18*AG18 -> 24.044557 | I18: =$AD18*AH18 -> 2.0325062 | J18: =$E18*AI18 -> 19.6 | K18: =$E18*AJ18 -> 69.262857 | L18: =$E18*AK18 -> 60 | M18: =$E18*(AB18/100) -> 42.419048 | N18: =$E18*AL18 -> 0 | O18: =$E18*(AA18/100) -> 181.99048 | P18: =$E18*AM18 -> 4.8180328 | Q18: =$E18*AN18 -> 3.4 | R18: =$E18*AQ18 -> 2.0721311 | S18: =$E18*AO18 -> 23.009524 | T18: =$E18*AP18 -> 4.9619048 | U18: =S18-T18 -> 18.047619 | V18: =F18/D18 -> 0.22496932 | W18: =(F18+M18+N18+P18)/(D18+M18+N18+Q18) -> 0.28932619 | X18: =(G18+H18*2+I18*3+J18*4)/D18 -> 0.38828547 | Y18: =W18+X18 -> 0.67761166 | Z18: 0.30073055 | AA18: 31.269841 | AB18: 7.2884962 | AD18: =(D18-O18-J18+Q18)*Z18 -> 99.183799 | AE18: 0.20247869 | AF18: 0.73024119 | AG18: 0.24242424 | AH18: 0.020492321 | AI18: 0.033676976 | AJ18: 0.11900835 | AK18: 0.10309278 | AL18: 0 | AM18: 0.0082784069 | AN18: 0.0058419244 | AO18: 0.039535264 | AP18: 0.0085256096 | AQ18: 0.0035603628
... A229: WSN | B229: Nathaniel Lowe | D229: 520 | E229: 595 | F229: =AD229+J229 -> 133.10009 | G229: =$AD229*AF229 -> 95.197425 | H229: =$AD229*AG229 -> 22.242389 | I229: =$AD229*AH229 -> 1.9950183 | J229: =$E229*AI229 -> 13.8 | K229: =$E229*AJ229 -> 65.31236 | L229: =$E229*AK229 -> 69 | M229: =$E229*(AB229/100) -> 66.794382 | N229: =$E229*AL229 -> 1.8955056 | O229: =$E229*(AA229/100) -> 127.97753 | P229: =$E229*AM229 -> 3.9920923 | Q229: =$E229*AN229 -> 3.6 | R229: =$E229*AQ229 -> 0 | S229: =$E229*AO229 -> 1.9910112 | T229: =$E229*AP229 -> 0.99550562 | U229: =S229-T229 -> 0.99550562 | V229: =F229/D229 -> 0.25596171 | W229: =(F229+M229+N229+P229)/(D229+M229+N229+Q229) -> 0.34743471 | X229: =(G229+H229*2+I229*3+J229*4)/D229 -> 0.38628319 | Y229: =W229+X229 -> 0.7337179 | Z229: 0.3124491 | AA229: 21.508828 | AB229: 11.225947 | AD229: =(D229-O229-J229+Q229)*Z229 -> 119.30009 | AE229: 0.22415258 | AF229: 0.7979661 | AG229: 0.18644068 | AH229: 0.016722689 | AI229: 0.023193277 | AJ229: 0.10976867 | AK229: 0.11596639 | AL229: 0.0031857237 | AM229: 0.0067093988 | AN229: 0.0060504202 | AO229: 0.0033462374 | AP229: 0.0016731187 | AQ229: 0

Sheet Fantasy Rank
A1: ='2025_Fantasy_Hitters_modified'!A1 -> Team | B1: ='2025_Fantasy_Hitters_modified'!B1 -> Name | C1: ='2025_Fantasy_Hitters_modified'!D1 -> AB | D1: ='2025_Fantasy_Hitters_modified'!E1 -> PA | E1: H | F1: H+ | G1: HR | H1: HR+ | I1: R | J1: RBI | K1: BB | L1: HBP | M1: SB | N1: CS | O1: NSB | P1: AVG | Q1: OBP | R1: SLG | S1: OPS | T1: Total | V1: ='2025_Fantasy_Hitters_modified'!F1 -> H | W1: ='2025_Fantasy_Hitters_modified'!G1 -> 1B | X1: ='2025_Fantasy_Hitters_modified'!H1 -> 2B | Y1: ='2025_Fantasy_Hitters_modified'!I1 -> 3B | Z1: ='2025_Fantasy_Hitters_modified'!J1 -> HR | AA1: ='2025_Fantasy_Hitters_modified'!K1 -> R | AB1: ='2025_Fantasy_Hitters_modified'!L1 -> RBI | AC1: ='2025_Fantasy_Hitters_modified'!M1 -> BB | ... AR1: ='2025_Fantasy_Hitters_modified'!AB1 -> BB%
A2: ='2025_Fantasy_Hitters_modified'!A114 -> LAD | B2: ='2025_Fantasy_Hitters_modified'!B114 -> Shohei Ohtani | C2: ='2025_Fantasy_Hitters_modified'!D114 -> 555 | D2: ='2025_Fantasy_Hitters_modified'!E114 -> 645 | E2: =(V2-AVERAGE(V$2:V$229))/AVERAGE(V$2:V$229)*100+100 -> 135.33082 | F2: =E2*1.51744-31.775 -> 173.5814 | G2: =(Z2-AVERAGE(Z$2:Z$229))/AVERAGE(Z$2:Z$229)*100+100 -> 226.98023 | H2: =G2*0.83285-13.6979 -> 175.34259 | I2: =(AA2-AVERAGE(AA$2:AA$229))/AVERAGE(AA$2:AA$229)*100+100 -> 177.6435 | J2: =(AB2-AVERAGE(AB$2:AB$229))/AVERAGE(AB$2:AB$229)*100+100 -> 163.7147 | K2: =(AC2-AVERAGE(AC$2:AC$229))/AVERAGE(AC$2:AC$229)*100+100 -> 176.65142 | L2: =(AF2-AVERAGE(AF$2:AF$229))/AVERAGE(AF$2:AF$229)*100+100 -> 84.892014 | M2: =(AI2-AVERAGE(AI$2:AI$229))/AVERAGE(AI$2:AI$229)*100+100 -> 326.52128 | N2: =(AVERAGE(AJ$2:AJ$229)-AJ2)/AVERAGE(AJ$2:AJ$229)*100+100 -> -87.167378 | O2: =(AK2-AVERAGE(AK$2:AK$229))/AVERAGE(AK$2:AK$229)*100+100 -> 340.30474 | P2: =(AL2-AVERAGE(AL$2:AL$229))/AVERAGE(AL$2:AL$229)*100+100 -> 114.81453 | Q2: =(AM2-AVERAGE(AM$2:AM$229))/AVERAGE(AM$2:AM$229)*100+100 -> 119.93377 | R2: =(AN2-AVERAGE(AN$2:AN$229))/AVERAGE(AN$2:AN$229)*100+100 -> 139.03608 | S2: =(AO2-AVERAGE(AO$2:AO$229))/AVERAGE(AO$2:AO$229)*100+100 -> 130.70201 | T2: =(F2*1.5+H2*2.5+I2+J2+K2*1.5+L2+O2*0.75+P2+S2)/11.25 -> 168.06231 | V2: ='2025_Fantasy_Hitters_modified'!F114 -> 158.97429 | W2: ='2025_Fantasy_Hitters_modified'!G114 -> 82.700559 | X2: ='2025_Fantasy_Hitters_modified'!H114 -> 30.888161 | Y2: ='2025_Fantasy_Hitters_modified'!I114 -> 5.360423 | Z2: ='2025_Fantasy_Hitters_modified'!J114 -> 41.4 | AA2: ='2025_Fantasy_Hitters_modified'!K114 -> 117.14194 | AB2: ='2025_Fantasy_Hitters_modified'!L114 -> 105 | AC2: ='2025_Fantasy_Hitters_modified'!M114 -> 80.727189 | ... AR2: ='2025_Fantasy_Hitters_modified'!AB114 -> 12.515843
A3: ='2025_Fantasy_Hitters_modified'!A146 -> NYY | B3: ='2025_Fantasy_Hitters_modified'!B146 -> Aaron Judge | C3: ='2025_Fantasy_Hitters_modified'!D146 -> 516 | D3: ='2025_Fantasy_Hitters_modified'!E146 -> 638 | E3: =(V3-AVERAGE(V$2:V$229))/AVERAGE(V$2:V$229)*100+100 -> 122.52821 | F3: =E3*1.51744-31.775 -> 154.15421 | G3: =(Z3-AVERAGE(Z$2:Z$229))/AVERAGE(Z$2:Z$229)*100+100 -> 256.58635 | H3: =G3*0.83285-13.6979 -> 200.00004 | I3: =(AA3-AVERAGE(AA$2:AA$229))/AVERAGE(AA$2:AA$229)*100+100 -> 160.1616 | J3: =(AB3-AVERAGE(AB$2:AB$229))/AVERAGE(AB$2:AB$229)*100+100 -> 179.30657 | K3: =(AC3-AVERAGE(AC$2:AC$229))/AVERAGE(AC$2:AC$229)*100+100 -> 232.36683 | L3: =(AF3-AVERAGE(AF$2:AF$229))/AVERAGE(AF$2:AF$229)*100+100 -> 100.73115 | M3: =(AI3-AVERAGE(AI$2:AI$229))/AVERAGE(AI$2:AI$229)*100+100 -> 75.918468 | N3: =(AVERAGE(AJ$2:AJ$229)-AJ3)/AVERAGE(AJ$2:AJ$229)*100+100 -> 126.83068 | O3: =(AK3-AVERAGE(AK$2:AK$229))/AVERAGE(AK$2:AK$229)*100+100 -> 76.88134 | P3: =(AL3-AVERAGE(AL$2:AL$229))/AVERAGE(AL$2:AL$229)*100+100 -> 111.80971 | Q3: =(AM3-AVERAGE(AM$2:AM$229))/AVERAGE(AM$2:AM$229)*100+100 -> 127.92715 | R3: =(AN3-AVERAGE(AN$2:AN$229))/AVERAGE(AN$2:AN$229)*100+100 -> 143.53141 | S3: =(AO3-AVERAGE(AO$2:AO$229))/AVERAGE(AO$2:AO$229)*100+100 -> 136.72349 | T3: =(F3*1.5+H3*2.5+I3+J3+K3*1.5+L3+O3*0.75+P3+S3)/11.25 -> 162.32668 | V3: ='2025_Fantasy_Hitters_modified'!F146 -> 143.93496 | W3: ='2025_Fantasy_Hitters_modified'!G146 -> 71.364458 | X3: ='2025_Fantasy_Hitters_modified'!H146 -> 25.770499 | Y3: ='2025_Fantasy_Hitters_modified'!I146 -> 0.97927895 | Z3: ='2025_Fantasy_Hitters_modified'!J146 -> 46.8 | AA3: ='2025_Fantasy_Hitters_modified'!K146 -> 105.61399 | AB3: ='2025_Fantasy_Hitters_modified'!L146 -> 115 | AC3: ='2025_Fantasy_Hitters_modified'!M146 -> 106.18834 | ... AR3: ='2025_Fantasy_Hitters_modified'!AB146 -> 16.64394
A4: ='2025_Fantasy_Hitters_modified'!A143 -> NYM | B4: ='2025_Fantasy_Hitters_modified'!B143 -> Juan Soto | C4: ='2025_Fantasy_Hitters_modified'!D143 -> 537 | D4: ='2025_Fantasy_Hitters_modified'!E143 -> 674 | E4: =(V4-AVERAGE(V$2:V$229))/AVERAGE(V$2:V$229)*100+100 -> 124.63781 | F4: =E4*1.51744-31.775 -> 157.3554 | G4: =(Z4-AVERAGE(Z$2:Z$229))/AVERAGE(Z$2:Z$229)*100+100 -> 186.40889 | H4: =G4*0.83285-13.6979 -> 141.55274 | I4: =(AA4-AVERAGE(AA$2:AA$229))/AVERAGE(AA$2:AA$229)*100+100 -> 164.71104 | J4: =(AB4-AVERAGE(AB$2:AB$229))/AVERAGE(AB$2:AB$229)*100+100 -> 149.68201 | K4: =(AC4-AVERAGE(AC$2:AC$229))/AVERAGE(AC$2:AC$229)*100+100 -> 279.14183 | L4: =(AF4-AVERAGE(AF$2:AF$229))/AVERAGE(AF$2:AF$229)*100+100 -> 81.933207 | M4: =(AI4-AVERAGE(AI$2:AI$229))/AVERAGE(AI$2:AI$229)*100+100 -> 76.319681 | N4: =(AVERAGE(AJ$2:AJ$229)-AJ4)/AVERAGE(AJ$2:AJ$229)*100+100 -> 86.046193 | O4: =(AK4-AVERAGE(AK$2:AK$229))/AVERAGE(AK$2:AK$229)*100+100 -> 63.138556 | P4: =(AL4-AVERAGE(AL$2:AL$229))/AVERAGE(AL$2:AL$229)*100+100 -> 109.28704 | Q4: =(AM4-AVERAGE(AM$2:AM$229))/AVERAGE(AM$2:AM$229)*100+100 -> 129.30986 | R4: =(AN4-AVERAGE(AN$2:AN$229))/AVERAGE(AN$2:AN$229)*100+100 -> 123.66921 | S4: =(AO4-AVERAGE(AO$2:AO$229))/AVERAGE(AO$2:AO$229)*100+100 -> 126.13014 | T4: =(F4*1.5+H4*2.5+I4+J4+K4*1.5+L4+O4*0.75+P4+S4)/11.25 -> 150.02001 | V4: ='2025_Fantasy_Hitters_modified'!F143 -> 146.41312 | W4: ='2025_Fantasy_Hitters_modified'!G143 -> 82.513769 | X4: ='2025_Fantasy_Hitters_modified'!H143 -> 28.103281 | Y4: ='2025_Fantasy_Hitters_modified'!I143 -> 1.9934807 | Z4: ='2025_Fantasy_Hitters_modified'!J143 -> 34 | AA4: ='2025_Fantasy_Hitters_modified'!K143 -> 108.61399 | AB4: ='2025_Fantasy_Hitters_modified'!L143 -> 96 | AC4: ='2025_Fantasy_Hitters_modified'!M143 -> 127.56385 | ... AR4: ='2025_Fantasy_Hitters_modified'!AB143 -> 18.926387
A5: ='2025_Fantasy_Hitters_modified'!A61 -> CIN | B5: ='2025_Fantasy_Hitters_modified'!B61 -> Elly De La Cruz | C5: ='2025_Fantasy_Hitters_modified'!D61 -> 580 | D5: ='2025_Fantasy_Hitters_modified'!E61 -> 648 | E5: =(V5-AVERAGE(V$2:V$229))/AVERAGE(V$2:V$229)*100+100 -> 127.93761 | F5: =E5*1.51744-31.775 -> 162.36265 | G5: =(Z5-AVERAGE(Z$2:Z$229))/AVERAGE(Z$2:Z$229)*100+100 -> 133.77579 | H5: =G5*0.83285-13.6979 -> 97.717267 | I5: =(AA5-AVERAGE(AA$2:AA$229))/AVERAGE(AA$2:AA$229)*100+100 -> 150.20868 | J5: =(AB5-AVERAGE(AB$2:AB$229))/AVERAGE(AB$2:AB$229)*100+100 -> 120.05744 | K5: =(AC5-AVERAGE(AC$2:AC$229))/AVERAGE(AC$2:AC$229)*100+100 -> 129.4165 | L5: =(AF5-AVERAGE(AF$2:AF$229))/AVERAGE(AF$2:AF$229)*100+100 -> 83.4601 | M5: =(AI5-AVERAGE(AI$2:AI$229))/AVERAGE(AI$2:AI$229)*100+100 -> 514.74132 | N5: =(AVERAGE(AJ$2:AJ$229)-AJ5)/AVERAGE(AJ$2:AJ$229)*100+100 -> -248.15933 | O5: =(AK5-AVERAGE(AK$2:AK$229))/AVERAGE(AK$2:AK$229)*100+100 -> 538.06127 | P5: =(AL5-AVERAGE(AL$2:AL$229))/AVERAGE(AL$2:AL$229)*100+100 -> 103.8636 | Q5: =(AM5-AVERAGE(AM$2:AM$229))/AVERAGE(AM$2:AM$229)*100+100 -> 102.78366 | R5: =(AN5-AVERAGE(AN$2:AN$229))/AVERAGE(AN$2:AN$229)*100+100 -> 110.95543 | S5: =(AO5-AVERAGE(AO$2:AO$229))/AVERAGE(AO$2:AO$229)*100+100 -> 107.3902 | T5: =(F5*1.5+H5*2.5+I5+J5+K5*1.5+L5+O5*0.75+P5+S5)/11.25 -> 146.71003 | V5: ='2025_Fantasy_Hitters_modified'!F61 -> 150.28943 | W5: ='2025_Fantasy_Hitters_modified'!G61 -> 88.043741 | X5: ='2025_Fantasy_Hitters_modified'!H61 -> 33.020178 | Y5: ='2025_Fantasy_Hitters_modified'!I61 -> 6.7751768 | Z5: ='2025_Fantasy_Hitters_modified'!J61 -> 24.4 | AA5: ='2025_Fantasy_Hitters_modified'!K61 -> 99.050827 | AB5: ='2025_Fantasy_Hitters_modified'!L61 -> 77 | AC5: ='2025_Fantasy_Hitters_modified'!M61 -> 59.141504 | ... AR5: ='2025_Fantasy_Hitters_modified'!AB61 -> 9.1267753
A6: ='2025_Fantasy_Hitters_modified'!A94 -> KCR | B6: ='2025_Fantasy_Hitters_modified'!B94 -> Bobby Witt Jr. | C6: ='2025_Fantasy_Hitters_modified'!D94 -> 606 | D6: ='2025_Fantasy_Hitters_modified'!E94 -> 668 | E6: =(V6-AVERAGE(V$2:V$229))/AVERAGE(V$2:V$229)*100+100 -> 152.40015 | F6: =E6*1.51744-31.775 -> 199.48309 | G6: =(Z6-AVERAGE(Z$2:Z$229))/AVERAGE(Z$2:Z$229)*100+100 -> 168.86452 | H6: =G6*0.83285-13.6979 -> 126.94092 | I6: =(AA6-AVERAGE(AA$2:AA$229))/AVERAGE(AA$2:AA$229)*100+100 -> 161.80807 | J6: =(AB6-AVERAGE(AB$2:AB$229))/AVERAGE(AB$2:AB$229)*100+100 -> 149.68201 | K6: =(AC6-AVERAGE(AC$2:AC$229))/AVERAGE(AC$2:AC$229)*100+100 -> 105.18665 | L6: =(AF6-AVERAGE(AF$2:AF$229))/AVERAGE(AF$2:AF$229)*100+100 -> 102.39746 | M6: =(AI6-AVERAGE(AI$2:AI$229))/AVERAGE(AI$2:AI$229)*100+100 -> 313.61226 | N6: =(AVERAGE(AJ$2:AJ$229)-AJ6)/AVERAGE(AJ$2:AJ$229)*100+100 -> -171.04537 | O6: =(AK6-AVERAGE(AK$2:AK$229))/AVERAGE(AK$2:AK$229)*100+100 -> 293.49666 | P6: =(AL6-AVERAGE(AL$2:AL$229))/AVERAGE(AL$2:AL$229)*100+100 -> 118.41478 | Q6: =(AM6-AVERAGE(AM$2:AM$229))/AVERAGE(AM$2:AM$229)*100+100 -> 109.43287 | R6: =(AN6-AVERAGE(AN$2:AN$229))/AVERAGE(AN$2:AN$229)*100+100 -> 127.47227 | S6: =(AO6-AVERAGE(AO$2:AO$229))/AVERAGE(AO$2:AO$229)*100+100 -> 119.60194 | T6: =(F6*1.5+H6*2.5+I6+J6+K6*1.5+L6+O6*0.75+P6+S6)/11.25 -> 146.34521 | V6: ='2025_Fantasy_Hitters_modified'!F94 -> 179.02579 | W6: ='2025_Fantasy_Hitters_modified'!G94 -> 105.16019 | X6: ='2025_Fantasy_Hitters_modified'!H94 -> 37.056447 | Y6: ='2025_Fantasy_Hitters_modified'!I94 -> 8.0122048 | Z6: ='2025_Fantasy_Hitters_modified'!J94 -> 30.8 | AA6: ='2025_Fantasy_Hitters_modified'!K94 -> 106.69971 | AB6: ='2025_Fantasy_Hitters_modified'!L94 -> 96 | AC6: ='2025_Fantasy_Hitters_modified'!M94 -> 48.068805 | ... AR6: ='2025_Fantasy_Hitters_modified'!AB94 -> 7.1959288
A7: ='2025_Fantasy_Hitters_modified'!A3 -> ARI | B7: ='2025_Fantasy_Hitters_modified'!B3 -> Corbin Carroll | C7: ='2025_Fantasy_Hitters_modified'!D3 -> 567 | D7: ='2025_Fantasy_Hitters_modified'!E3 -> 653 | E7: =(V7-AVERAGE(V$2:V$229))/AVERAGE(V$2:V$229)*100+100 -> 124.93603 | F7: =E7*1.51744-31.775 -> 157.80793 | G7: =(Z7-AVERAGE(Z$2:Z$229))/AVERAGE(Z$2:Z$229)*100+100 -> 119.52099 | H7: =G7*0.83285-13.6979 -> 85.845159 | I7: =(AA7-AVERAGE(AA$2:AA$229))/AVERAGE(AA$2:AA$229)*100+100 -> 154.9356 | J7: =(AB7-AVERAGE(AB$2:AB$229))/AVERAGE(AB$2:AB$229)*100+100 -> 116.93907 | K7: =(AC7-AVERAGE(AC$2:AC$229))/AVERAGE(AC$2:AC$229)*100+100 -> 146.83626 | L7: =(AF7-AVERAGE(AF$2:AF$229))/AVERAGE(AF$2:AF$229)*100+100 -> 158.56045 | M7: =(AI7-AVERAGE(AI$2:AI$229))/AVERAGE(AI$2:AI$229)*100+100 -> 370.72797 | N7: =(AVERAGE(AJ$2:AJ$229)-AJ7)/AVERAGE(AJ$2:AJ$229)*100+100 -> -57.167981 | O7: =(AK7-AVERAGE(AK$2:AK$229))/AVERAGE(AK$2:AK$229)*100+100 -> 410.50168 | P7: =(AL7-AVERAGE(AL$2:AL$229))/AVERAGE(AL$2:AL$229)*100+100 -> 103.7523 | Q7: =(AM7-AVERAGE(AM$2:AM$229))/AVERAGE(AM$2:AM$229)*100+100 -> 107.27254 | R7: =(AN7-AVERAGE(AN$2:AN$229))/AVERAGE(AN$2:AN$229)*100+100 -> 110.74138 | S7: =(AO7-AVERAGE(AO$2:AO$229))/AVERAGE(AO$2:AO$229)*100+100 -> 109.22798 | T7: =(F7*1.5+H7*2.5+I7+J7+K7*1.5+L7+O7*0.75+P7+S7)/11.25 -> 144.25518 | V7: ='2025_Fantasy_Hitters_modified'!F3 -> 146.76344 | W7: ='2025_Fantasy_Hitters_modified'!G3 -> 87.133857 | X7: ='2025_Fantasy_Hitters_modified'!H3 -> 30.990933 | Y7: ='2025_Fantasy_Hitters_modified'!I3 -> 9.6947246 | Z7: ='2025_Fantasy_Hitters_modified'!J3 -> 21.8 | AA7: ='2025_Fantasy_Hitters_modified'!K3 -> 102.16786 | AB7: ='2025_Fantasy_Hitters_modified'!L3 -> 75 | AC7: ='2025_Fantasy_Hitters_modified'!M3 -> 67.102083 | ... AR7: ='2025_Fantasy_Hitters_modified'!AB3 -> 10.27597
A8: ='2025_Fantasy_Hitters_modified'!A93 -> HOU | B8: ='2025_Fantasy_Hitters_modified'!B93 -> Yordan Alvarez | C8: ='2025_Fantasy_Hitters_modified'!D93 -> 503 | D8: ='2025_Fantasy_Hitters_modified'!E93 -> 591 | E8: =(V8-AVERAGE(V$2:V$229))/AVERAGE(V$2:V$229)*100+100 -> 127.08818 | F8: =E8*1.51744-31.775 -> 161.07369 | G8: =(Z8-AVERAGE(Z$2:Z$229))/AVERAGE(Z$2:Z$229)*100+100 -> 201.76021 | H8: =G8*0.83285-13.6979 -> 154.33809 | I8: =(AA8-AVERAGE(AA$2:AA$229))/AVERAGE(AA$2:AA$229)*100+100 -> 136.96719 | J8: =(AB8-AVERAGE(AB$2:AB$229))/AVERAGE(AB$2:AB$229)*100+100 -> 151.2412 | K8: =(AC8-AVERAGE(AC$2:AC$229))/AVERAGE(AC$2:AC$229)*100+100 -> 153.21868 | L8: =(AF8-AVERAGE(AF$2:AF$229))/AVERAGE(AF$2:AF$229)*100+100 -> 154.69033 | M8: =(AI8-AVERAGE(AI$2:AI$229))/AVERAGE(AI$2:AI$229)*100+100 -> 28.719378 | N8: =(AVERAGE(AJ$2:AJ$229)-AJ8)/AVERAGE(AJ$2:AJ$229)*100+100 -> 166.84179 | O8: =(AK8-AVERAGE(AK$2:AK$229))/AVERAGE(AK$2:AK$229)*100+100 -> 27.164706 | P8: =(AL8-AVERAGE(AL$2:AL$229))/AVERAGE(AL$2:AL$229)*100+100 -> 118.96804 | Q8: =(AM8-AVERAGE(AM$2:AM$229))/AVERAGE(AM$2:AM$229)*100+100 -> 123.83517 | R8: =(AN8-AVERAGE(AN$2:AN$229))/AVERAGE(AN$2:AN$229)*100+100 -> 137.20045 | S8: =(AO8-AVERAGE(AO$2:AO$229))/AVERAGE(AO$2:AO$229)*100+100 -> 131.36937 | T8: =(F8*1.5+H8*2.5+I8+J8+K8*1.5+L8+O8*0.75+P8+S8)/11.25 -> 139.63497 | V8: ='2025_Fantasy_Hitters_modified'!F93 -> 149.29159 | W8: ='2025_Fantasy_Hitters_modified'!G93 -> 81.011014 | X8: ='2025_Fantasy_Hitters_modified'!H93 -> 29.389695 | Y8: ='2025_Fantasy_Hitters_modified'!I93 -> 1.5687087 | Z8: ='2025_Fantasy_Hitters_modified'!J93 -> 36.8 | AA8: ='2025_Fantasy_Hitters_modified'!K93 -> 90.319105 | AB8: ='2025_Fantasy_Hitters_modified'!L93 -> 97 | AC8: ='2025_Fantasy_Hitters_modified'!M93 -> 70.018761 | ... AR8: ='2025_Fantasy_Hitters_modified'!AB93 -> 11.847506
A9: ='2025_Fantasy_Hitters_modified'!A145 -> NYM | B9: ='2025_Fantasy_Hitters_modified'!B145 -> Pete Alonso | C9: ='2025_Fantasy_Hitters_modified'!D145 -> 574 | D9: ='2025_Fantasy_Hitters_modified'!E145 -> 658 | E9: =(V9-AVERAGE(V$2:V$229))/AVERAGE(V$2:V$229)*100+100 -> 117.70363 | F9: =E9*1.51744-31.775 -> 146.8332 | G9: =(Z9-AVERAGE(Z$2:Z$229))/AVERAGE(Z$2:Z$229)*100+100 -> 197.37412 | H9: =G9*0.83285-13.6979 -> 150.68513 | I9: =(AA9-AVERAGE(AA$2:AA$229))/AVERAGE(AA$2:AA$229)*100+100 -> 130.1811 | J9: =(AB9-AVERAGE(AB$2:AB$229))/AVERAGE(AB$2:AB$229)*100+100 -> 157.47795 | K9: =(AC9-AVERAGE(AC$2:AC$229))/AVERAGE(AC$2:AC$229)*100+100 -> 140.98331 | L9: =(AF9-AVERAGE(AF$2:AF$229))/AVERAGE(AF$2:AF$229)*100+100 -> 239.25874 | M9: =(AI9-AVERAGE(AI$2:AI$229))/AVERAGE(AI$2:AI$229)*100+100 -> 38.186471 | N9: =(AVERAGE(AJ$2:AJ$229)-AJ9)/AVERAGE(AJ$2:AJ$229)*100+100 -> 163.19633 | O9: =(AK9-AVERAGE(AK$2:AK$229))/AVERAGE(AK$2:AK$229)*100+100 -> 38.670789 | P9: =(AL9-AVERAGE(AL$2:AL$229))/AVERAGE(AL$2:AL$229)*100+100 -> 96.554181 | Q9: =(AM9-AVERAGE(AM$2:AM$229))/AVERAGE(AM$2:AM$229)*100+100 -> 104.33454 | R9: =(AN9-AVERAGE(AN$2:AN$229))/AVERAGE(AN$2:AN$229)*100+100 -> 112.82818 | S9: =(AO9-AVERAGE(AO$2:AO$229))/AVERAGE(AO$2:AO$229)*100+100 -> 109.12253 | T9: =(F9*1.5+H9*2.5+I9+J9+K9*1.5+L9+O9*0.75+P9+S9)/11.25 -> 139.55868 | V9: ='2025_Fantasy_Hitters_modified'!F145 -> 138.26748 | W9: ='2025_Fantasy_Hitters_modified'!G145 -> 76.600348 | X9: ='2025_Fantasy_Hitters_modified'!H145 -> 25.065559 | Y9: ='2025_Fantasy_Hitters_modified'!I145 -> 1.0026224 | Z9: ='2025_Fantasy_Hitters_modified'!J145 -> 36 | AA9: ='2025_Fantasy_Hitters_modified'!K145 -> 85.844211 | AB9: ='2025_Fantasy_Hitters_modified'!L145 -> 101 | AC9: ='2025_Fantasy_Hitters_modified'!M145 -> 64.427368 | ... AR9: ='2025_Fantasy_Hitters_modified'!AB145 -> 9.7913934
A10: ='2025_Fantasy_Hitters_modified'!A140 -> NYM | B10: ='2025_Fantasy_Hitters_modified'!B140 -> Francisco Lindor | C10: ='2025_Fantasy_Hitters_modified'!D140 -> 596 | D10: ='2025_Fantasy_Hitters_modified'!E140 -> 671 | E10: =(V10-AVERAGE(V$2:V$229))/AVERAGE(V$2:V$229)*100+100 -> 129.50841 | F10: =E10*1.51744-31.775 -> 164.74625 | G10: =(Z10-AVERAGE(Z$2:Z$229))/AVERAGE(Z$2:Z$229)*100+100 -> 155.70625 | H10: =G10*0.83285-13.6979 -> 115.98205 | I10: =(AA10-AVERAGE(AA$2:AA$229))/AVERAGE(AA$2:AA$229)*100+100 -> 146.30238 | J10: =(AB10-AVERAGE(AB$2:AB$229))/AVERAGE(AB$2:AB$229)*100+100 -> 135.64932 | K10: =(AC10-AVERAGE(AC$2:AC$229))/AVERAGE(AC$2:AC$229)*100+100 -> 131.65014 | L10: =(AF10-AVERAGE(AF$2:AF$229))/AVERAGE(AF$2:AF$229)*100+100 -> 171.05267 | M10: =(AI10-AVERAGE(AI$2:AI$229))/AVERAGE(AI$2:AI$229)*100+100 -> 227.92397 | N10: =(AVERAGE(AJ$2:AJ$229)-AJ10)/AVERAGE(AJ$2:AJ$229)*100+100 -> -16.967662 | O10: =(AK10-AVERAGE(AK$2:AK$229))/AVERAGE(AK$2:AK$229)*100+100 -> 231.76135 | P10: =(AL10-AVERAGE(AL$2:AL$229))/AVERAGE(AL$2:AL$229)*100+100 -> 102.3163 | Q10: =(AM10-AVERAGE(AM$2:AM$229))/AVERAGE(AM$2:AM$229)*100+100 -> 103.2478 | R10: =(AN10-AVERAGE(AN$2:AN$229))/AVERAGE(AN$2:AN$229)*100+100 -> 108.39609 | S10: =(AO10-AVERAGE(AO$2:AO$229))/AVERAGE(AO$2:AO$229)*100+100 -> 106.14996 | T10: =(F10*1.5+H10*2.5+I10+J10+K10*1.5+L10+O10*0.75+P10+S10)/11.25 -> 139.54145 | V10: ='2025_Fantasy_Hitters_modified'!F140 -> 152.13466 | W10: ='2025_Fantasy_Hitters_modified'!G140 -> 90.586755 | X10: ='2025_Fantasy_Hitters_modified'!H140 -> 31.440775 | Y10: ='2025_Fantasy_Hitters_modified'!I140 -> 1.9992276 | Z10: ='2025_Fantasy_Hitters_modified'!J140 -> 28.4 | AA10: ='2025_Fantasy_Hitters_modified'!K140 -> 96.474927 | AB10: ='2025_Fantasy_Hitters_modified'!L140 -> 87 | AC10: ='2025_Fantasy_Hitters_modified'!M140 -> 60.162245 | ... AR10: ='2025_Fantasy_Hitters_modified'!AB140 -> 8.9660574
A11: ='2025_Fantasy_Hitters_modified'!A32 -> BAL | B11: ='2025_Fantasy_Hitters_modified'!B32 -> Gunnar Henderson | C11: ='2025_Fantasy_Hitters_modified'!D32 -> 584 | D11: ='2025_Fantasy_Hitters_modified'!E32 -> 665 | E11: =(V11-AVERAGE(V$2:V$229))/AVERAGE(V$2:V$229)*100+100 -> 134.65875 | F11: =E11*1.51744-31.775 -> 172.56157 | G11: =(Z11-AVERAGE(Z$2:Z$229))/AVERAGE(Z$2:Z$229)*100+100 -> 169.96104 | H11: =G11*0.83285-13.6979 -> 127.85416 | I11: =(AA11-AVERAGE(AA$2:AA$229))/AVERAGE(AA$2:AA$229)*100+100 -> 156.29446 | J11: =(AB11-AVERAGE(AB$2:AB$229))/AVERAGE(AB$2:AB$229)*100+100 -> 138.76769 | K11: =(AC11-AVERAGE(AC$2:AC$229))/AVERAGE(AC$2:AC$229)*100+100 -> 155.90279 | L11: =(AF11-AVERAGE(AF$2:AF$229))/AVERAGE(AF$2:AF$229)*100+100 -> 102.47504 | M11: =(AI11-AVERAGE(AI$2:AI$229))/AVERAGE(AI$2:AI$229)*100+100 -> 153.52753 | N11: =(AVERAGE(AJ$2:AJ$229)-AJ11)/AVERAGE(AJ$2:AJ$229)*100+100 -> 52.934053 | O11: =(AK11-AVERAGE(AK$2:AK$229))/AVERAGE(AK$2:AK$229)*100+100 -> 155.79066 | P11: =(AL11-AVERAGE(AL$2:AL$229))/AVERAGE(AL$2:AL$229)*100+100 -> 108.57125 | Q11: =(AM11-AVERAGE(AM$2:AM$229))/AVERAGE(AM$2:AM$229)*100+100 -> 109.8527 | R11: =(AN11-AVERAGE(AN$2:AN$229))/AVERAGE(AN$2:AN$229)*100+100 -> 120.221 | S11: =(AO11-AVERAGE(AO$2:AO$229))/AVERAGE(AO$2:AO$229)*100+100 -> 115.69746 | T11: =(F11*1.5+H11*2.5+I11+J11+K11*1.5+L11+O11*0.75+P11+S11)/11.25 -> 137.86496 | V11: ='2025_Fantasy_Hitters_modified'!F32 -> 158.18481 | W11: ='2025_Fantasy_Hitters_modified'!G32 -> 89.954519 | X11: ='2025_Fantasy_Hitters_modified'!H32 -> 32.300903 | Y11: ='2025_Fantasy_Hitters_modified'!I32 -> 6.06688 | Z11: ='2025_Fantasy_Hitters_modified'!J32 -> 31 | AA11: ='2025_Fantasy_Hitters_modified'!K32 -> 103.06392 | AB11: ='2025_Fantasy_Hitters_modified'!L32 -> 89 | AC11: ='2025_Fantasy_Hitters_modified'!M32 -> 71.245361 | ... AR11: ='2025_Fantasy_Hitters_modified'!AB32 -> 10.713588
A12: ='2025_Fantasy_Hitters_modified'!A71 -> CLE | B12: ='2025_Fantasy_Hitters_modified'!B71 -> Jose Ramirez | C12: ='2025_Fantasy_Hitters_modified'!D71 -> 590 | D12: ='2025_Fantasy_Hitters_modified'!E71 -> 662 | E12: =(V12-AVERAGE(V$2:V$229))/AVERAGE(V$2:V$229)*100+100 -> 136.21672 | F12: =E12*1.51744-31.775 -> 174.92571 | G12: =(Z12-AVERAGE(Z$2:Z$229))/AVERAGE(Z$2:Z$229)*100+100 -> 156.80277 | H12: =G12*0.83285-13.6979 -> 116.89529 | I12: =(AA12-AVERAGE(AA$2:AA$229))/AVERAGE(AA$2:AA$229)*100+100 -> 143.06914 | J12: =(AB12-AVERAGE(AB$2:AB$229))/AVERAGE(AB$2:AB$229)*100+100 -> 152.80038 | K12: =(AC12-AVERAGE(AC$2:AC$229))/AVERAGE(AC$2:AC$229)*100+100 -> 129.99258 | L12: =(AF12-AVERAGE(AF$2:AF$229))/AVERAGE(AF$2:AF$229)*100+100 -> 66.652871 | M12: =(AI12-AVERAGE(AI$2:AI$229))/AVERAGE(AI$2:AI$229)*100+100 -> 285.33224 | N12: =(AVERAGE(AJ$2:AJ$229)-AJ12)/AVERAGE(AJ$2:AJ$229)*100+100 -> -87.042165 | O12: =(AK12-AVERAGE(AK$2:AK$229))/AVERAGE(AK$2:AK$229)*100+100 -> 284.73334 | P12: =(AL12-AVERAGE(AL$2:AL$229))/AVERAGE(AL$2:AL$229)*100+100 -> 108.71051 | Q12: =(AM12-AVERAGE(AM$2:AM$229))/AVERAGE(AM$2:AM$229)*100+100 -> 107.36218 | R12: =(AN12-AVERAGE(AN$2:AN$229))/AVERAGE(AN$2:AN$229)*100+100 -> 114.45978 | S12: =(AO12-AVERAGE(AO$2:AO$229))/AVERAGE(AO$2:AO$229)*100+100 -> 111.3632 | T12: =(F12*1.5+H12*2.5+I12+J12+K12*1.5+L12+O12*0.75+P12+S12)/11.25 -> 137.40105 | V12: ='2025_Fantasy_Hitters_modified'!F71 -> 160.01497 | W12: ='2025_Fantasy_Hitters_modified'!G71 -> 93.185162 | X12: ='2025_Fantasy_Hitters_modified'!H71 -> 33.849311 | Y12: ='2025_Fantasy_Hitters_modified'!I71 -> 3.3849311 | Z12: ='2025_Fantasy_Hitters_modified'!J71 -> 28.6 | AA12: ='2025_Fantasy_Hitters_modified'!K71 -> 94.342857 | AB12: ='2025_Fantasy_Hitters_modified'!L71 -> 98 | AC12: ='2025_Fantasy_Hitters_modified'!M71 -> 59.404762 | ... AR12: ='2025_Fantasy_Hitters_modified'!AB71 -> 8.973529
A13: ='2025_Fantasy_Hitters_modified'!A169 -> SDP | B13: ='2025_Fantasy_Hitters_modified'!B169 -> Fernando Tatis Jr. | C13: ='2025_Fantasy_Hitters_modified'!D169 -> 566 | D13: ='2025_Fantasy_Hitters_modified'!E169 -> 629 | E13: =(V13-AVERAGE(V$2:V$229))/AVERAGE(V$2:V$229)*100+100 -> 132.407 | F13: =E13*1.51744-31.775 -> 169.14468 | G13: =(Z13-AVERAGE(Z$2:Z$229))/AVERAGE(Z$2:Z$229)*100+100 -> 173.25061 | H13: =G13*0.83285-13.6979 -> 130.59387 | I13: =(AA13-AVERAGE(AA$2:AA$229))/AVERAGE(AA$2:AA$229)*100+100 -> 149.29731 | J13: =(AB13-AVERAGE(AB$2:AB$229))/AVERAGE(AB$2:AB$229)*100+100 -> 137.20851 | K13: =(AC13-AVERAGE(AC$2:AC$229))/AVERAGE(AC$2:AC$229)*100+100 -> 124.18063 | L13: =(AF13-AVERAGE(AF$2:AF$229))/AVERAGE(AF$2:AF$229)*100+100 -> 117.83913 | M13: =(AI13-AVERAGE(AI$2:AI$229))/AVERAGE(AI$2:AI$229)*100+100 -> 189.37762 | N13: =(AVERAGE(AJ$2:AJ$229)-AJ13)/AVERAGE(AJ$2:AJ$229)*100+100 -> 20.121494 | O13: =(AK13-AVERAGE(AK$2:AK$229))/AVERAGE(AK$2:AK$229)*100+100 -> 192.70462 | P13: =(AL13-AVERAGE(AL$2:AL$229))/AVERAGE(AL$2:AL$229)*100+100 -> 110.15079 | Q13: =(AM13-AVERAGE(AM$2:AM$229))/AVERAGE(AM$2:AM$229)*100+100 -> 107.41895 | R13: =(AN13-AVERAGE(AN$2:AN$229))/AVERAGE(AN$2:AN$229)*100+100 -> 118.67215 | S13: =(AO13-AVERAGE(AO$2:AO$229))/AVERAGE(AO$2:AO$229)*100+100 -> 113.76254 | T13: =(F13*1.5+H13*2.5+I13+J13+K13*1.5+L13+O13*0.75+P13+S13)/11.25 -> 136.82306 | V13: ='2025_Fantasy_Hitters_modified'!F169 -> 155.53966 | W13: ='2025_Fantasy_Hitters_modified'!G169 -> 90.414997 | X13: ='2025_Fantasy_Hitters_modified'!H169 -> 30.476965 | Y13: ='2025_Fantasy_Hitters_modified'!I169 -> 2.045343 | Z13: ='2025_Fantasy_Hitters_modified'!J169 -> 31.6 | AA13: ='2025_Fantasy_Hitters_modified'!K169 -> 98.449848 | AB13: ='2025_Fantasy_Hitters_modified'!L169 -> 88 | AC13: ='2025_Fantasy_Hitters_modified'!M169 -> 56.748784 | ... AR13: ='2025_Fantasy_Hitters_modified'!AB169 -> 9.0220643
A14: ='2025_Fantasy_Hitters_modified'!A113 -> LAD | B14: ='2025_Fantasy_Hitters_modified'!B113 -> Mookie Betts | C14: ='2025_Fantasy_Hitters_modified'!D113 -> 565 | D14: ='2025_Fantasy_Hitters_modified'!E113 -> 653 | E14: =(V14-AVERAGE(V$2:V$229))/AVERAGE(V$2:V$229)*100+100 -> 131.01311 | F14: =E14*1.51744-31.775 -> 167.02954 | G14: =(Z14-AVERAGE(Z$2:Z$229))/AVERAGE(Z$2:Z$229)*100+100 -> 151.32016 | H14: =G14*0.83285-13.6979 -> 112.32909 | I14: =(AA14-AVERAGE(AA$2:AA$229))/AVERAGE(AA$2:AA$229)*100+100 -> 153.00644 | J14: =(AB14-AVERAGE(AB$2:AB$229))/AVERAGE(AB$2:AB$229)*100+100 -> 141.88607 | K14: =(AC14-AVERAGE(AC$2:AC$229))/AVERAGE(AC$2:AC$229)*100+100 -> 163.41504 | L14: =(AF14-AVERAGE(AF$2:AF$229))/AVERAGE(AF$2:AF$229)*100+100 -> 118.92784 | M14: =(AI14-AVERAGE(AI$2:AI$229))/AVERAGE(AI$2:AI$229)*100+100 -> 142.80125 | N14: =(AVERAGE(AJ$2:AJ$229)-AJ14)/AVERAGE(AJ$2:AJ$229)*100+100 -> 89.895875 | O14: =(AK14-AVERAGE(AK$2:AK$229))/AVERAGE(AK$2:AK$229)*100+100 -> 154.25322 | P14: =(AL14-AVERAGE(AL$2:AL$229))/AVERAGE(AL$2:AL$229)*100+100 -> 109.18411 | Q14: =(AM14-AVERAGE(AM$2:AM$229))/AVERAGE(AM$2:AM$229)*100+100 -> 112.43711 | R14: =(AN14-AVERAGE(AN$2:AN$229))/AVERAGE(AN$2:AN$229)*100+100 -> 114.73102 | S14: =(AO14-AVERAGE(AO$2:AO$229))/AVERAGE(AO$2:AO$229)*100+100 -> 113.73022 | T14: =(F14*1.5+H14*2.5+I14+J14+K14*1.5+L14+O14*0.75+P14+S14)/11.25 -> 135.90348 | V14: ='2025_Fantasy_Hitters_modified'!F113 -> 153.90224 | W14: ='2025_Fantasy_Hitters_modified'!G113 -> 92.034194 | X14: ='2025_Fantasy_Hitters_modified'!H113 -> 31.330789 | Y14: ='2025_Fantasy_Hitters_modified'!I113 -> 2.9652354 | Z14: ='2025_Fantasy_Hitters_modified'!J113 -> 27.6 | AA14: ='2025_Fantasy_Hitters_modified'!K113 -> 100.89573 | AB14: ='2025_Fantasy_Hitters_modified'!L113 -> 91 | AC14: ='2025_Fantasy_Hitters_modified'!M113 -> 74.67835 | ... AR14: ='2025_Fantasy_Hitters_modified'!AB113 -> 11.436195
A15: ='2025_Fantasy_Hitters_modified'!A180 -> SEA | B15: ='2025_Fantasy_Hitters_modified'!B180 -> Julio Rodriguez | C15: ='2025_Fantasy_Hitters_modified'!D180 -> 584 | D15: ='2025_Fantasy_Hitters_modified'!E180 -> 641 | E15: =(V15-AVERAGE(V$2:V$229))/AVERAGE(V$2:V$229)*100+100 -> 138.1403 | F15: =E15*1.51744-31.775 -> 177.84461 | G15: =(Z15-AVERAGE(Z$2:Z$229))/AVERAGE(Z$2:Z$229)*100+100 -> 148.03059 | H15: =G15*0.83285-13.6979 -> 109.58937 | I15: =(AA15-AVERAGE(AA$2:AA$229))/AVERAGE(AA$2:AA$229)*100+100 -> 136.19517 | J15: =(AB15-AVERAGE(AB$2:AB$229))/AVERAGE(AB$2:AB$229)*100+100 -> 130.97176 | K15: =(AC15-AVERAGE(AC$2:AC$229))/AVERAGE(AC$2:AC$229)*100+100 -> 102.47883 | L15: =(AF15-AVERAGE(AF$2:AF$229))/AVERAGE(AF$2:AF$229)*100+100 -> 151.70053 | M15: =(AI15-AVERAGE(AI$2:AI$229))/AVERAGE(AI$2:AI$229)*100+100 -> 257.48841 | N15: =(AVERAGE(AJ$2:AJ$229)-AJ15)/AVERAGE(AJ$2:AJ$229)*100+100 -> -56.453842 | O15: =(AK15-AVERAGE(AK$2:AK$229))/AVERAGE(AK$2:AK$229)*100+100 -> 257.85077 | P15: =(AL15-AVERAGE(AL$2:AL$229))/AVERAGE(AL$2:AL$229)*100+100 -> 111.37832 | Q15: =(AM15-AVERAGE(AM$2:AM$229))/AVERAGE(AM$2:AM$229)*100+100 -> 106.07583 | R15: =(AN15-AVERAGE(AN$2:AN$229))/AVERAGE(AN$2:AN$229)*100+100 -> 111.2735 | S15: =(AO15-AVERAGE(AO$2:AO$229))/AVERAGE(AO$2:AO$229)*100+100 -> 109.00583 | T15: =(F15*1.5+H15*2.5+I15+J15+K15*1.5+L15+O15*0.75+P15+S15)/11.25 -> 135.74207 | V15: ='2025_Fantasy_Hitters_modified'!F180 -> 162.27461 | W15: ='2025_Fantasy_Hitters_modified'!G180 -> 104.00796 | X15: ='2025_Fantasy_Hitters_modified'!H180 -> 27.669806 | Y15: ='2025_Fantasy_Hitters_modified'!I180 -> 2.4410455 | Z15: ='2025_Fantasy_Hitters_modified'!J180 -> 27 | AA15: ='2025_Fantasy_Hitters_modified'!K180 -> 89.810015 | AB15: ='2025_Fantasy_Hitters_modified'!L180 -> 84 | AC15: ='2025_Fantasy_Hitters_modified'!M180 -> 46.83137 | ... AR15: ='2025_Fantasy_Hitters_modified'!AB180 -> 7.3059859
A16: ='2025_Fantasy_Hitters_modified'!A52 -> CHC | B16: ='2025_Fantasy_Hitters_modified'!B52 -> Kyle Tucker | C16: ='2025_Fantasy_Hitters_modified'!D52 -> 551 | D16: ='2025_Fantasy_Hitters_modified'!E52 -> 642 | E16: =(V16-AVERAGE(V$2:V$229))/AVERAGE(V$2:V$229)*100+100 -> 127.74987 | F16: =E16*1.51744-31.775 -> 162.07777 | G16: =(Z16-AVERAGE(Z$2:Z$229))/AVERAGE(Z$2:Z$229)*100+100 -> 161.18886 | H16: =G16*0.83285-13.6979 -> 120.54824 | I16: =(AA16-AVERAGE(AA$2:AA$229))/AVERAGE(AA$2:AA$229)*100+100 -> 138.92151 | J16: =(AB16-AVERAGE(AB$2:AB$229))/AVERAGE(AB$2:AB$229)*100+100 -> 146.56363 | K16: =(AC16-AVERAGE(AC$2:AC$229))/AVERAGE(AC$2:AC$229)*100+100 -> 172.90776 | L16: =(AF16-AVERAGE(AF$2:AF$229))/AVERAGE(AF$2:AF$229)*100+100 -> 48.169798 | M16: =(AI16-AVERAGE(AI$2:AI$229))/AVERAGE(AI$2:AI$229)*100+100 -> 199.99611 | N16: =(AVERAGE(AJ$2:AJ$229)-AJ16)/AVERAGE(AJ$2:AJ$229)*100+100 -> 23.538512 | O16: =(AK16-AVERAGE(AK$2:AK$229))/AVERAGE(AK$2:AK$229)*100+100 -> 208.23897 | P16: =(AL16-AVERAGE(AL$2:AL$229))/AVERAGE(AL$2:AL$229)*100+100 -> 109.16967 | Q16: =(AM16-AVERAGE(AM$2:AM$229))/AVERAGE(AM$2:AM$229)*100+100 -> 113.34166 | R16: =(AN16-AVERAGE(AN$2:AN$229))/AVERAGE(AN$2:AN$229)*100+100 -> 115.87636 | S16: =(AO16-AVERAGE(AO$2:AO$229))/AVERAGE(AO$2:AO$229)*100+100 -> 114.77051 | T16: =(F16*1.5+H16*2.5+I16+J16+K16*1.5+L16+O16*0.75+P16+S16)/11.25 -> 134.89984 | V16: ='2025_Fantasy_Hitters_modified'!F52 -> 150.06889 | W16: ='2025_Fantasy_Hitters_modified'!G52 -> 88.188163 | X16: ='2025_Fantasy_Hitters_modified'!H52 -> 28.450389 | Y16: ='2025_Fantasy_Hitters_modified'!I52 -> 2.393596 | Z16: ='2025_Fantasy_Hitters_modified'!J52 -> 29.4 | AA16: ='2025_Fantasy_Hitters_modified'!K52 -> 91.60782 | AB16: ='2025_Fantasy_Hitters_modified'!L52 -> 94 | AC16: ='2025_Fantasy_Hitters_modified'!M52 -> 79.016391 | ... AR16: ='2025_Fantasy_Hitters_modified'!AB52 -> 12.307849
A17: ='2025_Fantasy_Hitters_modified'!A222 -> TOR | B17: ='2025_Fantasy_Hitters_modified'!B222 -> Vladimir Guerrero Jr. | C17: ='2025_Fantasy_Hitters_modified'!D222 -> 587 | D17: ='2025_Fantasy_Hitters_modified'!E222 -> 666 | E17: =(V17-AVERAGE(V$2:V$229))/AVERAGE(V$2:V$229)*100+100 -> 147.98449 | F17: =E17*1.51744-31.775 -> 192.78258 | G17: =(Z17-AVERAGE(Z$2:Z$229))/AVERAGE(Z$2:Z$229)*100+100 -> 174.34714 | H17: =G17*0.83285-13.6979 -> 131.50711 | I17: =(AA17-AVERAGE(AA$2:AA$229))/AVERAGE(AA$2:AA$229)*100+100 -> 146.31062 | J17: =(AB17-AVERAGE(AB$2:AB$229))/AVERAGE(AB$2:AB$229)*100+100 -> 154.35957 | K17: =(AC17-AVERAGE(AC$2:AC$229))/AVERAGE(AC$2:AC$229)*100+100 -> 147.34945 | L17: =(AF17-AVERAGE(AF$2:AF$229))/AVERAGE(AF$2:AF$229)*100+100 -> 117.77248 | M17: =(AI17-AVERAGE(AI$2:AI$229))/AVERAGE(AI$2:AI$229)*100+100 -> 39.139713 | N17: =(AVERAGE(AJ$2:AJ$229)-AJ17)/AVERAGE(AJ$2:AJ$229)*100+100 -> 126.38089 | O17: =(AK17-AVERAGE(AK$2:AK$229))/AVERAGE(AK$2:AK$229)*100+100 -> 27.063512 | P17: =(AL17-AVERAGE(AL$2:AL$229))/AVERAGE(AL$2:AL$229)*100+100 -> 118.7056 | Q17: =(AM17-AVERAGE(AM$2:AM$229))/AVERAGE(AM$2:AM$229)*100+100 -> 117.3627 | R17: =(AN17-AVERAGE(AN$2:AN$229))/AVERAGE(AN$2:AN$229)*100+100 -> 121.69327 | S17: =(AO17-AVERAGE(AO$2:AO$229))/AVERAGE(AO$2:AO$229)*100+100 -> 119.80391 | T17: =(F17*1.5+H17*2.5+I17+J17+K17*1.5+L17+O17*0.75+P17+S17)/11.25 -> 134.77472 | V17: ='2025_Fantasy_Hitters_modified'!F222 -> 173.83866 | W17: ='2025_Fantasy_Hitters_modified'!G222 -> 108.1721 | X17: ='2025_Fantasy_Hitters_modified'!H222 -> 31.784876 | Y17: ='2025_Fantasy_Hitters_modified'!I222 -> 0.99747431 | Z17: ='2025_Fantasy_Hitters_modified'!J222 -> 31.8 | AA17: ='2025_Fantasy_Hitters_modified'!K222 -> 96.480357 | AB17: ='2025_Fantasy_Hitters_modified'!L222 -> 99 | AC17: ='2025_Fantasy_Hitters_modified'!M222 -> 67.336607 | ... AR17: ='2025_Fantasy_Hitters_modified'!AB222 -> 10.110602
A18: ='2025_Fantasy_Hitters_modified'!A159 -> PHI | B18: ='2025_Fantasy_Hitters_modified'!B159 -> Kyle Schwarber | C18: ='2025_Fantasy_Hitters_modified'!D159 -> 551 | D18: ='2025_Fantasy_Hitters_modified'!E159 -> 660 | E18: =(V18-AVERAGE(V$2:V$229))/AVERAGE(V$2:V$229)*100+100 -> 102.88376 | F18: =E18*1.51744-31.775 -> 124.34494 | G18: =(Z18-AVERAGE(Z$2:Z$229))/AVERAGE(Z$2:Z$229)*100+100 -> 196.27759 | H18: =G18*0.83285-13.6979 -> 149.77189 | I18: =(AA18-AVERAGE(AA$2:AA$229))/AVERAGE(AA$2:AA$229)*100+100 -> 143.12629 | J18: =(AB18-AVERAGE(AB$2:AB$229))/AVERAGE(AB$2:AB$229)*100+100 -> 146.56363 | K18: =(AC18-AVERAGE(AC$2:AC$229))/AVERAGE(AC$2:AC$229)*100+100 -> 218.45272 | L18: =(AF18-AVERAGE(AF$2:AF$229))/AVERAGE(AF$2:AF$229)*100+100 -> 117.96283 | M18: =(AI18-AVERAGE(AI$2:AI$229))/AVERAGE(AI$2:AI$229)*100+100 -> 39.196901 | N18: =(AVERAGE(AJ$2:AJ$229)-AJ18)/AVERAGE(AJ$2:AJ$229)*100+100 -> 126.2927 | O18: =(AK18-AVERAGE(AK$2:AK$229))/AVERAGE(AK$2:AK$229)*100+100 -> 27.109843 | P18: =(AL18-AVERAGE(AL$2:AL$229))/AVERAGE(AL$2:AL$229)*100+100 -> 87.920137 | Q18: =(AM18-AVERAGE(AM$2:AM$229))/AVERAGE(AM$2:AM$229)*100+100 -> 107.43766 | R18: =(AN18-AVERAGE(AN$2:AN$229))/AVERAGE(AN$2:AN$229)*100+100 -> 108.92308 | S18: =(AO18-AVERAGE(AO$2:AO$229))/AVERAGE(AO$2:AO$229)*100+100 -> 108.27501 | T18: =(F18*1.5+H18*2.5+I18+J18+K18*1.5+L18+O18*0.75+P18+S18)/11.25 -> 134.47169 | V18: ='2025_Fantasy_Hitters_modified'!F159 -> 120.85845 | W18: ='2025_Fantasy_Hitters_modified'!G159 -> 63.443599 | X18: ='2025_Fantasy_Hitters_modified'!H159 -> 22.015129 | Y18: ='2025_Fantasy_Hitters_modified'!I159 -> 1.0006877 | Z18: ='2025_Fantasy_Hitters_modified'!J159 -> 35.8 | AA18: ='2025_Fantasy_Hitters_modified'!K159 -> 94.380547 | AB18: ='2025_Fantasy_Hitters_modified'!L159 -> 94 | AC18: ='2025_Fantasy_Hitters_modified'!M159 -> 99.829787 | ... AR18: ='2025_Fantasy_Hitters_modified'!AB159 -> 15.125725
A19: ='2025_Fantasy_Hitters_modified'!A19 -> ATL | B19: ='2025_Fantasy_Hitters_modified'!B19 -> Austin Riley | C19: ='2025_Fantasy_Hitters_modified'!D19 -> 579 | D19: ='2025_Fantasy_Hitters_modified'!E19 -> 648 | E19: =(V19-AVERAGE(V$2:V$229))/AVERAGE(V$2:V$229)*100+100 -> 132.53779 | F19: =E19*1.51744-31.775 -> 169.34315 | G19: =(Z19-AVERAGE(Z$2:Z$229))/AVERAGE(Z$2:Z$229)*100+100 -> 177.6367 | H19: =G19*0.83285-13.6979 -> 134.24683 | I19: =(AA19-AVERAGE(AA$2:AA$229))/AVERAGE(AA$2:AA$229)*100+100 -> 137.43113 | J19: =(AB19-AVERAGE(AB$2:AB$229))/AVERAGE(AB$2:AB$229)*100+100 -> 145.00445 | K19: =(AC19-AVERAGE(AC$2:AC$229))/AVERAGE(AC$2:AC$229)*100+100 -> 120.01321 | L19: =(AF19-AVERAGE(AF$2:AF$229))/AVERAGE(AF$2:AF$229)*100+100 -> 170.07472 | M19: =(AI19-AVERAGE(AI$2:AI$229))/AVERAGE(AI$2:AI$229)*100+100 -> 19.026092 | N19: =(AVERAGE(AJ$2:AJ$229)-AJ19)/AVERAGE(AJ$2:AJ$229)*100+100 -> 200 | O19: =(AK19-AVERAGE(AK$2:AK$229))/AVERAGE(AK$2:AK$229)*100+100 -> 25.689866 | P19: =(AL19-AVERAGE(AL$2:AL$229))/AVERAGE(AL$2:AL$229)*100+100 -> 107.784 | Q19: =(AM19-AVERAGE(AM$2:AM$229))/AVERAGE(AM$2:AM$229)*100+100 -> 106.16201 | R19: =(AN19-AVERAGE(AN$2:AN$229))/AVERAGE(AN$2:AN$229)*100+100 -> 117.4442 | S19: =(AO19-AVERAGE(AO$2:AO$229))/AVERAGE(AO$2:AO$229)*100+100 -> 112.52194 | T19: =(F19*1.5+H19*2.5+I19+J19+K19*1.5+L19+O19*0.75+P19+S19)/11.25 -> 129.93202 | V19: ='2025_Fantasy_Hitters_modified'!F19 -> 155.6933 | W19: ='2025_Fantasy_Hitters_modified'!G19 -> 90.179041 | X19: ='2025_Fantasy_Hitters_modified'!H19 -> 30.823325 | Y19: ='2025_Fantasy_Hitters_modified'!I19 -> 1.9983021 | Z19: ='2025_Fantasy_Hitters_modified'!J19 -> 32.4 | AA19: ='2025_Fantasy_Hitters_modified'!K19 -> 90.625037 | AB19: ='2025_Fantasy_Hitters_modified'!L19 -> 93 | AC19: ='2025_Fantasy_Hitters_modified'!M19 -> 54.84433 | ... AR19: ='2025_Fantasy_Hitters_modified'!AB19 -> 8.4636312
A20: ='2025_Fantasy_Hitters_modified'!A12 -> ATH | B20: ='2025_Fantasy_Hitters_modified'!B12 -> Brent Rooker | C20: ='2025_Fantasy_Hitters_modified'!D12 -> 533 | D20: ='2025_Fantasy_Hitters_modified'!E12 -> 603 | E20: =(V20-AVERAGE(V$2:V$229))/AVERAGE(V$2:V$229)*100+100 -> 113.45626 | F20: =E20*1.51744-31.775 -> 140.38807 | G20: =(Z20-AVERAGE(Z$2:Z$229))/AVERAGE(Z$2:Z$229)*100+100 -> 191.8915 | H20: =G20*0.83285-13.6979 -> 146.11894 | I20: =(AA20-AVERAGE(AA$2:AA$229))/AVERAGE(AA$2:AA$229)*100+100 -> 123.6158 | J20: =(AB20-AVERAGE(AB$2:AB$229))/AVERAGE(AB$2:AB$229)*100+100 -> 143.44526 | K20: =(AC20-AVERAGE(AC$2:AC$229))/AVERAGE(AC$2:AC$229)*100+100 -> 121.22677 | L20: =(AF20-AVERAGE(AF$2:AF$229))/AVERAGE(AF$2:AF$229)*100+100 -> 165.80579 | M20: =(AI20-AVERAGE(AI$2:AI$229))/AVERAGE(AI$2:AI$229)*100+100 -> 75.966681 | N20: =(AVERAGE(AJ$2:AJ$229)-AJ20)/AVERAGE(AJ$2:AJ$229)*100+100 -> 126.78421 | O20: =(AK20-AVERAGE(AK$2:AK$229))/AVERAGE(AK$2:AK$229)*100+100 -> 76.930164 | P20: =(AL20-AVERAGE(AL$2:AL$229))/AVERAGE(AL$2:AL$229)*100+100 -> 100.22922 | Q20: =(AM20-AVERAGE(AM$2:AM$229))/AVERAGE(AM$2:AM$229)*100+100 -> 103.52806 | R20: =(AN20-AVERAGE(AN$2:AN$229))/AVERAGE(AN$2:AN$229)*100+100 -> 118.3857 | S20: =(AO20-AVERAGE(AO$2:AO$229))/AVERAGE(AO$2:AO$229)*100+100 -> 111.90352 | T20: =(F20*1.5+H20*2.5+I20+J20+K20*1.5+L20+O20*0.75+P20+S20)/11.25 -> 129.81483 | V20: ='2025_Fantasy_Hitters_modified'!F12 -> 133.27806 | W20: ='2025_Fantasy_Hitters_modified'!G12 -> 71.811174 | X20: ='2025_Fantasy_Hitters_modified'!H12 -> 25.070933 | Y20: ='2025_Fantasy_Hitters_modified'!I12 -> 1.584607 | Z20: ='2025_Fantasy_Hitters_modified'!J12 -> 35 | AA20: ='2025_Fantasy_Hitters_modified'!K12 -> 81.514907 | AB20: ='2025_Fantasy_Hitters_modified'!L12 -> 92 | AC20: ='2025_Fantasy_Hitters_modified'!M12 -> 55.398913 | ... AR20: ='2025_Fantasy_Hitters_modified'!AB12 -> 9.1872161
A21: ='2025_Fantasy_Hitters_modified'!A152 -> NYY | B21: ='2025_Fantasy_Hitters_modified'!B152 -> Jazz Chisholm Jr. | C21: ='2025_Fantasy_Hitters_modified'!D152 -> 544 | D21: ='2025_Fantasy_Hitters_modified'!E152 -> 604 | E21: =(V21-AVERAGE(V$2:V$229))/AVERAGE(V$2:V$229)*100+100 -> 114.39619 | F21: =E21*1.51744-31.775 -> 141.81436 | G21: =(Z21-AVERAGE(Z$2:Z$229))/AVERAGE(Z$2:Z$229)*100+100 -> 145.83754 | H21: =G21*0.83285-13.6979 -> 107.7629 | I21: =(AA21-AVERAGE(AA$2:AA$229))/AVERAGE(AA$2:AA$229)*100+100 -> 124.96699 | J21: =(AB21-AVERAGE(AB$2:AB$229))/AVERAGE(AB$2:AB$229)*100+100 -> 118.49826 | K21: =(AC21-AVERAGE(AC$2:AC$229))/AVERAGE(AC$2:AC$229)*100+100 -> 113.47864 | L21: =(AF21-AVERAGE(AF$2:AF$229))/AVERAGE(AF$2:AF$229)*100+100 -> 84.26767 | M21: =(AI21-AVERAGE(AI$2:AI$229))/AVERAGE(AI$2:AI$229)*100+100 -> 359.0643 | N21: =(AVERAGE(AJ$2:AJ$229)-AJ21)/AVERAGE(AJ$2:AJ$229)*100+100 -> -131.30982 | O21: =(AK21-AVERAGE(AK$2:AK$229))/AVERAGE(AK$2:AK$229)*100+100 -> 368.78514 | P21: =(AL21-AVERAGE(AL$2:AL$229))/AVERAGE(AL$2:AL$229)*100+100 -> 99.016094 | Q21: =(AM21-AVERAGE(AM$2:AM$229))/AVERAGE(AM$2:AM$229)*100+100 -> 98.322764 | R21: =(AN21-AVERAGE(AN$2:AN$229))/AVERAGE(AN$2:AN$229)*100+100 -> 107.29878 | S21: =(AO21-AVERAGE(AO$2:AO$229))/AVERAGE(AO$2:AO$229)*100+100 -> 103.38267 | T21: =(F21*1.5+H21*2.5+I21+J21+K21*1.5+L21+O21*0.75+P21+S21)/11.25 -> 129.69487 | V21: ='2025_Fantasy_Hitters_modified'!F152 -> 134.38221 | W21: ='2025_Fantasy_Hitters_modified'!G152 -> 81.236728 | X21: ='2025_Fantasy_Hitters_modified'!H152 -> 24.403518 | Y21: ='2025_Fantasy_Hitters_modified'!I152 -> 3.4248551 | Z21: ='2025_Fantasy_Hitters_modified'!J152 -> 26.6 | AA21: ='2025_Fantasy_Hitters_modified'!K152 -> 82.405911 | AB21: ='2025_Fantasy_Hitters_modified'!L152 -> 76 | AC21: ='2025_Fantasy_Hitters_modified'!M152 -> 51.858128 | ... AR21: ='2025_Fantasy_Hitters_modified'!AB152 -> 8.5857828
A22: ='2025_Fantasy_Hitters_modified'!A26 -> ATL | B22: ='2025_Fantasy_Hitters_modified'!B26 -> Ronald Acuna Jr. | C22: ='2025_Fantasy_Hitters_modified'!D26 -> 452 | D22: ='2025_Fantasy_Hitters_modified'!E26 -> 525 | E22: =(V22-AVERAGE(V$2:V$229))/AVERAGE(V$2:V$229)*100+100 -> 111.80233 | F22: =E22*1.51744-31.775 -> 137.87833 | G22: =(Z22-AVERAGE(Z$2:Z$229))/AVERAGE(Z$2:Z$229)*100+100 -> 123.90708 | H22: =G22*0.83285-13.6979 -> 89.498115 | I22: =(AA22-AVERAGE(AA$2:AA$229))/AVERAGE(AA$2:AA$229)*100+100 -> 143.65873 | J22: =(AB22-AVERAGE(AB$2:AB$229))/AVERAGE(AB$2:AB$229)*100+100 -> 98.228818 | K22: =(AC22-AVERAGE(AC$2:AC$229))/AVERAGE(AC$2:AC$229)*100+100 -> 129.90737 | L22: =(AF22-AVERAGE(AF$2:AF$229))/AVERAGE(AF$2:AF$229)*100+100 -> 137.61882 | M22: =(AI22-AVERAGE(AI$2:AI$229))/AVERAGE(AI$2:AI$229)*100+100 -> 302.0152 | N22: =(AVERAGE(AJ$2:AJ$229)-AJ22)/AVERAGE(AJ$2:AJ$229)*100+100 -> -163.06136 | O22: =(AK22-AVERAGE(AK$2:AK$229))/AVERAGE(AK$2:AK$229)*100+100 -> 280.63415 | P22: =(AL22-AVERAGE(AL$2:AL$229))/AVERAGE(AL$2:AL$229)*100+100 -> 116.46771 | Q22: =(AM22-AVERAGE(AM$2:AM$229))/AVERAGE(AM$2:AM$229)*100+100 -> 118.99399 | R22: =(AN22-AVERAGE(AN$2:AN$229))/AVERAGE(AN$2:AN$229)*100+100 -> 121.41488 | S22: =(AO22-AVERAGE(AO$2:AO$229))/AVERAGE(AO$2:AO$229)*100+100 -> 120.35868 | T22: =(F22*1.5+H22*2.5+I22+J22+K22*1.5+L22+O22*0.75+P22+S22)/11.25 -> 129.08731 | V22: ='2025_Fantasy_Hitters_modified'!F26 -> 131.33517 | W22: ='2025_Fantasy_Hitters_modified'!G26 -> 82.152795 | X22: ='2025_Fantasy_Hitters_modified'!H26 -> 26.689542 | Y22: ='2025_Fantasy_Hitters_modified'!I26 -> 2.0102611 | Z22: ='2025_Fantasy_Hitters_modified'!J26 -> 22.6 | AA22: ='2025_Fantasy_Hitters_modified'!K26 -> 94.731646 | AB22: ='2025_Fantasy_Hitters_modified'!L26 -> 63 | AC22: ='2025_Fantasy_Hitters_modified'!M26 -> 59.365823 | ... AR22: ='2025_Fantasy_Hitters_modified'!AB26 -> 11.307776
