Workbook

Sheet P14_Relievers
A1: Name | B1: Team | C1: Position | D1: G | E1: IP | F1: TBF | G1: W | H1: L | I1: SV | J1: HLD | K1: BS | L1: H | M1: R | N1: ER | O1: HR | P1: IBB | Q1: HBP | R1: SO | S1: BB | U1: W% | V1: L% | W1: SV% | X1: HLD% | Y1: BS% | Z1: H% | AA1: R% | AB1: ER% | AC1: HR% | AD1: IBB% | AE1: HBP% | AF1: K% | AG1: BB%
A2: Mason Miller | B2: SD | C2: RP | D2: 59 | E2: 64.2 | F2: 254 | G2: =$D2*U2 -> 3.4030303 | H2: =$D2*V2 -> 1.2237722 | I2: =$D2*W2 -> 32.121212 | J2: =$D2*X2 -> 2.4432602 | K2: =$D2*Y2 -> 4 | L2: =$F2*Z2 -> 38.174295 | M2: =$F2*AA2 -> 18.934816 | N2: =$F2*AB2 -> 17.717123 | O2: =$F2*AC2 -> 6.1266876 | P2: =$F2*AD2 -> 1.9770095 | Q2: =$F2*AE2 -> 2.0490733 | R2: =$F2*AF2 -> 103.17949 | S2: =$F2*AG2 -> 23.88218 | U2: 0.05767848 | V2: 0.020741901776384512 | W2: 0.5444273240883409 | X2: 0.04141119 | Y2: 0.06779661 | Z2: 0.15029250138614442 | AA2: 0.074546518 | AB2: 0.069752453 | AC2: 0.024120817 | AD2: 0.0077835018 | AE2: 0.0080672177 | AF2: 0.40621848298025276 | AG2: 0.094024329
A3: Edwin Diaz | B3: LAD | C3: RP | D3: 64 | E3: 65.2 | F3: 265 | G3: =$D3*U3 -> 4.4090909 | H3: =$D3*V3 -> 2.3834131 | I3: =$D3*W3 -> 36.581818 | J3: =$D3*X3 -> 3.0464115 | K3: =$D3*Y3 -> 5 | L3: =$F3*Z3 -> 47.093238 | M3: =$F3*AA3 -> 23.718879 | N3: =$F3*AB3 -> 21.601945 | O3: =$F3*AC3 -> 6.8374173 | P3: =$F3*AD3 -> 0.99038396 | Q3: =$F3*AE3 -> 4.5982815 | R3: =$F3*AF3 -> 92.157286 | S3: =$F3*AG3 -> 23.052587 | U3: 0.068892045 | V3: 0.037240829 | W3: 0.5715909090909091 | X3: 0.047600179 | Y3: 0.078125 | Z3: 0.17771033033323613 | AA3: 0.089505203 | AB3: 0.081516775 | AC3: 0.025801575 | AD3: 0.0037372979 | AE3: 0.017352005 | AF3: 0.3477633419089394 | AG3: 0.086990893
A4: Andres Munoz | B4: SEA | C4: RP | D4: 60 | E4: 61.2 | F4: 253 | G4: =$D4*U4 -> 3.825 | H4: =$D4*V4 -> 2.1864919 | I4: =$D4*W4 -> 32.45 | J4: =$D4*X4 -> 2.9243952 | K4: =$D4*Y4 -> 5 | L4: =$F4*Z4 -> 44.334069 | M4: =$F4*AA4 -> 21.773968 | N4: =$F4*AB4 -> 19.765062 | O4: =$F4*AC4 -> 4.9978299 | P4: =$F4*AD4 -> 1.9828321 | Q4: =$F4*AE4 -> 3.5275873 | R4: =$F4*AF4 -> 80.029399 | S4: =$F4*AG4 -> 24.447682 | U4: 0.06375 | V4: 0.036441532 | W4: 0.5408333333333333 | X4: 0.048739919 | Y4: 0.083333333 | Z4: 0.17523347396093944 | AA4: 0.086063116 | AB4: 0.078122775 | AC4: 0.019754269 | AD4: 0.0078372809 | AE4: 0.013943033 | AF4: 0.31632173565840876 | AG4: 0.096631156
A5: Jhoan Duran | B5: PHI | C5: RP | D5: 65 | E5: 66.1 | F5: 271 | G5: =$D5*U5 -> 4.6571429 | H5: =$D5*V5 -> 2.8701299 | I5: =$D5*W5 -> 31.785714 | J5: =$D5*X5 -> 2.9266234 | K5: =$D5*Y5 -> 4 | L5: =$F5*Z5 -> 53.016484 | M5: =$F5*AA5 -> 21.964211 | N5: =$F5*AB5 -> 19.98386 | O5: =$F5*AC5 -> 3.9263158 | P5: =$F5*AD5 -> 1.9759553 | Q5: =$F5*AE5 -> 3.7705263 | R5: =$F5*AF5 -> 79.764912 | S5: =$F5*AG5 -> 20.833684 | U5: 0.071648352 | V5: 0.044155844 | W5: 0.48901098901098894 | X5: 0.045024975 | Y5: 0.061538462 | Z5: 0.1956327805036292 | AA5: 0.081048747 | AB5: 0.07374118 | AC5: 0.01448825 | AD5: 0.0072913479 | AE5: 0.013913381 | AF5: 0.2943354696704862 | AG5: 0.076877064
A6: Cade Smith | B6: CLE | C6: RP | D6: 67 | E6: 69 | F6: 277 | G6: =$D6*U6 -> 4.5628571 | H6: =$D6*V6 -> 2.9136555 | I6: =$D6*W6 -> 30.542857 | J6: =$D6*X6 -> 3.452605 | K6: =$D6*Y6 -> 5 | L6: =$F6*Z6 -> 50.74523 | M6: =$F6*AA6 -> 23.315833 | N6: =$F6*AB6 -> 21.348262 | O6: =$F6*AC6 -> 5.6880491 | P6: =$F6*AD6 -> 1.9760511 | Q6: =$F6*AE6 -> 4.2301544 | R6: =$F6*AF6 -> 89.514485 | S6: =$F6*AG6 -> 21.42779 | U6: 0.068102345 | V6: 0.043487395 | W6: 0.45586353944562896 | X6: 0.051531419 | Y6: 0.074626866 | Z6: 0.18319577502519416 | AA6: 0.084172682 | AB6: 0.077069539 | AC6: 0.020534473278014567 | AD6: 0.0071337584 | AE6: 0.015271315383277709 | AF6: 0.32315698611123234 | AG6: 0.077356642
A7: David Bednar | B7: NYY | C7: RP | D7: 62 | E7: 63.2 | F7: 259 | G7: =$D7*U7 -> 4.0615385 | H7: =$D7*V7 -> 3.6215385 | I7: =$D7*W7 -> 31.095385 | J7: =$D7*X7 -> 2.9723077 | K7: =$D7*Y7 -> 4 | L7: =$F7*Z7 -> 50.186779 | M7: =$F7*AA7 -> 25.01456 | N7: =$F7*AB7 -> 22.99612 | O7: =$F7*AC7 -> 7.0410314 | P7: =$F7*AD7 -> 1.9819695 | Q7: =$F7*AE7 -> 2.0184397 | R7: =$F7*AF7 -> 78.36962 | S7: =$F7*AG7 -> 21.711834 | U7: 0.065508685 | V7: 0.058411911 | W7: 0.5015384615384616 | X7: 0.047940447 | Y7: 0.064516129 | Z7: 0.19377134872395207 | AA7: 0.096581311 | AB7: 0.088788108 | AC7: 0.027185449 | AD7: 0.0076523917 | AE7: 0.0077932034 | AF7: 0.30258540404921175 | AG7: 0.083829476
A8: Aroldis Chapman | B8: BOS | C8: RP | D8: 57 | E8: 57.1 | F8: 234 | G8: =$D8*U8 -> 3.4983871 | H8: =$D8*V8 -> 2.3968894 | I8: =$D8*W8 -> 29.7 | J8: =$D8*X8 -> 2.4587558 | K8: =$D8*Y8 -> 4 | L8: =$F8*Z8 -> 40.372277 | M8: =$F8*AA8 -> 20.351222 | N8: =$F8*AB8 -> 18.806389 | O8: =$F8*AC8 -> 4.9621442 | P8: =$F8*AD8 -> 0.9753125 | Q8: =$F8*AE8 -> 1.5448329 | R8: =$F8*AF8 -> 80.674351 | S8: =$F8*AG8 -> 25.631427 | U8: 0.061375212224108605 | V8: 0.042050691244239595 | W8: 0.5210526315789473 | X8: 0.043136066 | Y8: 0.070175439 | Z8: 0.17253109926377247 | AA8: 0.086971035 | AB8: 0.080369185 | AC8: 0.021205744372514157 | AD8: 0.0041680021 | AE8: 0.0066018501 | AF8: 0.34476218 | AG8: 0.10953601242477184
A9: Devin Williams | B9: NYM | C9: RP | D9: 64 | E9: 64.1 | F9: 263 | G9: =$D9*U9 -> 4.5 | H9: =$D9*V9 -> 3.7983607 | I9: =$D9*W9 -> 30.4 | J9: =$D9*X9 -> 4.0295082 | K9: =$D9*Y9 -> 4 | L9: =$F9*Z9 -> 45.431865 | M9: =$F9*AA9 -> 24.769674 | N9: =$F9*AB9 -> 22.635657 | O9: =$F9*AC9 -> 5.8260196 | P9: =$F9*AD9 -> 0.99548021 | Q9: =$F9*AE9 -> 3.2010253 | R9: =$F9*AF9 -> 86.735984 | S9: =$F9*AG9 -> 26.827982 | U9: 0.0703125 | V9: 0.059349385245901595 | W9: 0.475 | X9: 0.062961066 | Y9: 0.0625 | Z9: 0.1727447328480401 | AA9: 0.094181271 | AB9: 0.086067138 | AC9: 0.022152166 | AD9: 0.0037850959 | AE9: 0.012171198823189951 | AF9: 0.32979461448390135 | AG9: 0.10200753445028252
A10: Josh Hader | B10: HOU | C10: RP | D10: 53 | E10: 56 | F10: 225 | G10: =$D10*U10 -> 3.6090909 | H10: =$D10*V10 -> 2.8373737 | I10: =$D10*W10 -> 28.178788 | J10: =$D10*X10 -> 1.8744108 | K10: =$D10*Y10 -> 3 | L10: =$F10*Z10 -> 38.757792 | M10: =$F10*AA10 -> 21.754499 | N10: =$F10*AB10 -> 19.790286 | O10: =$F10*AC10 -> 7.0050052 | P10: =$F10*AD10 -> 0.96081149 | Q10: =$F10*AE10 -> 2.1302651 | R10: =$F10*AF10 -> 78.220833 | S10: =$F10*AG10 -> 21.418024 | U10: 0.068096055 | V10: 0.053535354 | W10: 0.5316752429959978 | X10: 0.035366241 | Y10: 0.056603774 | Z10: 0.17225685402561325 | AA10: 0.096686663 | AB10: 0.087956825 | AC10: 0.031133357 | AD10: 0.0042702733 | AE10: 0.0094678448 | AF10: 0.3476481462392193 | AG10: 0.095191217
A11: Raisel Iglesias | B11: ATL | C11: RP | D11: 62 | E11: 63.2 | F11: 260 | G11: =$D11*U11 -> 3.5484848 | H11: =$D11*V11 -> 3.1732409 | I11: =$D11*W11 -> 25.684848 | J11: =$D11*X11 -> 3.9679507 | K11: =$D11*Y11 -> 4 | L11: =$F11*Z11 -> 55.987978 | M11: =$F11*AA11 -> 27.669078 | N11: =$F11*AB11 -> 25.541824 | O11: =$F11*AC11 -> 7.8874182 | P11: =$F11*AD11 -> 1.1711512 | Q11: =$F11*AE11 -> 2.1272541 | R11: =$F11*AF11 -> 68.394756 | S11: =$F11*AG11 -> 17.350377 | U11: 0.057233627 | V11: 0.051181304571135046 | W11: 0.4142717497556207 | X11: 0.063999205 | Y11: 0.064516129 | Z11: 0.21533837676766376 | AA11: 0.10641953019405884 | AB11: 0.098237784 | AC11: 0.030336224 | AD11: 0.0045044278 | AE11: 0.0081817464 | AF11: 0.2630567531452487 | AG11: 0.066732219
A12: Carlos Estevez | B12: KC | C12: RP | D12: 63 | E12: 64.2 | F12: 273 | G12: =$D12*U12 -> 3.4292308 | H12: =$D12*V12 -> 3.9771317 | I12: =$D12*W12 -> 31.609231 | J12: =$D12*X12 -> 2.0086571 | K12: =$D12*Y12 -> 5 | L12: =$F12*Z12 -> 58.582987 | M12: =$F12*AA12 -> 32.024002 | N12: =$F12*AB12 -> 29.863716 | O12: =$F12*AC12 -> 7.9381531 | P12: =$F12*AD12 -> 2.4778207 | Q12: =$F12*AE12 -> 2.654592 | R12: =$F12*AF12 -> 57.106009 | S12: =$F12*AG12 -> 23.830043 | U12: 0.054432234 | V12: 0.063129074 | W12: 0.50173382 | X12: 0.031883446 | Y12: 0.079365079 | Z12: 0.21458969597420208 | AA12: 0.11730404 | AB12: 0.10939090234830459 | AC12: 0.029077484 | AD12: 0.0090762664 | AE12: 0.0097237801 | AF12: 0.20917952 | AG12: 0.087289535
A13: Ryan Helsley | B13: BAL | C13: RP | D13: 61 | E13: 63.1 | F13: 264 | G13: =$D13*U13 -> 3.3921875 | H13: =$D13*V13 -> 3.0636161 | I13: =$D13*W13 -> 27.965625 | J13: =$D13*X13 -> 3.5151786 | K13: =$D13*Y13 -> 7 | L13: =$F13*Z13 -> 53.540646 | M13: =$F13*AA13 -> 26.195628 | N13: =$F13*AB13 -> 24.090879 | O13: =$F13*AC13 -> 6.8041356 | P13: =$F13*AD13 -> 1.69325 | Q13: =$F13*AE13 -> 1.5501275 | R13: =$F13*AF13 -> 73.545378 | S13: =$F13*AG13 -> 23.229898 | U13: 0.055609631 | V13: 0.050223214 | W13: 0.45845286885245895 | X13: 0.057625878 | Y13: 0.1147540983606557 | Z13: 0.20280547625748857 | AA13: 0.099225865 | AB13: 0.09125333 | AC13: 0.025773241 | AD13: 0.0064138257 | AE13: 0.0058716949 | AF13: 0.27858097784568375 | AG13: 0.087992039
A14: Jeff Hoffman | B14: TOR | C14: RP | D14: 61 | E14: 62 | F14: 256 | G14: =$D14*U14 -> 3.6206349 | H14: =$D14*V14 -> 4.3396825 | I14: =$D14*W14 -> 25.834921 | J14: =$D14*X14 -> 3.9619048 | K14: =$D14*Y14 -> 4 | L14: =$F14*Z14 -> 49.264766 | M14: =$F14*AA14 -> 25.980916 | N14: =$F14*AB14 -> 23.966076 | O14: =$F14*AC14 -> 7.7479084 | P14: =$F14*AD14 -> 1.1850926 | Q14: =$F14*AE14 -> 3.5342595 | R14: =$F14*AF14 -> 74.660308 | S14: =$F14*AG14 -> 23.158549 | U14: 0.059354670830080614 | V14: 0.071142337 | W14: 0.42352328909705955 | X14: 0.064949258 | Y14: 0.06557377 | Z14: 0.19244049329501914 | AA14: 0.1014879532442748 | AB14: 0.093617486 | AC14: 0.030265267175572493 | AD14: 0.0046292678 | AE14: 0.013805701 | AF14: 0.2916418269230769 | AG14: 0.090463083
A15: Kenley Jansen | B15: DET | C15: RP | D15: 55 | E15: 56 | F15: 233 | G15: =$D15*U15 -> 3.3083333 | H15: =$D15*V15 -> 3.1448718 | I15: =$D15*W15 -> 21.816667 | J15: =$D15*X15 -> 3.4461538 | K15: =$D15*Y15 -> 3 | L15: =$F15*Z15 -> 48.364286 | M15: =$F15*AA15 -> 27.685779 | N15: =$F15*AB15 -> 25.530074 | O15: =$F15*AC15 -> 7.9622891 | P15: =$F15*AD15 -> 1.1669291 | Q15: =$F15*AE15 -> 1.5613169 | R15: =$F15*AF15 -> 55.812237 | S15: =$F15*AG15 -> 20.601955 | U15: 0.060151515151515136 | V15: 0.057179487 | W15: 0.39666666666666667 | X15: 0.062657343 | Y15: 0.054545455 | Z15: 0.2075720416922133 | AA15: 0.11882308396306375 | AB15: 0.10957113270099358 | AC15: 0.034172915 | AD15: 0.0050082795 | AE15: 0.0067009309 | AF15: 0.23953749671542435 | AG15: 0.088420408
A16: Trevor Megill | B16: MIL | C16: RP | D16: 61 | E16: 64 | F16: 263 | G16: =$D16*U16 -> 3.5106061 | H16: =$D16*V16 -> 2.6312616 | I16: =$D16*W16 -> 18.033333 | J16: =$D16*X16 -> 8.2362709 | K16: =$D16*Y16 -> 6 | L16: =$F16*Z16 -> 52.648836 | M16: =$F16*AA16 -> 24.945427 | N16: =$F16*AB16 -> 22.975183 | O16: =$F16*AC16 -> 7.1365671 | P16: =$F16*AD16 -> 1.965495 | Q16: =$F16*AE16 -> 1.6702438 | R16: =$F16*AF16 -> 78.26461 | S16: =$F16*AG16 -> 22.796533 | U16: 0.057550919 | V16: 0.043135436 | W16: 0.2956284153005464 | X16: 0.13502083396696976 | Y16: 0.098360656 | Z16: 0.2001856873928278 | AA16: 0.094849532 | AB16: 0.087358111 | AC16: 0.027135236040891887 | AD16: 0.0074733652 | AE16: 0.006350737 | AF16: 0.29758406823291056 | AG16: 0.086678832
A17: Emilio Pagan | B17: CIN | C17: RP | D17: 63 | E17: 65 | F17: 267 | G17: =$D17*U17 -> 2.9045455 | H17: =$D17*V17 -> 3.0611285 | I17: =$D17*W17 -> 25.954545 | J17: =$D17*X17 -> 4.0144201 | K17: =$D17*Y17 -> 5 | L17: =$F17*Z17 -> 54.846981 | M17: =$F17*AA17 -> 31.625617 | N17: =$F17*AB17 -> 29.165233 | O17: =$F17*AC17 -> 9.8742703 | P17: =$F17*AD17 -> 0.98657163 | Q17: =$F17*AE17 -> 1.5722784 | R17: =$F17*AF17 -> 71.167893 | S17: =$F17*AG17 -> 22.763815 | U17: 0.046103896103896064 | V17: 0.048589342 | W17: 0.41197691 | X17: 0.063720953 | Y17: 0.079365079 | Z17: 0.20541940480592571 | AA17: 0.11844800455235471 | AB17: 0.10923308277102514 | AC17: 0.036982286 | AD17: 0.0036950248 | AE17: 0.0058886831 | AF17: 0.2665464173327077 | AG17: 0.085257734
A18: Daniel Palencia | B18: CHC | C18: RP | D18: 62 | E18: 64.2 | F18: 273 | G18: =$D18*U18 -> 3.2134328 | H18: =$D18*V18 -> 3.2860189 | I18: =$D18*W18 -> 28.752239 | J18: =$D18*X18 -> 4.1226927 | K18: =$D18*Y18 -> 4 | L18: =$F18*Z18 -> 52.577006 | M18: =$F18*AA18 -> 28.919832 | N18: =$F18*AB18 -> 26.809141 | O18: =$F18*AC18 -> 7.0937746 | P18: =$F18*AD18 -> 1.188337 | Q18: =$F18*AE18 -> 3.7277646 | R18: =$F18*AF18 -> 73.427213 | S18: =$F18*AG18 -> 27.063357 | U18: 0.051829562 | V18: 0.053000305 | W18: 0.46374578719306686 | X18: 0.066495043 | Y18: 0.064516129 | Z18: 0.19258976620087725 | AA18: 0.10593345014148792 | AB18: 0.098201982 | AC18: 0.025984522 | AD18: 0.0043528827 | AE18: 0.013654815546068448 | AF18: 0.26896415028802734 | AG18: 0.099133176
A19: Pete Fairbanks | B19: MIA | C19: RP | D19: 61 | E19: 63 | F19: 261 | G19: =$D19*U19 -> 3.4629032 | H19: =$D19*V19 -> 3.1394428 | I19: =$D19*W19 -> 26.112903 | J19: =$D19*X19 -> 4.0679179 | K19: =$D19*Y19 -> 5 | L19: =$F19*Z19 -> 53.294178 | M19: =$F19*AA19 -> 26.055397 | N19: =$F19*AB19 -> 23.860528 | O19: =$F19*AC19 -> 5.6997779 | P19: =$F19*AD19 -> 0.99813531 | Q19: =$F19*AE19 -> 1.5989792 | R19: =$F19*AF19 -> 65.227879 | S19: =$F19*AG19 -> 22.697838 | U19: 0.056768905341089304 | V19: 0.051466276 | W19: 0.4280803807509254 | X19: 0.066687179 | Y19: 0.081967213 | Z19: 0.20419225318847423 | AA19: 0.099829109 | AB19: 0.091419647 | AC19: 0.021838229 | AD19: 0.0038242732 | AE19: 0.0061263571 | AF19: 0.24991524464651232 | AG19: 0.086964897
A20: Dennis Santana | B20: PIT | C20: RP | D20: 64 | E20: 66.2 | F20: 280 | G20: =$D20*U20 -> 3.3647059 | H20: =$D20*V20 -> 2.9355742 | I20: =$D20*W20 -> 24.094118 | J20: =$D20*X20 -> 5.9276377 | K20: =$D20*Y20 -> 3 | L20: =$F20*Z20 -> 59.742186 | M20: =$F20*AA20 -> 30.059043 | N20: =$F20*AB20 -> 27.496452 | O20: =$F20*AC20 -> 6.4224566 | P20: =$F20*AD20 -> 1.4722923 | Q20: =$F20*AE20 -> 3.1052266 | R20: =$F20*AF20 -> 62.495403 | S20: =$F20*AG20 -> 22.58205 | U20: 0.052573529411764686 | V20: 0.045868347 | W20: 0.3764705882352941 | X20: 0.092619339 | Y20: 0.046875 | Z20: 0.21336494900448383 | AA20: 0.10735372355607309 | AB20: 0.098201613 | AC20: 0.022937345 | AD20: 0.0052581868 | AE20: 0.011090095 | AF20: 0.2231978693868638 | AG20: 0.08065018
A21: Robert Suarez | B21: ATL | C21: RP | D21: 64 | E21: 66.1 | F21: 273 | G21: =$D21*U21 -> 4.3656716 | H21: =$D21*V21 -> 4.0605394 | I21: =$D21*W21 -> 10.328358 | J21: =$D21*X21 -> 12.622414 | K21: =$D21*Y21 -> 5 | L21: =$F21*Z21 -> 58.438126 | M21: =$F21*AA21 -> 28.694856 | N21: =$F21*AB21 -> 26.494085 | O21: =$F21*AC21 -> 7.5807283 | P21: =$F21*AD21 -> 1.9757239 | Q21: =$F21*AE21 -> 2.2007704 | R21: =$F21*AF21 -> 68.004214 | S21: =$F21*AG21 -> 21.042569 | U21: 0.068213619 | V21: 0.063445928 | W21: 0.16138059701492538 | X21: 0.19722522257135372 | Y21: 0.078125 | Z21: 0.21405906788075396 | AA21: 0.10510936189296152 | AB21: 0.097047932 | AC21: 0.027768236 | AD21: 0.0072370839 | AE21: 0.0080614299 | AF21: 0.24909968469918628 | AG21: 0.077079007
A22: Ryan Walker | B22: SF | C22: RP | D22: 60 | E22: 62 | F22: 261 | G22: =$D22*U22 -> 3.5809524 | H22: =$D22*V22 -> 3.4940476 | I22: =$D22*W22 -> 24.342857 | J22: =$D22*X22 -> 4.8660714 | K22: =$D22*Y22 -> 4 | L22: =$F22*Z22 -> 55.060352 | M22: =$F22*AA22 -> 24.909169 | N22: =$F22*AB22 -> 22.940435 | O22: =$F22*AC22 -> 5.4187803 | P22: =$F22*AD22 -> 0.99359754 | Q22: =$F22*AE22 -> 4.9077272 | R22: =$F22*AF22 -> 66.419432 | S22: =$F22*AG22 -> 19.860198 | U22: 0.05968254 | V22: 0.058234127 | W22: 0.4057142857142857 | X22: 0.08110119 | Y22: 0.066666667 | Z22: 0.21095920161896853 | AA22: 0.095437428 | AB22: 0.087894388 | AC22: 0.02076161 | AD22: 0.0038068871 | AE22: 0.018803553 | AF22: 0.2544805832974016 | AG22: 0.076092712
A23: Matt Strahm | B23: KC | C23: RP | D23: 62 | E23: 64.1 | F23: 262 | G23: =$D23*U23 -> 3.3606061 | H23: =$D23*V23 -> 2.2901776 | I23: =$D23*W23 -> 1.7878788 | J23: =$D23*X23 -> 17.925392 | K23: =$D23*Y23 -> 3 | L23: =$F23*Z23 -> 53.037594 | M23: =$F23*AA23 -> 26.447095 | N23: =$F23*AB23 -> 24.541656 | O23: =$F23*AC23 -> 7.5170445 | P23: =$F23*AD23 -> 1.1765796 | Q23: =$F23*AE23 -> 3.1439768 | R23: =$F23*AF23 -> 69.07413 | S23: =$F23*AG23 -> 19.414371 | U23: 0.054203323558162216 | V23: 0.036938349 | W23: 0.028836754643206217 | X23: 0.28911922337951257 | Y23: 0.048387097 | Z23: 0.20243356482810076 | AA23: 0.10094310983802618 | AB23: 0.093670442 | AC23: 0.028691009 | AD23: 0.0044907619 | AE23: 0.011999911409039221 | AF23: 0.2636417194121592 | AG23: 0.074100652
A24: Tyler Rogers | B24: TOR | C24: RP | D24: 68 | E24: 69 | F24: 286 | G24: =$D24*U24 -> 3.9567568 | H24: =$D24*V24 -> 3.1540541 | I24: =$D24*W24 -> 1.9675676 | J24: =$D24*X24 -> 20.062162 | K24: =$D24*Y24 -> 3 | L24: =$F24*Z24 -> 67.406596 | M24: =$F24*AA24 -> 31.175715 | N24: =$F24*AB24 -> 28.673418 | O24: =$F24*AC24 -> 7.2795593 | P24: =$F24*AD24 -> 1.1652055 | Q24: =$F24*AE24 -> 3.0319269 | R24: =$F24*AF24 -> 47.887305 | S24: =$F24*AG24 -> 16.48766 | U24: 0.058187599364069906 | V24: 0.046383148 | W24: 0.028934817 | X24: 0.29503179650238476 | Y24: 0.044117647 | Z24: 0.23568739858492505 | AA24: 0.10900599634776845 | AB24: 0.10025670531999645 | AC24: 0.025453004566928582 | AD24: 0.0040741452 | AE24: 0.010601143 | AF24: 0.16743812933523539 | AG24: 0.05764916
A25: Luke Weaver | B25: NYM | C25: RP | D25: 60 | E25: 67.2 | F25: 280 | G25: =$D25*U25 -> 3.7074627 | H25: =$D25*V25 -> 4.0755795 | I25: =$D25*W25 -> 4.7164179 | J25: =$D25*X25 -> 16.835662 | K25: =$D25*Y25 -> 3 | L25: =$F25*Z25 -> 59.965664 | M25: =$F25*AA25 -> 32.522217 | N25: =$F25*AB25 -> 29.795069 | O25: =$F25*AC25 -> 9.4522962 | P25: =$F25*AD25 -> 1.3926016 | Q25: =$F25*AE25 -> 2.1502457 | R25: =$F25*AF25 -> 71.744186 | S25: =$F25*AG25 -> 22.489652 | U25: 0.061791045 | V25: 0.067926326 | W25: 0.078606965 | X25: 0.28059436858261877 | Y25: 0.05 | Z25: 0.21416308628714636 | AA25: 0.1161507734766504 | AB25: 0.10641095940155415 | AC25: 0.033758201 | AD25: 0.0049735772 | AE25: 0.007679449 | AF25: 0.25622923727795005 | AG25: 0.080320185
A26: Alex Vesia | B26: LAD | C26: RP | D26: 62 | E26: 61.2 | F26: 254 | G26: =$D26*U26 -> 3.5377049 | H26: =$D26*V26 -> 2.8922372 | I26: =$D26*W26 -> 1.8032787 | J26: =$D26*X26 -> 19.770878 | K26: =$D26*Y26 -> 3 | L26: =$F26*Z26 -> 46.314196 | M26: =$F26*AA26 -> 25.939384 | N26: =$F26*AB26 -> 23.91986 | O26: =$F26*AC26 -> 8.3652567 | P26: =$F26*AD26 -> 2.0000926 | Q26: =$F26*AE26 -> 3.0292864 | R26: =$F26*AF26 -> 78.504418 | S26: =$F26*AG26 -> 25.250622 | U26: 0.057059757 | V26: 0.046648987 | W26: 0.029085140137493356 | X26: 0.31888512147323234 | Y26: 0.048387097 | Z26: 0.1823393547580746 | AA26: 0.10212356037552539 | AB26: 0.094172677 | AC26: 0.032934081432365134 | AD26: 0.0078743805 | AE26: 0.011926325 | AF26: 0.3090725116232841 | AG26: 0.099411896
A27: Kyle Finnegan | B27: DET | C27: RP | D27: 59 | E27: 61 | F27: 256 | G27: =$D27*U27 -> 3.3203125 | H27: =$D27*V27 -> 3.9779776 | I27: =$D27*W27 -> 5.5375 | J27: =$D27*X27 -> 12.989652 | K27: =$D27*Y27 -> 5 | L27: =$F27*Z27 -> 57.254485 | M27: =$F27*AA27 -> 29.056402 | N27: =$F27*AB27 -> 26.634286 | O27: =$F27*AC27 -> 7.3911111 | P27: =$F27*AD27 -> 1.6769337 | Q27: =$F27*AE27 -> 0.97925926 | R27: =$F27*AF27 -> 56.393439 | S27: =$F27*AG27 -> 22.15873 | U27: 0.056276483 | V27: 0.067423349 | W27: 0.093855932 | X27: 0.2201635952990086 | Y27: 0.084745763 | Z27: 0.2236503322259136 | AA27: 0.11350157076719572 | AB27: 0.10404017857142855 | AC27: 0.028871528 | AD27: 0.0065505222 | AE27: 0.0038252315 | AF27: 0.22028687169312164 | AG27: 0.08655754
A28: Garrett Whitlock | B28: BOS | C28: RP | D28: 58 | E28: 64 | F28: 262 | G28: =$D28*U28 -> 3.6857143 | H28: =$D28*V28 -> 3.1761905 | I28: =$D28*W28 -> 3.6971429 | J28: =$D28*X28 -> 16.588889 | K28: =$D28*Y28 -> 2 | L28: =$F28*Z28 -> 54.960481 | M28: =$F28*AA28 -> 25.176632 | N28: =$F28*AB28 -> 23.316151 | O28: =$F28*AC28 -> 6.2419244 | P28: =$F28*AD28 -> 1.1601375 | Q28: =$F28*AE28 -> 2.7907216 | R28: =$F28*AF28 -> 71.906478 | S28: =$F28*AG28 -> 17.644555 | U28: 0.063546798 | V28: 0.054761905 | W28: 0.063743842 | X28: 0.2860153256704981 | Y28: 0.034482759 | Z28: 0.20977282862464253 | AA28: 0.096094016 | AB28: 0.088992944 | AC28: 0.023824139 | AD28: 0.0044280056 | AE28: 0.010651609 | AF28: 0.2744522064099481 | AG28: 0.067345628
A29: Adrian Morejon | B29: SD | C29: RP | D29: 65 | E29: 66.1 | F29: 274 | G29: =$D29*U29 -> 4.8588235 | H29: =$D29*V29 -> 5.0073529 | I29: =$D29*W29 -> 2.9735294 | J29: =$D29*X29 -> 14.827941 | K29: =$D29*Y29 -> 2 | L29: =$F29*Z29 -> 57.405882 | M29: =$F29*AA29 -> 27.140399 | N29: =$F29*AB29 -> 24.950068 | O29: =$F29*AC29 -> 5.7588079 | P29: =$F29*AD29 -> 1.4886525 | Q29: =$F29*AE29 -> 1.492329 | R29: =$F29*AF29 -> 66.919112 | S29: =$F29*AG29 -> 22.291792 | U29: 0.074751131 | V29: 0.077036199 | W29: 0.045746606 | X29: 0.2281221719457013 | Y29: 0.030769231 | Z29: 0.2095105195362816 | AA29: 0.099052553 | AB29: 0.091058642 | AC29: 0.021017547 | AD29: 0.0054330383 | AE29: 0.005446456 | AF29: 0.24423033734382085 | AG29: 0.081356904
A30: Will Vest | B30: DET | C30: RP | D30: 61 | E30: 64 | F30: 265 | G30: =$D30*U30 -> 3.7117647 | H30: =$D30*V30 -> 3.5583333 | I30: =$D30*W30 -> 6.4970588 | J30: =$D30*X30 -> 13.169412 | K30: =$D30*Y30 -> 5 | L30: =$F30*Z30 -> 56.111102 | M30: =$F30*AA30 -> 25.711015 | N30: =$F30*AB30 -> 23.74765 | O30: =$F30*AC30 -> 5.1575273 | P30: =$F30*AD30 -> 1.1700973 | Q30: =$F30*AE30 -> 1.9633643 | R30: =$F30*AF30 -> 65.286625 | S30: =$F30*AG30 -> 20.310495 | U30: 0.060848602 | V30: 0.058333333333333286 | W30: 0.10650916104146572 | X30: 0.21589199614271937 | Y30: 0.081967213 | Z30: 0.2117400093591103 | AA30: 0.097022697 | AB30: 0.089613775 | AC30: 0.019462367 | AD30: 0.0044154617 | AE30: 0.0074089218 | AF30: 0.24636462408950827 | AG30: 0.076643379
A31: Kirby Yates | B31: LAA | C31: RP | D31: 55 | E31: 56.1 | F31: 239 | G31: =$D31*U31 -> 2.9625 | H31: =$D31*V31 -> 4.1577381 | I31: =$D31*W31 -> 7.9857143 | J31: =$D31*X31 -> 10.785714 | K31: =$D31*Y31 -> 2 | L31: =$F31*Z31 -> 45.451005 | M31: =$F31*AA31 -> 27.11031 | N31: =$F31*AB31 -> 24.795443 | O31: =$F31*AC31 -> 6.9917906 | P31: =$F31*AD31 -> 0 | Q31: =$F31*AE31 -> 3.2714609 | R31: =$F31*AF31 -> 67.55425 | S31: =$F31*AG31 -> 26.626663 | U31: 0.053863636 | V31: 0.075595238 | W31: 0.14519481 | X31: 0.19610389610389606 | Y31: 0.036363636 | Z31: 0.19017157 | AA31: 0.1134322605772273 | AB31: 0.10374662256276823 | AC31: 0.029254353817484452 | AE31: 0.013688121 | AF31: 0.2826537637988302 | AG31: 0.11140863356053221
A32: Abner Uribe | B32: MIL | C32: RP | D32: 67 | E32: 68.2 | F32: 286 | G32: =$D32*U32 -> 3.8055556 | H32: =$D32*V32 -> 1.5311869 | I32: =$D32*W32 -> 16.336111 | J32: =$D32*X32 -> 11.875379 | K32: =$D32*Y32 -> 3 | L32: =$F32*Z32 -> 50.627998 | M32: =$F32*AA32 -> 26.009448 | N32: =$F32*AB32 -> 23.808746 | O32: =$F32*AC32 -> 5.2858632 | P32: =$F32*AD32 -> 1.9767174 | Q32: =$F32*AE32 -> 4.3494394 | R32: =$F32*AF32 -> 82.841971 | S32: =$F32*AG32 -> 31.697818 | U32: 0.056799337 | V32: 0.022853535353535293 | W32: 0.24382255389718074 | X32: 0.1772444595205789 | Y32: 0.044776119 | Z32: 0.17702097145612153 | AA32: 0.090942127 | AB32: 0.083247362 | AC32: 0.018482039155288413 | AD32: 0.0069115991 | AE32: 0.01520783 | AF32: 0.2896572427729232 | AG32: 0.11083153230382861
A33: Bryan Abreu | B33: HOU | C33: RP | D33: 65 | E33: 67.1 | F33: 279 | G33: =$D33*U33 -> 3.5764706 | H33: =$D33*V33 -> 2.184676 | I33: =$D33*W33 -> 7.7735294 | J33: =$D33*X33 -> 16.177217 | K33: =$D33*Y33 -> 4 | L33: =$F33*Z33 -> 49.848328 | M33: =$F33*AA33 -> 23.944629 | N33: =$F33*AB33 -> 21.785614 | O33: =$F33*AC33 -> 6.3738533 | P33: =$F33*AD33 -> 0.99259065 | Q33: =$F33*AE33 -> 3.7244129 | R33: =$F33*AF33 -> 91.01241 | S33: =$F33*AG33 -> 28.347656 | U33: 0.055022624 | V33: 0.033610400682011904 | W33: 0.11959276018099543 | X33: 0.24888025444291426 | Y33: 0.061538462 | Z33: 0.17866784365080984 | AA33: 0.085823044 | AB33: 0.078084639 | AC33: 0.022845352 | AD33: 0.0035576726 | AE33: 0.01334915 | AF33: 0.32620935467584833 | AG33: 0.10160450196406799
A34: Seranthony Dominguez | B34: CWS | C34: RP | D34: 62 | E34: 61.2 | F34: 262 | G34: =$D34*U34 -> 3.1634921 | H34: =$D34*V34 -> 3.6730159 | I34: =$D34*W34 -> 20.736508 | J34: =$D34*X34 -> 5.9714286 | K34: =$D34*Y34 -> 5 | L34: =$F34*Z34 -> 51.061506 | M34: =$F34*AA34 -> 29.169312 | N34: =$F34*AB34 -> 27.082033 | O34: =$F34*AC34 -> 7.7830887 | P34: =$F34*AD34 -> 0.99552239 | Q34: =$F34*AE34 -> 2.5828015 | R34: =$F34*AF34 -> 69.452632 | S34: =$F34*AG34 -> 29.213826 | U34: 0.051024065540194535 | V34: 0.059242192 | W34: 0.33445980542754733 | X34: 0.096313364 | Y34: 0.080645161 | Z34: 0.19489124532881913 | AA34: 0.11133325356354065 | AB34: 0.10336653949581992 | AC34: 0.029706446 | AD34: 0.0037997038 | AE34: 0.0098580209 | AF34: 0.26508638258132816 | AG34: 0.11150315368762874
A35: Griffin Jax | B35: TB | C35: RP | D35: 65 | E35: 65.2 | F35: 265 | G35: =$D35*U35 -> 4.1104478 | H35: =$D35*V35 -> 2.8890474 | I35: =$D35*W35 -> 14.328358 | J35: =$D35*X35 -> 11.822212 | K35: =$D35*Y35 -> 6 | L35: =$F35*Z35 -> 52.100432 | M35: =$F35*AA35 -> 23.117987 | N35: =$F35*AB35 -> 21.133468 | O35: =$F35*AC35 -> 5.9359746 | P35: =$F35*AD35 -> 1.6827228 | Q35: =$F35*AE35 -> 1.984519 | R35: =$F35*AF35 -> 85.491939 | S35: =$F35*AG35 -> 18.462407 | U35: 0.063237658 | V35: 0.044446883230904254 | W35: 0.22043628013777264 | X35: 0.1818801918011751 | Y35: 0.092307692 | Z35: 0.19660540239487606 | AA35: 0.087237688 | AB35: 0.079748937 | AC35: 0.022399904 | AD35: 0.0063498975 | AE35: 0.0074887509 | AF35: 0.3226110921031769 | AG35: 0.069669459
A36: Robert Garcia | B36: TEX | C36: RP | D36: 62 | E36: 61.2 | F36: 257 | G36: =$D36*U36 -> 3.621875 | H36: =$D36*V36 -> 3.646875 | I36: =$D36*W36 -> 17.475 | J36: =$D36*X36 -> 7.44375 | K36: =$D36*Y36 -> 5 | L36: =$F36*Z36 -> 52.94294 | M36: =$F36*AA36 -> 26.479272 | N36: =$F36*AB36 -> 24.439503 | O36: =$F36*AC36 -> 6.5791592 | P36: =$F36*AD36 -> 1.9729607 | Q36: =$F36*AE36 -> 2.0397693 | R36: =$F36*AF36 -> 67.260786 | S36: =$F36*AG36 -> 21.784858 | U36: 0.058417339 | V36: 0.058820565 | W36: 0.28185483870967737 | X36: 0.12006048387096772 | Y36: 0.080645161 | Z36: 0.2060036585924744 | AA36: 0.10303218838811262 | AB36: 0.095095343 | AC36: 0.025599841 | AD36: 0.00767689 | AE36: 0.0079368455 | AF36: 0.2617151189816398 | AG36: 0.084765985
A37: Edwin Uceta | B37: TB | C37: RP | D37: 63 | E37: 68.1 | F37: 283 | G37: =$D37*U37 -> 3.8161765 | H37: =$D37*V37 -> 3.7105932 | I37: =$D37*W37 -> 11.823529 | J37: =$D37*X37 -> 13.406505 | K37: =$D37*Y37 -> 2 | L37: =$F37*Z37 -> 54.485845 | M37: =$F37*AA37 -> 29.649069 | N37: =$F37*AB37 -> 27.691155 | O37: =$F37*AC37 -> 8.8074421 | P37: =$F37*AD37 -> 1.9841088 | Q37: =$F37*AE37 -> 4.6758534 | R37: =$F37*AF37 -> 82.258481 | S37: =$F37*AG37 -> 25.174047 | U37: 0.060574229691876695 | V37: 0.058898305084745736 | W37: 0.18767507002801115 | X37: 0.21280167434205316 | Y37: 0.031746032 | Z37: 0.19252948599066932 | AA37: 0.10476702823396622 | AB37: 0.097848606 | AC37: 0.031121704 | AD37: 0.0070109851 | AE37: 0.016522450267274072 | AF37: 0.2906660088429268 | AG37: 0.088954229
A38: Riley O'Brien | B38: STL | C38: RP | D38: 61 | E38: 63.1 | F38: 275 | G38: =$D38*U38 -> 2.9333333 | H38: =$D38*V38 -> 2.4548086 | I38: =$D38*W38 -> 15.898413 | J38: =$D38*X38 -> 11.267227 | K38: =$D38*Y38 -> 5 | L38: =$F38*Z38 -> 54.234066 | M38: =$F38*AA38 -> 28.93238 | N38: =$F38*AB38 -> 26.791771 | O38: =$F38*AC38 -> 5.8693668 | P38: =$F38*AD38 -> 2.0111117 | Q38: =$F38*AE38 -> 6.2787492 | R38: =$F38*AF38 -> 66.334774 | S38: =$F38*AG38 -> 28.643337 | U38: 0.048087432 | V38: 0.040242764 | W38: 0.2606297163674212 | X38: 0.18470863755338196 | Y38: 0.081967213 | Z38: 0.1972147864151108 | AA38: 0.10520865546557404 | AB38: 0.097424622 | AC38: 0.021343152 | AD38: 0.0073131335 | AE38: 0.022831815 | AF38: 0.24121735877291428 | AG38: 0.10415758896151049

Sheet P14_Rank
A1: Name | B1: =P14_Relievers!B1 -> Team | C1: =P14_Relievers!C1 -> Position | D1: =P14_Relievers!D1 -> G | E1: IP | F1: =P14_Relievers!F1 -> TBF | G1: W+ | H1: ERA | I1: WHIP | J1: K/9+ | K1: BB/9+ | L1: SV+HLD+ | M1: K-BB%+ | N1: Total | P1: W | Q1: L | R1: SV+HLD | S1: BS | T1: H | U1: R | V1: ER | W1: HR | X1: IBB | Y1: HBP | Z1: K/9 | AA1: BB/9 | AB1: ERA | AC1: WHIP | AD1: K-BB% | AF1: =P14_Relievers!G1 -> W | AG1: =P14_Relievers!H1 -> L | AH1: =P14_Relievers!I1 -> SV | AI1: =P14_Relievers!J1 -> HLD | AJ1: SV+HLD | AK1: =P14_Relievers!K1 -> BS | AL1: =P14_Relievers!L1 -> H | AM1: =P14_Relievers!M1 -> R | AN1: =P14_Relievers!N1 -> ER | AO1: =P14_Relievers!O1 -> HR | AP1: =P14_Relievers!P1 -> IBB | AQ1: =P14_Relievers!Q1 -> HBP | AR1: =P14_Relievers!R1 -> SO | AS1: =P14_Relievers!S1 -> BB | AT1: K/9 | AU1: BB/9 | AV1: ERA | AW1: WHIP | AX1: K-BB%
A2: Mason Miller | B2: =P14_Relievers!B2 -> SD | C2: =P14_Relievers!C2 -> RP | D2: =P14_Relievers!D2 -> 59 | E2: 64.67 | F2: =P14_Relievers!F2 -> 254 | G2: =(P2-P$39)/P$40 -> -0.5882652 | H2: =(AB2-AB$39)/AB$40 -> 2.2529326 | I2: =(AC2-AC$39)/AC$40 -> 2.8794218 | J2: =(Z2-Z$39)/Z$40 -> 2.5380756 | K2: =(AA2-AA$39)/AA$40 -> -0.12502321 | L2: =(R2-R$39)/R$40 -> 1.2171985 | M2: =(AD2-AD$39)/AD$40 -> 2.8151292 | N2: =G2+H2+I2+J2+K2+L2+M2*2 -> 13.804599 | P2: =(AF2-AVERAGE(AF$2:AF$38))/AVERAGE(AF$2:AF$38)*100+100 -> 92.340169 | Q2: =(AVERAGE(AG$2:AG$38)-AG2)/AVERAGE(AG$2:AG$38)*100+100 -> 161.27238 | R2: =(AJ2-AVERAGE(AJ$2:AJ$38))/AVERAGE(AJ$2:AJ$38)*100+100 -> 125.07096 | S2: =(AVERAGE(AK$2:AK$38)-AK2)/AVERAGE(AK$2:AK$38)*100+100 -> 101.98675 | T2: =(AVERAGE(AL$2:AL$38)-AL2)/AVERAGE(AL$2:AL$38)*100+100 -> 126.57524 | U2: =(AVERAGE(AM$2:AM$38)-AM2)/AVERAGE(AM$2:AM$38)*100+100 -> 128.06687 | V2: =(AVERAGE(AN$2:AN$38)-AN2)/AVERAGE(AN$2:AN$38)*100+100 -> 126.87729 | W2: =(AVERAGE(AO$2:AO$38)-AO2)/AVERAGE(AO$2:AO$38)*100+100 -> 109.6023 | X2: =(AVERAGE(AP$2:AP$38)-AP2)/AVERAGE(AP$2:AP$38)*100+100 -> 64.378098 | Y2: =(AVERAGE(AQ$2:AQ$38)-AQ2)/AVERAGE(AQ$2:AQ$38)*100+100 -> 127.63525 | Z2: =(AT2-AVERAGE(AT$2:AT$38))/AVERAGE(AT$2:AT$38)*100+100 -> 138.16335 | AA2: =(AVERAGE(AU$2:AU$38)-AU2)/AVERAGE(AU$2:AU$38)*100+100 -> 98.021095 | AB2: =(AVERAGE(AV$2:AV$38)-AV2)/AVERAGE(AV$2:AV$38)*100+100 -> 127.93845 | AC2: =(AVERAGE(AW$2:AW$38)-AW2)/AVERAGE(AW$2:AW$38)*100+100 -> 118.42893 | AD2: =(AX2-AVERAGE(AX$2:AX$38))/AVERAGE(AX$2:AX$38)*100+100 -> 162.13498 | AF2: =P14_Relievers!G2 -> 3.4030303 | AG2: =P14_Relievers!H2 -> 1.2237722 | AH2: =P14_Relievers!I2 -> 32.121212 | AI2: =P14_Relievers!J2 -> 2.4432602 | AJ2: =AH2+AI2 -> 34.564472 | AK2: =P14_Relievers!K2 -> 4 | AL2: =P14_Relievers!L2 -> 38.174295 | AM2: =P14_Relievers!M2 -> 18.934816 | AN2: =P14_Relievers!N2 -> 17.717123 | AO2: =P14_Relievers!O2 -> 6.1266876 | AP2: =P14_Relievers!P2 -> 1.9770095 | AQ2: =P14_Relievers!Q2 -> 2.0490733 | AR2: =P14_Relievers!R2 -> 103.17949 | AS2: =P14_Relievers!S2 -> 23.88218 | AT2: =AR2/$E2*9 -> 14.359293 | AU2: =AS2/$E2*9 -> 3.3236372 | AV2: =AN2/$E2*9 -> 2.4656581 | AW2: =(AS2+AL2)/E2 -> 0.95958675 | AX2: =(AR2-AS2)/F2 -> 0.31219415
A3: Edwin Diaz | B3: =P14_Relievers!B3 -> LAD | C3: =P14_Relievers!C3 -> RP | D3: =P14_Relievers!D3 -> 64 | E3: 65.67 | F3: =P14_Relievers!F3 -> 265 | G3: =(P3-P$39)/P$40 -> 1.508274 | H3: =(AB3-AB$39)/AB$40 -> 1.0866525 | I3: =(AC3-AC$39)/AC$40 -> 1.4374224 | J3: =(Z3-Z$39)/Z$40 -> 1.4315205 | K3: =(AA3-AA$39)/AA$40 -> 0.19348142 | L3: =(R3-R$39)/R$40 -> 2.1067886 | M3: =(AD3-AD$39)/AD$40 -> 1.6051982 | N3: =G3+H3+I3+J3+K3+L3+M3*2 -> 10.974536 | P3: =(AF3-AVERAGE(AF$2:AF$38))/AVERAGE(AF$2:AF$38)*100+100 -> 119.63931 | Q3: =(AVERAGE(AG$2:AG$38)-AG3)/AVERAGE(AG$2:AG$38)*100+100 -> 124.57426 | R3: =(AJ3-AVERAGE(AJ$2:AJ$38))/AVERAGE(AJ$2:AJ$38)*100+100 -> 143.39408 | S3: =(AVERAGE(AK$2:AK$38)-AK3)/AVERAGE(AK$2:AK$38)*100+100 -> 77.483444 | T3: =(AVERAGE(AL$2:AL$38)-AL3)/AVERAGE(AL$2:AL$38)*100+100 -> 109.42047 | U3: =(AVERAGE(AM$2:AM$38)-AM3)/AVERAGE(AM$2:AM$38)*100+100 -> 109.89227 | V3: =(AVERAGE(AN$2:AN$38)-AN3)/AVERAGE(AN$2:AN$38)*100+100 -> 110.84372 | W3: =(AVERAGE(AO$2:AO$38)-AO3)/AVERAGE(AO$2:AO$38)*100+100 -> 99.115667 | X3: =(AVERAGE(AP$2:AP$38)-AP3)/AVERAGE(AP$2:AP$38)*100+100 -> 132.06014 | Y3: =(AVERAGE(AQ$2:AQ$38)-AQ3)/AVERAGE(AQ$2:AQ$38)*100+100 -> 37.607812 | Z3: =(AT3-AVERAGE(AT$2:AT$38))/AVERAGE(AT$2:AT$38)*100+100 -> 121.52482 | AA3: =(AVERAGE(AU$2:AU$38)-AU3)/AVERAGE(AU$2:AU$38)*100+100 -> 103.06248 | AB3: =(AVERAGE(AV$2:AV$38)-AV3)/AVERAGE(AV$2:AV$38)*100+100 -> 113.4755 | AC3: =(AVERAGE(AW$2:AW$38)-AW3)/AVERAGE(AW$2:AW$38)*100+100 -> 109.19982 | AD3: =(AX3-AVERAGE(AX$2:AX$38))/AVERAGE(AX$2:AX$38)*100+100 -> 135.42962 | AF3: =P14_Relievers!G3 -> 4.4090909 | AG3: =P14_Relievers!H3 -> 2.3834131 | AH3: =P14_Relievers!I3 -> 36.581818 | AI3: =P14_Relievers!J3 -> 3.0464115 | AJ3: =AH3+AI3 -> 39.62823 | AK3: =P14_Relievers!K3 -> 5 | AL3: =P14_Relievers!L3 -> 47.093238 | AM3: =P14_Relievers!M3 -> 23.718879 | AN3: =P14_Relievers!N3 -> 21.601945 | AO3: =P14_Relievers!O3 -> 6.8374173 | AP3: =P14_Relievers!P3 -> 0.99038396 | AQ3: =P14_Relievers!Q3 -> 4.5982815 | AR3: =P14_Relievers!R3 -> 92.157286 | AS3: =P14_Relievers!S3 -> 23.052587 | AT3: =AR3/$E3*9 -> 12.630053 | AU3: =AS3/$E3*9 -> 3.1593312 | AV3: =AN3/$E3*9 -> 2.9605224 | AW3: =(AS3+AL3)/E3 -> 1.0681563 | AX3: =(AR3-AS3)/F3 -> 0.26077245
A4: Cade Smith | B4: =P14_Relievers!B6 -> CLE | C4: =P14_Relievers!C6 -> RP | D4: =P14_Relievers!D6 -> 67 | E4: 69 | F4: =P14_Relievers!F6 -> 277 | G4: =(P4-P$39)/P$40 -> 1.8287089 | H4: =(AB4-AB$39)/AB$40 -> 1.5013645 | I4: =(AC4-AC$39)/AC$40 -> 1.7318867 | J4: =(Z4-Z$39)/Z$40 -> 0.82088757 | K4: =(AA4-AA$39)/AA$40 -> 0.89986926 | L4: =(R4-R$39)/R$40 -> 1.1172361 | M4: =(AD4-AD$39)/AD$40 -> 1.2529109 | N4: =G4+H4+I4+J4+K4+L4+M4*2 -> 10.405775 | P4: =(AF4-AVERAGE(AF$2:AF$38))/AVERAGE(AF$2:AF$38)*100+100 -> 123.81171 | Q4: =(AVERAGE(AG$2:AG$38)-AG4)/AVERAGE(AG$2:AG$38)*100+100 -> 107.79416 | R4: =(AJ4-AVERAGE(AJ$2:AJ$38))/AVERAGE(AJ$2:AJ$38)*100+100 -> 123.012 | S4: =(AVERAGE(AK$2:AK$38)-AK4)/AVERAGE(AK$2:AK$38)*100+100 -> 77.483444 | T4: =(AVERAGE(AL$2:AL$38)-AL4)/AVERAGE(AL$2:AL$38)*100+100 -> 102.3962 | U4: =(AVERAGE(AM$2:AM$38)-AM4)/AVERAGE(AM$2:AM$38)*100+100 -> 111.42344 | V4: =(AVERAGE(AN$2:AN$38)-AN4)/AVERAGE(AN$2:AN$38)*100+100 -> 111.89073 | W4: =(AVERAGE(AO$2:AO$38)-AO4)/AVERAGE(AO$2:AO$38)*100+100 -> 116.0743 | X4: =(AVERAGE(AP$2:AP$38)-AP4)/AVERAGE(AP$2:AP$38)*100+100 -> 64.443842 | Y4: =(AVERAGE(AQ$2:AQ$38)-AQ4)/AVERAGE(AQ$2:AQ$38)*100+100 -> 50.608531 | Z4: =(AT4-AVERAGE(AT$2:AT$38))/AVERAGE(AT$2:AT$38)*100+100 -> 112.34314 | AA4: =(AVERAGE(AU$2:AU$38)-AU4)/AVERAGE(AU$2:AU$38)*100+100 -> 114.2434 | AB4: =(AVERAGE(AV$2:AV$38)-AV4)/AVERAGE(AV$2:AV$38)*100+100 -> 118.61831 | AC4: =(AVERAGE(AW$2:AW$38)-AW4)/AVERAGE(AW$2:AW$38)*100+100 -> 111.08445 | AD4: =(AX4-AVERAGE(AX$2:AX$38))/AVERAGE(AX$2:AX$38)*100+100 -> 127.654 | AF4: =P14_Relievers!G6 -> 4.5628571 | AG4: =P14_Relievers!H6 -> 2.9136555 | AH4: =P14_Relievers!I6 -> 30.542857 | AI4: =P14_Relievers!J6 -> 3.452605 | AJ4: =AH4+AI4 -> 33.995462 | AK4: =P14_Relievers!K6 -> 5 | AL4: =P14_Relievers!L6 -> 50.74523 | AM4: =P14_Relievers!M6 -> 23.315833 | AN4: =P14_Relievers!N6 -> 21.348262 | AO4: =P14_Relievers!O6 -> 5.6880491 | AP4: =P14_Relievers!P6 -> 1.9760511 | AQ4: =P14_Relievers!Q6 -> 4.2301544 | AR4: =P14_Relievers!R6 -> 89.514485 | AS4: =P14_Relievers!S6 -> 21.42779 | AT4: =AR4/$E4*9 -> 11.675802 | AU4: =AS4/$E4*9 -> 2.7949291 | AV4: =AN4/$E4*9 -> 2.784556 | AW4: =(AS4+AL4)/E4 -> 1.0459858 | AX4: =(AR4-AS4)/F4 -> 0.24580034
A5: Griffin Jax | B5: =P14_Relievers!B35 -> TB | C5: =P14_Relievers!C35 -> RP | D5: =P14_Relievers!D35 -> 65 | E5: 65.67 | F5: =P14_Relievers!F35 -> 265 | G5: =(P5-P$39)/P$40 -> 0.88592873 | H5: =(AB5-AB$39)/AB$40 -> 1.237967 | I5: =(AC5-AC$39)/AC$40 -> 1.353081 | J5: =(Z5-Z$39)/Z$40 -> 0.84697805 | K5: =(AA5-AA$39)/AA$40 -> 1.4129415 | L5: =(R5-R$39)/R$40 -> -0.2609377 | M5: =(AD5-AD$39)/AD$40 -> 1.4209424 | N5: =G5+H5+I5+J5+K5+L5+M5*2 -> 8.3178433 | P5: =(AF5-AVERAGE(AF$2:AF$38))/AVERAGE(AF$2:AF$38)*100+100 -> 111.53572 | Q5: =(AVERAGE(AG$2:AG$38)-AG5)/AVERAGE(AG$2:AG$38)*100+100 -> 108.5729 | R5: =(AJ5-AVERAGE(AJ$2:AJ$38))/AVERAGE(AJ$2:AJ$38)*100+100 -> 94.625398 | S5: =(AVERAGE(AK$2:AK$38)-AK5)/AVERAGE(AK$2:AK$38)*100+100 -> 52.980132 | T5: =(AVERAGE(AL$2:AL$38)-AL5)/AVERAGE(AL$2:AL$38)*100+100 -> 99.789595 | U5: =(AVERAGE(AM$2:AM$38)-AM5)/AVERAGE(AM$2:AM$38)*100+100 -> 112.17505 | V5: =(AVERAGE(AN$2:AN$38)-AN5)/AVERAGE(AN$2:AN$38)*100+100 -> 112.77724 | W5: =(AVERAGE(AO$2:AO$38)-AO5)/AVERAGE(AO$2:AO$38)*100+100 -> 112.41622 | X5: =(AVERAGE(AP$2:AP$38)-AP5)/AVERAGE(AP$2:AP$38)*100+100 -> 84.56602 | Y5: =(AVERAGE(AQ$2:AQ$38)-AQ5)/AVERAGE(AQ$2:AQ$38)*100+100 -> 129.91504 | Z5: =(AT5-AVERAGE(AT$2:AT$38))/AVERAGE(AT$2:AT$38)*100+100 -> 112.73545 | AA5: =(AVERAGE(AU$2:AU$38)-AU5)/AVERAGE(AU$2:AU$38)*100+100 -> 122.36447 | AB5: =(AVERAGE(AV$2:AV$38)-AV5)/AVERAGE(AV$2:AV$38)*100+100 -> 115.35194 | AC5: =(AVERAGE(AW$2:AW$38)-AW5)/AVERAGE(AW$2:AW$38)*100+100 -> 108.66002 | AD5: =(AX5-AVERAGE(AX$2:AX$38))/AVERAGE(AX$2:AX$38)*100+100 -> 131.36276 | AF5: =P14_Relievers!G35 -> 4.1104478 | AG5: =P14_Relievers!H35 -> 2.8890474 | AH5: =P14_Relievers!I35 -> 14.328358 | AI5: =P14_Relievers!J35 -> 11.822212 | AJ5: =AH5+AI5 -> 26.150571 | AK5: =P14_Relievers!K35 -> 6 | AL5: =P14_Relievers!L35 -> 52.100432 | AM5: =P14_Relievers!M35 -> 23.117987 | AN5: =P14_Relievers!N35 -> 21.133468 | AO5: =P14_Relievers!O35 -> 5.9359746 | AP5: =P14_Relievers!P35 -> 1.6827228 | AQ5: =P14_Relievers!Q35 -> 1.984519 | AR5: =P14_Relievers!R35 -> 85.491939 | AS5: =P14_Relievers!S35 -> 18.462407 | AT5: =AR5/$E5*9 -> 11.716575 | AU5: =AS5/$E5*9 -> 2.5302522 | AV5: =AN5/$E5*9 -> 2.8963182 | AW5: =(AS5+AL5)/E5 -> 1.0745064 | AX5: =(AR5-AS5)/F5 -> 0.25294163
A6: Jhoan Duran | B6: =P14_Relievers!B5 -> PHI | C6: =P14_Relievers!C5 -> RP | D6: =P14_Relievers!D5 -> 65 | E6: 66.33 | F6: =P14_Relievers!F5 -> 271 | G6: =(P6-P$39)/P$40 -> 2.0251918 | H6: =(AB6-AB$39)/AB$40 -> 1.673507 | I6: =(AC6-AC$39)/AC$40 -> 0.8368357 | J6: =(Z6-Z$39)/Z$40 -> 0.27512022 | K6: =(AA6-AA$39)/AA$40 -> 0.83804381 | L6: =(R6-R$39)/R$40 -> 1.2431752 | M6: =(AD6-AD$39)/AD$40 -> 0.58603702 | N6: =G6+H6+I6+J6+K6+L6+M6*2 -> 8.0639477 | P6: =(AF6-AVERAGE(AF$2:AF$38))/AVERAGE(AF$2:AF$38)*100+100 -> 126.37012 | Q6: =(AVERAGE(AG$2:AG$38)-AG6)/AVERAGE(AG$2:AG$38)*100+100 -> 109.17157 | R6: =(AJ6-AVERAGE(AJ$2:AJ$38))/AVERAGE(AJ$2:AJ$38)*100+100 -> 125.60601 | S6: =(AVERAGE(AK$2:AK$38)-AK6)/AVERAGE(AK$2:AK$38)*100+100 -> 101.98675 | T6: =(AVERAGE(AL$2:AL$38)-AL6)/AVERAGE(AL$2:AL$38)*100+100 -> 98.027653 | U6: =(AVERAGE(AM$2:AM$38)-AM6)/AVERAGE(AM$2:AM$38)*100+100 -> 116.55824 | V6: =(AVERAGE(AN$2:AN$38)-AN6)/AVERAGE(AN$2:AN$38)*100+100 -> 117.52194 | W6: =(AVERAGE(AO$2:AO$38)-AO6)/AVERAGE(AO$2:AO$38)*100+100 -> 142.06822 | X6: =(AVERAGE(AP$2:AP$38)-AP6)/AVERAGE(AP$2:AP$38)*100+100 -> 64.450415 | Y6: =(AVERAGE(AQ$2:AQ$38)-AQ6)/AVERAGE(AQ$2:AQ$38)*100+100 -> 66.840683 | Z6: =(AT6-AVERAGE(AT$2:AT$38))/AVERAGE(AT$2:AT$38)*100+100 -> 104.1368 | AA6: =(AVERAGE(AU$2:AU$38)-AU6)/AVERAGE(AU$2:AU$38)*100+100 -> 113.26481 | AB6: =(AVERAGE(AV$2:AV$38)-AV6)/AVERAGE(AV$2:AV$38)*100+100 -> 120.75303 | AC6: =(AVERAGE(AW$2:AW$38)-AW6)/AVERAGE(AW$2:AW$38)*100+100 -> 105.35593 | AD6: =(AX6-AVERAGE(AX$2:AX$38))/AVERAGE(AX$2:AX$38)*100+100 -> 112.93489 | AF6: =P14_Relievers!G5 -> 4.6571429 | AG6: =P14_Relievers!H5 -> 2.8701299 | AH6: =P14_Relievers!I5 -> 31.785714 | AI6: =P14_Relievers!J5 -> 2.9266234 | AJ6: =AH6+AI6 -> 34.712338 | AK6: =P14_Relievers!K5 -> 4 | AL6: =P14_Relievers!L5 -> 53.016484 | AM6: =P14_Relievers!M5 -> 21.964211 | AN6: =P14_Relievers!N5 -> 19.98386 | AO6: =P14_Relievers!O5 -> 3.9263158 | AP6: =P14_Relievers!P5 -> 1.9759553 | AQ6: =P14_Relievers!Q5 -> 3.7705263 | AR6: =P14_Relievers!R5 -> 79.764912 | AS6: =P14_Relievers!S5 -> 20.833684 | AT6: =AR6/$E6*9 -> 10.822919 | AU6: =AS6/$E6*9 -> 2.8268228 | AV6: =AN6/$E6*9 -> 2.7115142 | AW6: =(AS6+AL6)/E6 -> 1.1133751 | AX6: =(AR6-AS6)/F6 -> 0.21745841
A7: Josh Hader | B7: =P14_Relievers!B10 -> HOU | C7: =P14_Relievers!C10 -> RP | D7: =P14_Relievers!D10 -> 53 | E7: 56 | F7: =P14_Relievers!F10 -> 225 | G7: =(P7-P$39)/P$40 -> -0.15885355 | H7: =(AB7-AB$39)/AB$40 -> 0.56802419 | I7: =(AC7-AC$39)/AC$40 -> 1.3522615 | J7: =(Z7-Z$39)/Z$40 -> 1.3938634 | K7: =(AA7-AA$39)/AA$40 -> -0.35482133 | L7: =(R7-R$39)/R$40 -> 0.42466764 | M7: =(AD7-AD$39)/AD$40 -> 1.4095375 | N7: =G7+H7+I7+J7+K7+L7+M7*2 -> 6.0442169 | P7: =(AF7-AVERAGE(AF$2:AF$38))/AVERAGE(AF$2:AF$38)*100+100 -> 97.93156 | Q7: =(AVERAGE(AG$2:AG$38)-AG7)/AVERAGE(AG$2:AG$38)*100+100 -> 110.20817 | R7: =(AJ7-AVERAGE(AJ$2:AJ$38))/AVERAGE(AJ$2:AJ$38)*100+100 -> 108.74699 | S7: =(AVERAGE(AK$2:AK$38)-AK7)/AVERAGE(AK$2:AK$38)*100+100 -> 126.49007 | T7: =(AVERAGE(AL$2:AL$38)-AL7)/AVERAGE(AL$2:AL$38)*100+100 -> 125.45294 | U7: =(AVERAGE(AM$2:AM$38)-AM7)/AVERAGE(AM$2:AM$38)*100+100 -> 117.35493 | V7: =(AVERAGE(AN$2:AN$38)-AN7)/AVERAGE(AN$2:AN$38)*100+100 -> 118.32086 | W7: =(AVERAGE(AO$2:AO$38)-AO7)/AVERAGE(AO$2:AO$38)*100+100 -> 96.64295 | X7: =(AVERAGE(AP$2:AP$38)-AP7)/AVERAGE(AP$2:AP$38)*100+100 -> 134.08879 | Y7: =(AVERAGE(AQ$2:AQ$38)-AQ7)/AVERAGE(AQ$2:AQ$38)*100+100 -> 124.76789 | Z7: =(AT7-AVERAGE(AT$2:AT$38))/AVERAGE(AT$2:AT$38)*100+100 -> 120.9586 | AA7: =(AVERAGE(AU$2:AU$38)-AU7)/AVERAGE(AU$2:AU$38)*100+100 -> 94.38378 | AB7: =(AVERAGE(AV$2:AV$38)-AV7)/AVERAGE(AV$2:AV$38)*100+100 -> 107.04403 | AC7: =(AVERAGE(AW$2:AW$38)-AW7)/AVERAGE(AW$2:AW$38)*100+100 -> 108.65477 | AD7: =(AX7-AVERAGE(AX$2:AX$38))/AVERAGE(AX$2:AX$38)*100+100 -> 131.11103 | AF7: =P14_Relievers!G10 -> 3.6090909 | AG7: =P14_Relievers!H10 -> 2.8373737 | AH7: =P14_Relievers!I10 -> 28.178788 | AI7: =P14_Relievers!J10 -> 1.8744108 | AJ7: =AH7+AI7 -> 30.053199 | AK7: =P14_Relievers!K10 -> 3 | AL7: =P14_Relievers!L10 -> 38.757792 | AM7: =P14_Relievers!M10 -> 21.754499 | AN7: =P14_Relievers!N10 -> 19.790286 | AO7: =P14_Relievers!O10 -> 7.0050052 | AP7: =P14_Relievers!P10 -> 0.96081149 | AQ7: =P14_Relievers!Q10 -> 2.1302651 | AR7: =P14_Relievers!R10 -> 78.220833 | AS7: =P14_Relievers!S10 -> 21.418024 | AT7: =AR7/$E7*9 -> 12.571205 | AU7: =AS7/$E7*9 -> 3.4421824 | AV7: =AN7/$E7*9 -> 3.1805816 | AW7: =(AS7+AL7)/E7 -> 1.0745681 | AX7: =(AR7-AS7)/F7 -> 0.25245693
A8: Devin Williams | B8: =P14_Relievers!B9 -> NYM | C8: =P14_Relievers!C9 -> RP | D8: =P14_Relievers!D9 -> 64 | E8: 64.33 | F8: =P14_Relievers!F9 -> 263 | G8: =(P8-P$39)/P$40 -> 1.6977203 | H8: =(AB8-AB$39)/AB$40 -> 0.60047968 | I8: =(AC8-AC$39)/AC$40 -> 0.70543634 | J8: =(Z8-Z$39)/Z$40 -> 1.1145261 | K8: =(AA8-AA$39)/AA$40 -> -0.95797962 | L8: =(R8-R$39)/R$40 -> 1.1934883 | M8: =(AD8-AD$39)/AD$40 -> 0.82906636 | N8: =G8+H8+I8+J8+K8+L8+M8*2 -> 6.0118039 | P8: =(AF8-AVERAGE(AF$2:AF$38))/AVERAGE(AF$2:AF$38)*100+100 -> 122.1061 | Q8: =(AVERAGE(AG$2:AG$38)-AG8)/AVERAGE(AG$2:AG$38)*100+100 -> 79.796683 | R8: =(AJ8-AVERAGE(AJ$2:AJ$38))/AVERAGE(AJ$2:AJ$38)*100+100 -> 124.58259 | S8: =(AVERAGE(AK$2:AK$38)-AK8)/AVERAGE(AK$2:AK$38)*100+100 -> 101.98675 | T8: =(AVERAGE(AL$2:AL$38)-AL8)/AVERAGE(AL$2:AL$38)*100+100 -> 112.61597 | U8: =(AVERAGE(AM$2:AM$38)-AM8)/AVERAGE(AM$2:AM$38)*100+100 -> 105.90031 | V8: =(AVERAGE(AN$2:AN$38)-AN8)/AVERAGE(AN$2:AN$38)*100+100 -> 106.57735 | W8: =(AVERAGE(AO$2:AO$38)-AO8)/AVERAGE(AO$2:AO$38)*100+100 -> 114.03858 | X8: =(AVERAGE(AP$2:AP$38)-AP8)/AVERAGE(AP$2:AP$38)*100+100 -> 131.71053 | Y8: =(AVERAGE(AQ$2:AQ$38)-AQ8)/AVERAGE(AQ$2:AQ$38)*100+100 -> 86.953092 | Z8: =(AT8-AVERAGE(AT$2:AT$38))/AVERAGE(AT$2:AT$38)*100+100 -> 116.75839 | AA8: =(AVERAGE(AU$2:AU$38)-AU8)/AVERAGE(AU$2:AU$38)*100+100 -> 84.836808 | AB8: =(AVERAGE(AV$2:AV$38)-AV8)/AVERAGE(AV$2:AV$38)*100+100 -> 107.4465 | AC8: =(AVERAGE(AW$2:AW$38)-AW8)/AVERAGE(AW$2:AW$38)*100+100 -> 104.51495 | AD8: =(AX8-AVERAGE(AX$2:AX$38))/AVERAGE(AX$2:AX$38)*100+100 -> 118.29899 | AF8: =P14_Relievers!G9 -> 4.5 | AG8: =P14_Relievers!H9 -> 3.7983607 | AH8: =P14_Relievers!I9 -> 30.4 | AI8: =P14_Relievers!J9 -> 4.0295082 | AJ8: =AH8+AI8 -> 34.429508 | AK8: =P14_Relievers!K9 -> 4 | AL8: =P14_Relievers!L9 -> 45.431865 | AM8: =P14_Relievers!M9 -> 24.769674 | AN8: =P14_Relievers!N9 -> 22.635657 | AO8: =P14_Relievers!O9 -> 5.8260196 | AP8: =P14_Relievers!P9 -> 0.99548021 | AQ8: =P14_Relievers!Q9 -> 3.2010253 | AR8: =P14_Relievers!R9 -> 86.735984 | AS8: =P14_Relievers!S9 -> 26.827982 | AT8: =AR8/$E8*9 -> 12.134678 | AU8: =AS8/$E8*9 -> 3.7533318 | AV8: =AN8/$E8*9 -> 3.1668104 | AW8: =(AS8+AL8)/E8 -> 1.1232682 | AX8: =(AR8-AS8)/F8 -> 0.22778708
A9: Andres Munoz | B9: =P14_Relievers!B4 -> SEA | C9: =P14_Relievers!C4 -> RP | D9: =P14_Relievers!D4 -> 60 | E9: 61.67 | F9: =P14_Relievers!F4 -> 253 | G9: =(P9-P$39)/P$40 -> 0.29108144 | H9: =(AB9-AB$39)/AB$40 -> 1.2658792 | I9: =(AC9-AC$39)/AC$40 -> 0.8110105 | J9: =(Z9-Z$39)/Z$40 -> 0.82314813 | K9: =(AA9-AA$39)/AA$40 -> -0.59842075 | L9: =(R9-R$39)/R$40 -> 1.3594841 | M9: =(AD9-AD$39)/AD$40 -> 0.63855912 | N9: =G9+H9+I9+J9+K9+L9+M9*2 -> 5.2293008 | P9: =(AF9-AVERAGE(AF$2:AF$38))/AVERAGE(AF$2:AF$38)*100+100 -> 103.79019 | Q9: =(AVERAGE(AG$2:AG$38)-AG9)/AVERAGE(AG$2:AG$38)*100+100 -> 130.80605 | R9: =(AJ9-AVERAGE(AJ$2:AJ$38))/AVERAGE(AJ$2:AJ$38)*100+100 -> 128.00165 | S9: =(AVERAGE(AK$2:AK$38)-AK9)/AVERAGE(AK$2:AK$38)*100+100 -> 77.483444 | T9: =(AVERAGE(AL$2:AL$38)-AL9)/AVERAGE(AL$2:AL$38)*100+100 -> 114.72748 | U9: =(AVERAGE(AM$2:AM$38)-AM9)/AVERAGE(AM$2:AM$38)*100+100 -> 117.28096 | V9: =(AVERAGE(AN$2:AN$38)-AN9)/AVERAGE(AN$2:AN$38)*100+100 -> 118.42497 | W9: =(AVERAGE(AO$2:AO$38)-AO9)/AVERAGE(AO$2:AO$38)*100+100 -> 126.2583 | X9: =(AVERAGE(AP$2:AP$38)-AP9)/AVERAGE(AP$2:AP$38)*100+100 -> 63.978669 | Y9: =(AVERAGE(AQ$2:AQ$38)-AQ9)/AVERAGE(AQ$2:AQ$38)*100+100 -> 75.42028 | Z9: =(AT9-AVERAGE(AT$2:AT$38))/AVERAGE(AT$2:AT$38)*100+100 -> 112.37713 | AA9: =(AVERAGE(AU$2:AU$38)-AU9)/AVERAGE(AU$2:AU$38)*100+100 -> 90.528015 | AB9: =(AVERAGE(AV$2:AV$38)-AV9)/AVERAGE(AV$2:AV$38)*100+100 -> 115.69807 | AC9: =(AVERAGE(AW$2:AW$38)-AW9)/AVERAGE(AW$2:AW$38)*100+100 -> 105.19065 | AD9: =(AX9-AVERAGE(AX$2:AX$38))/AVERAGE(AX$2:AX$38)*100+100 -> 114.09415 | AF9: =P14_Relievers!G4 -> 3.825 | AG9: =P14_Relievers!H4 -> 2.1864919 | AH9: =P14_Relievers!I4 -> 32.45 | AI9: =P14_Relievers!J4 -> 2.9243952 | AJ9: =AH9+AI9 -> 35.374395 | AK9: =P14_Relievers!K4 -> 5 | AL9: =P14_Relievers!L4 -> 44.334069 | AM9: =P14_Relievers!M4 -> 21.773968 | AN9: =P14_Relievers!N4 -> 19.765062 | AO9: =P14_Relievers!O4 -> 4.9978299 | AP9: =P14_Relievers!P4 -> 1.9828321 | AQ9: =P14_Relievers!Q4 -> 3.5275873 | AR9: =P14_Relievers!R4 -> 80.029399 | AS9: =P14_Relievers!S4 -> 24.447682 | AT9: =AR9/$E9*9 -> 11.679335 | AU9: =AS9/$E9*9 -> 3.5678473 | AV9: =AN9/$E9*9 -> 2.8844748 | AW9: =(AS9+AL9)/E9 -> 1.1153195 | AX9: =(AR9-AS9)/F9 -> 0.21969058
A10: David Bednar | B10: =P14_Relievers!B7 -> NYY | C10: =P14_Relievers!C7 -> RP | D10: =P14_Relievers!D7 -> 62 | E10: 63.67 | F10: =P14_Relievers!F7 -> 259 | G10: =(P10-P$39)/P$40 -> 0.78400618 | H10: =(AB10-AB$39)/AB$40 -> 0.40303023 | I10: =(AC10-AC$39)/AC$40 -> 0.62614095 | J10: =(Z10-Z$39)/Z$40 -> 0.43825145 | K10: =(AA10-AA$39)/AA$40 -> 0.36848724 | L10: =(R10-R$39)/R$40 -> 1.1299253 | M10: =(AD10-AD$39)/AD$40 -> 0.61656716 | N10: =G10+H10+I10+J10+K10+L10+M10*2 -> 4.9829757 | P10: =(AF10-AVERAGE(AF$2:AF$38))/AVERAGE(AF$2:AF$38)*100+100 -> 110.20858 | Q10: =(AVERAGE(AG$2:AG$38)-AG10)/AVERAGE(AG$2:AG$38)*100+100 -> 85.392416 | R10: =(AJ10-AVERAGE(AJ$2:AJ$38))/AVERAGE(AJ$2:AJ$38)*100+100 -> 123.27337 | S10: =(AVERAGE(AK$2:AK$38)-AK10)/AVERAGE(AK$2:AK$38)*100+100 -> 101.98675 | T10: =(AVERAGE(AL$2:AL$38)-AL10)/AVERAGE(AL$2:AL$38)*100+100 -> 103.47033 | U10: =(AVERAGE(AM$2:AM$38)-AM10)/AVERAGE(AM$2:AM$38)*100+100 -> 104.97 | V10: =(AVERAGE(AN$2:AN$38)-AN10)/AVERAGE(AN$2:AN$38)*100+100 -> 105.08964 | W10: =(AVERAGE(AO$2:AO$38)-AO10)/AVERAGE(AO$2:AO$38)*100+100 -> 96.111393 | X10: =(AVERAGE(AP$2:AP$38)-AP10)/AVERAGE(AP$2:AP$38)*100+100 -> 64.037844 | Y10: =(AVERAGE(AQ$2:AQ$38)-AQ10)/AVERAGE(AQ$2:AQ$38)*100+100 -> 128.7171 | Z10: =(AT10-AVERAGE(AT$2:AT$38))/AVERAGE(AT$2:AT$38)*100+100 -> 106.5897 | AA10: =(AVERAGE(AU$2:AU$38)-AU10)/AVERAGE(AU$2:AU$38)*100+100 -> 105.83253 | AB10: =(AVERAGE(AV$2:AV$38)-AV10)/AVERAGE(AV$2:AV$38)*100+100 -> 104.99795 | AC10: =(AVERAGE(AW$2:AW$38)-AW10)/AVERAGE(AW$2:AW$38)*100+100 -> 104.00744 | AD10: =(AX10-AVERAGE(AX$2:AX$38))/AVERAGE(AX$2:AX$38)*100+100 -> 113.60875 | AF10: =P14_Relievers!G7 -> 4.0615385 | AG10: =P14_Relievers!H7 -> 3.6215385 | AH10: =P14_Relievers!I7 -> 31.095385 | AI10: =P14_Relievers!J7 -> 2.9723077 | AJ10: =AH10+AI10 -> 34.067692 | AK10: =P14_Relievers!K7 -> 4 | AL10: =P14_Relievers!L7 -> 50.186779 | AM10: =P14_Relievers!M7 -> 25.01456 | AN10: =P14_Relievers!N7 -> 22.99612 | AO10: =P14_Relievers!O7 -> 7.0410314 | AP10: =P14_Relievers!P7 -> 1.9819695 | AQ10: =P14_Relievers!Q7 -> 2.0184397 | AR10: =P14_Relievers!R7 -> 78.36962 | AS10: =P14_Relievers!S7 -> 21.711834 | AT10: =AR10/$E10*9 -> 11.077848 | AU10: =AS10/$E10*9 -> 3.0690515 | AV10: =AN10/$E10*9 -> 3.2505902 | AW10: =(AS10+AL10)/E10 -> 1.1292385 | AX10: =(AR10-AS10)/F10 -> 0.21875593
A11: Aroldis Chapman | B11: =P14_Relievers!B8 -> BOS | C11: =P14_Relievers!C8 -> RP | D11: =P14_Relievers!D8 -> 57 | E11: 57.33 | F11: =P14_Relievers!F8 -> 234 | G11: =(P11-P$39)/P$40 -> -0.38955027 | H11: =(AB11-AB$39)/AB$40 -> 1.1059427 | I11: =(AC11-AC$39)/AC$40 -> 0.33319936 | J11: =(Z11-Z$39)/Z$40 -> 1.4537127 | K11: =(AA11-AA$39)/AA$40 -> -1.4822236 | L11: =(R11-R$39)/R$40 -> 0.79456741 | M11: =(AD11-AD$39)/AD$40 -> 1.004105 | N11: =G11+H11+I11+J11+K11+L11+M11*2 -> 3.8238584 | P11: =(AF11-AVERAGE(AF$2:AF$38))/AVERAGE(AF$2:AF$38)*100+100 -> 94.927646 | Q11: =(AVERAGE(AG$2:AG$38)-AG11)/AVERAGE(AG$2:AG$38)*100+100 -> 124.14779 | R11: =(AJ11-AVERAGE(AJ$2:AJ$38))/AVERAGE(AJ$2:AJ$38)*100+100 -> 116.36591 | S11: =(AVERAGE(AK$2:AK$38)-AK11)/AVERAGE(AK$2:AK$38)*100+100 -> 101.98675 | T11: =(AVERAGE(AL$2:AL$38)-AL11)/AVERAGE(AL$2:AL$38)*100+100 -> 122.34763 | U11: =(AVERAGE(AM$2:AM$38)-AM11)/AVERAGE(AM$2:AM$38)*100+100 -> 122.68596 | V11: =(AVERAGE(AN$2:AN$38)-AN11)/AVERAGE(AN$2:AN$38)*100+100 -> 122.38163 | W11: =(AVERAGE(AO$2:AO$38)-AO11)/AVERAGE(AO$2:AO$38)*100+100 -> 126.78484 | X11: =(AVERAGE(AP$2:AP$38)-AP11)/AVERAGE(AP$2:AP$38)*100+100 -> 133.09403 | Y11: =(AVERAGE(AQ$2:AQ$38)-AQ11)/AVERAGE(AQ$2:AQ$38)*100+100 -> 145.44292 | Z11: =(AT11-AVERAGE(AT$2:AT$38))/AVERAGE(AT$2:AT$38)*100+100 -> 121.85851 | AA11: =(AVERAGE(AU$2:AU$38)-AU11)/AVERAGE(AU$2:AU$38)*100+100 -> 76.538915 | AB11: =(AVERAGE(AV$2:AV$38)-AV11)/AVERAGE(AV$2:AV$38)*100+100 -> 113.71471 | AC11: =(AVERAGE(AW$2:AW$38)-AW11)/AVERAGE(AW$2:AW$38)*100+100 -> 102.13255 | AD11: =(AX11-AVERAGE(AX$2:AX$38))/AVERAGE(AX$2:AX$38)*100+100 -> 122.16241 | AF11: =P14_Relievers!G8 -> 3.4983871 | AG11: =P14_Relievers!H8 -> 2.3968894 | AH11: =P14_Relievers!I8 -> 29.7 | AI11: =P14_Relievers!J8 -> 2.4587558 | AJ11: =AH11+AI11 -> 32.158756 | AK11: =P14_Relievers!K8 -> 4 | AL11: =P14_Relievers!L8 -> 40.372277 | AM11: =P14_Relievers!M8 -> 20.351222 | AN11: =P14_Relievers!N8 -> 18.806389 | AO11: =P14_Relievers!O8 -> 4.9621442 | AP11: =P14_Relievers!P8 -> 0.9753125 | AQ11: =P14_Relievers!Q8 -> 1.5448329 | AR11: =P14_Relievers!R8 -> 80.674351 | AS11: =P14_Relievers!S8 -> 25.631427 | AT11: =AR11/$E11*9 -> 12.664733 | AU11: =AS11/$E11*9 -> 4.0237719 | AV11: =AN11/$E11*9 -> 2.9523374 | AW11: =(AS11+AL11)/E11 -> 1.1512943 | AX11: =(AR11-AS11)/F11 -> 0.23522617
A12: Bryan Abreu | B12: =P14_Relievers!B33 -> HOU | C12: =P14_Relievers!C33 -> RP | D12: =P14_Relievers!D33 -> 65 | E12: 67.33 | F12: =P14_Relievers!F33 -> 279 | G12: =(P12-P$39)/P$40 -> -0.22683135 | H12: =(AB12-AB$39)/AB$40 -> 1.2008136 | I12: =(AC12-AC$39)/AC$40 -> 0.19919045 | J12: =(Z12-Z$39)/Z$40 -> 1.1343307 | K12: =(AA12-AA$39)/AA$40 -> -1.0275691 | L12: =(R12-R$39)/R$40 -> -0.6473982 | M12: =(AD12-AD$39)/AD$40 -> 0.75418989 | N12: =G12+H12+I12+J12+K12+L12+M12*2 -> 2.1409159 | P12: =(AF12-AVERAGE(AF$2:AF$38))/AVERAGE(AF$2:AF$38)*100+100 -> 97.046418 | Q12: =(AVERAGE(AG$2:AG$38)-AG12)/AVERAGE(AG$2:AG$38)*100+100 -> 130.86351 | R12: =(AJ12-AVERAGE(AJ$2:AJ$38))/AVERAGE(AJ$2:AJ$38)*100+100 -> 86.665369 | S12: =(AVERAGE(AK$2:AK$38)-AK12)/AVERAGE(AK$2:AK$38)*100+100 -> 101.98675 | T12: =(AVERAGE(AL$2:AL$38)-AL12)/AVERAGE(AL$2:AL$38)*100+100 -> 104.12131 | U12: =(AVERAGE(AM$2:AM$38)-AM12)/AVERAGE(AM$2:AM$38)*100+100 -> 109.03465 | V12: =(AVERAGE(AN$2:AN$38)-AN12)/AVERAGE(AN$2:AN$38)*100+100 -> 110.08568 | W12: =(AVERAGE(AO$2:AO$38)-AO12)/AVERAGE(AO$2:AO$38)*100+100 -> 105.95543 | X12: =(AVERAGE(AP$2:AP$38)-AP12)/AVERAGE(AP$2:AP$38)*100+100 -> 131.90876 | Y12: =(AVERAGE(AQ$2:AQ$38)-AQ12)/AVERAGE(AQ$2:AQ$38)*100+100 -> 68.469218 | Z12: =(AT12-AVERAGE(AT$2:AT$38))/AVERAGE(AT$2:AT$38)*100+100 -> 117.05618 | AA12: =(AVERAGE(AU$2:AU$38)-AU12)/AVERAGE(AU$2:AU$38)*100+100 -> 83.735324 | AB12: =(AVERAGE(AV$2:AV$38)-AV12)/AVERAGE(AV$2:AV$38)*100+100 -> 114.8912 | AC12: =(AVERAGE(AW$2:AW$38)-AW12)/AVERAGE(AW$2:AW$38)*100+100 -> 101.27486 | AD12: =(AX12-AVERAGE(AX$2:AX$38))/AVERAGE(AX$2:AX$38)*100+100 -> 116.64633 | AF12: =P14_Relievers!G33 -> 3.5764706 | AG12: =P14_Relievers!H33 -> 2.184676 | AH12: =P14_Relievers!I33 -> 7.7735294 | AI12: =P14_Relievers!J33 -> 16.177217 | AJ12: =AH12+AI12 -> 23.950746 | AK12: =P14_Relievers!K33 -> 4 | AL12: =P14_Relievers!L33 -> 49.848328 | AM12: =P14_Relievers!M33 -> 23.944629 | AN12: =P14_Relievers!N33 -> 21.785614 | AO12: =P14_Relievers!O33 -> 6.3738533 | AP12: =P14_Relievers!P33 -> 0.99259065 | AQ12: =P14_Relievers!Q33 -> 3.7244129 | AR12: =P14_Relievers!R33 -> 91.01241 | AS12: =P14_Relievers!S33 -> 28.347656 | AT12: =AR12/$E12*9 -> 12.165627 | AU12: =AS12/$E12*9 -> 3.7892307 | AV12: =AN12/$E12*9 -> 2.9120827 | AW12: =(AS12+AL12)/E12 -> 1.161384 | AX12: =(AR12-AS12)/F12 -> 0.22460485
A13: Garrett Whitlock | B13: =P14_Relievers!B28 -> BOS | C13: =P14_Relievers!C28 -> RP | D13: =P14_Relievers!D28 -> 58 | E13: 64 | F13: =P14_Relievers!F28 -> 262 | G13: =(P13-P$39)/P$40 -> 0.00082262736 | H13: =(AB13-AB$39)/AB$40 -> 0.3364668 | I13: =(AC13-AC$39)/AC$40 -> 0.55687357 | J13: =(Z13-Z$39)/Z$40 -> -0.17989974 | K13: =(AA13-AA$39)/AA$40 -> 1.5079014 | L13: =(R13-R$39)/R$40 -> -1.2912074 | M13: =(AD13-AD$39)/AD$40 -> 0.34246287 | N13: =G13+H13+I13+J13+K13+L13+M13*2 -> 1.615883 | P13: =(AF13-AVERAGE(AF$2:AF$38))/AVERAGE(AF$2:AF$38)*100+100 -> 100.01071 | Q13: =(AVERAGE(AG$2:AG$38)-AG13)/AVERAGE(AG$2:AG$38)*100+100 -> 99.485945 | R13: =(AJ13-AVERAGE(AJ$2:AJ$38))/AVERAGE(AJ$2:AJ$38)*100+100 -> 73.404663 | S13: =(AVERAGE(AK$2:AK$38)-AK13)/AVERAGE(AK$2:AK$38)*100+100 -> 150.99338 | T13: =(AVERAGE(AL$2:AL$38)-AL13)/AVERAGE(AL$2:AL$38)*100+100 -> 94.288552 | U13: =(AVERAGE(AM$2:AM$38)-AM13)/AVERAGE(AM$2:AM$38)*100+100 -> 104.35428 | V13: =(AVERAGE(AN$2:AN$38)-AN13)/AVERAGE(AN$2:AN$38)*100+100 -> 103.76879 | W13: =(AVERAGE(AO$2:AO$38)-AO13)/AVERAGE(AO$2:AO$38)*100+100 -> 107.90201 | X13: =(AVERAGE(AP$2:AP$38)-AP13)/AVERAGE(AP$2:AP$38)*100+100 -> 120.41513 | Y13: =(AVERAGE(AQ$2:AQ$38)-AQ13)/AVERAGE(AQ$2:AQ$38)*100+100 -> 101.44331 | Z13: =(AT13-AVERAGE(AT$2:AT$38))/AVERAGE(AT$2:AT$38)*100+100 -> 97.294967 | AA13: =(AVERAGE(AU$2:AU$38)-AU13)/AVERAGE(AU$2:AU$38)*100+100 -> 123.86752 | AB13: =(AVERAGE(AV$2:AV$38)-AV13)/AVERAGE(AV$2:AV$38)*100+100 -> 104.1725 | AC13: =(AVERAGE(AW$2:AW$38)-AW13)/AVERAGE(AW$2:AW$38)*100+100 -> 103.56411 | AD13: =(AX13-AVERAGE(AX$2:AX$38))/AVERAGE(AX$2:AX$38)*100+100 -> 107.55877 | AF13: =P14_Relievers!G28 -> 3.6857143 | AG13: =P14_Relievers!H28 -> 3.1761905 | AH13: =P14_Relievers!I28 -> 3.6971429 | AI13: =P14_Relievers!J28 -> 16.588889 | AJ13: =AH13+AI13 -> 20.286032 | AK13: =P14_Relievers!K28 -> 2 | AL13: =P14_Relievers!L28 -> 54.960481 | AM13: =P14_Relievers!M28 -> 25.176632 | AN13: =P14_Relievers!N28 -> 23.316151 | AO13: =P14_Relievers!O28 -> 6.2419244 | AP13: =P14_Relievers!P28 -> 1.1601375 | AQ13: =P14_Relievers!Q28 -> 2.7907216 | AR13: =P14_Relievers!R28 -> 71.906478 | AS13: =P14_Relievers!S28 -> 17.644555 | AT13: =AR13/$E13*9 -> 10.111848 | AU13: =AS13/$E13*9 -> 2.4812655 | AV13: =AN13/$E13*9 -> 3.2788338 | AW13: =(AS13+AL13)/E13 -> 1.1344537 | AX13: =(AR13-AS13)/F13 -> 0.20710658
A14: Raisel Iglesias | B14: =P14_Relievers!B11 -> ATL | C14: =P14_Relievers!C11 -> RP | D14: =P14_Relievers!D11 -> 62 | E14: 63.67 | F14: =P14_Relievers!F11 -> 260 | G14: =(P14-P$39)/P$40 -> -0.28515109 | H14: =(AB14-AB$39)/AB$40 -> -0.44504078 | I14: =(AC14-AC$39)/AC$40 -> 0.32580547 | J14: =(Z14-Z$39)/Z$40 -> -0.46401015 | K14: =(AA14-AA$39)/AA$40 -> 1.5635801 | L14: =(R14-R$39)/R$40 -> 0.35432632 | M14: =(AD14-AD$39)/AD$40 -> 0.088765923 | N14: =G14+H14+I14+J14+K14+L14+M14*2 -> 1.2270417 | P14: =(AF14-AVERAGE(AF$2:AF$38))/AVERAGE(AF$2:AF$38)*100+100 -> 96.287033 | Q14: =(AVERAGE(AG$2:AG$38)-AG14)/AVERAGE(AG$2:AG$38)*100+100 -> 99.579288 | R14: =(AJ14-AVERAGE(AJ$2:AJ$38))/AVERAGE(AJ$2:AJ$38)*100+100 -> 107.29815 | S14: =(AVERAGE(AK$2:AK$38)-AK14)/AVERAGE(AK$2:AK$38)*100+100 -> 101.98675 | T14: =(AVERAGE(AL$2:AL$38)-AL14)/AVERAGE(AL$2:AL$38)*100+100 -> 92.312256 | U14: =(AVERAGE(AM$2:AM$38)-AM14)/AVERAGE(AM$2:AM$38)*100+100 -> 94.885515 | V14: =(AVERAGE(AN$2:AN$38)-AN14)/AVERAGE(AN$2:AN$38)*100+100 -> 94.582921 | W14: =(AVERAGE(AO$2:AO$38)-AO14)/AVERAGE(AO$2:AO$38)*100+100 -> 83.623173 | X14: =(AVERAGE(AP$2:AP$38)-AP14)/AVERAGE(AP$2:AP$38)*100+100 -> 119.65959 | Y14: =(AVERAGE(AQ$2:AQ$38)-AQ14)/AVERAGE(AQ$2:AQ$38)*100+100 -> 124.87423 | Z14: =(AT14-AVERAGE(AT$2:AT$38))/AVERAGE(AT$2:AT$38)*100+100 -> 93.022988 | AA14: =(AVERAGE(AU$2:AU$38)-AU14)/AVERAGE(AU$2:AU$38)*100+100 -> 124.74882 | AB14: =(AVERAGE(AV$2:AV$38)-AV14)/AVERAGE(AV$2:AV$38)*100+100 -> 94.481083 | AC14: =(AVERAGE(AW$2:AW$38)-AW14)/AVERAGE(AW$2:AW$38)*100+100 -> 102.08523 | AD14: =(AX14-AVERAGE(AX$2:AX$38))/AVERAGE(AX$2:AX$38)*100+100 -> 101.95922 | AF14: =P14_Relievers!G11 -> 3.5484848 | AG14: =P14_Relievers!H11 -> 3.1732409 | AH14: =P14_Relievers!I11 -> 25.684848 | AI14: =P14_Relievers!J11 -> 3.9679507 | AJ14: =AH14+AI14 -> 29.652799 | AK14: =P14_Relievers!K11 -> 4 | AL14: =P14_Relievers!L11 -> 55.987978 | AM14: =P14_Relievers!M11 -> 27.669078 | AN14: =P14_Relievers!N11 -> 25.541824 | AO14: =P14_Relievers!O11 -> 7.8874182 | AP14: =P14_Relievers!P11 -> 1.1711512 | AQ14: =P14_Relievers!Q11 -> 2.1272541 | AR14: =P14_Relievers!R11 -> 68.394756 | AS14: =P14_Relievers!S11 -> 17.350377 | AT14: =AR14/$E14*9 -> 9.6678625 | AU14: =AS14/$E14*9 -> 2.4525427 | AV14: =AN14/$E14*9 -> 3.6104353 | AW14: =(AS14+AL14)/E14 -> 1.151851 | AX14: =(AR14-AS14)/F14 -> 0.19632453
