Workbook

Sheet 2026_Fantasy_Starters
A1: Team | B1: Name | C1: Position | D1: G | E1: IP | F1: TBF | G1: W | H1: L | I1: QS | J1: H | K1: R | L1: ER | M1: HR | N1: IBB | O1: HBP | P1: K | Q1: BB | R1: K/9 | S1: BB/9 | T1: K-BB% | U1: ERA | V1: WHIP | W1: W% | X1: L% | Y1: QS% | Z1: H% | AA1: R% | AB1: ER% | AC1: HR% | AD1: IBB% | AE1: HBP% | AF1: K% | AG1: BB%
A2: DET | B2: Tarik Skubal | C2: SP | D2: 30 | E2: 192.33 | F2: 752 | G2: =W2*$D2 -> 13.694625 | H2: =X2*$D2 -> 7.8046875 | I2: =Y2*$D2 -> 18.791667 | J2: =Z2*$F2 -> 147.68703 | K2: =AA2*$F2 -> 61.689588 | L2: =AB2*$F2 -> 55.759516 | M2: =AC2*$F2 -> 18.965674 | N2: =AD2*$F2 -> 0.50000029 | O2: =AE2*$F2 -> 6.5151911 | P2: =AF2*$F2 -> 233.52855 | Q2: =AG2*$F2 -> 39.871036 | R2: =P2/$E2*9 -> 10.927869 | S2: =Q2/$E2*9 -> 1.8657481 | T2: =AF2-AG2 -> 0.25752329 | U2: =L2/$E2*9 -> 2.6092427 | V2: =(Q2+J2)/$E2 -> 0.97518883 | W2: 0.4564875 | X2: 0.26015625 | Y2: 0.6263888888888889 | Z2: 0.19639232846717486 | AA2: 0.082034027 | AB2: 0.074148293 | AC2: 0.025220311 | AD2: 0.000664894 | AE2: 0.008663818 | AF2: 0.31054328485626237 | AG2: 0.053019995168297196
A3: PIT | B3: Paul Skenes | C3: SP | D3: 30 | E3: 187.33 | F3: 745 | G3: =W3*$D3 -> 12.778875 | H3: =X3*$D3 -> 8.1376875 | I3: =Y3*$D3 -> 18 | J3: =Z3*$F3 -> 147.24492 | K3: =AA3*$F3 -> 63.561676 | L3: =AB3*$F3 -> 57.998112 | M3: =AC3*$F3 -> 15.851604 | N3: =AD3*$F3 -> 0.97391839 | O3: =AE3*$F3 -> 6.8651675 | P3: =AF3*$F3 -> 216.81336 | Q3: =AG3*$F3 -> 46.595927 | R3: =P3/$E3*9 -> 10.416486 | S3: =Q3/$E3*9 -> 2.2386342 | T3: =AF3-AG3 -> 0.22847978 | U3: =L3/$E3*9 -> 2.7864358 | V3: =(Q3+J3)/$E3 -> 1.034756 | W3: 0.4259625 | X3: 0.27125625 | Y3: 0.6 | Z3: 0.19764418595629166 | AA3: 0.085317686 | AB3: 0.077849815 | AC3: 0.021277321029525426 | AD3: 0.001307273 | AE3: 0.00921499 | AF3: 0.2910246443737717 | AG3: 0.062544868
A4: BOS | B4: Garrett Crochet | C4: SP | D4: 29 | E4: 181.67 | F4: 727 | G4: =W4*$D4 -> 13.382437 | H4: =X4*$D4 -> 8.0440312 | I4: =Y4*$D4 -> 17.166667 | J4: =Z4*$F4 -> 147.10707 | K4: =AA4*$F4 -> 64.217862 | L4: =AB4*$F4 -> 57.307448 | M4: =AC4*$F4 -> 19.042319 | N4: =AD4*$F4 -> 1.0000001 | O4: =AE4*$F4 -> 5.1998319 | P4: =AF4*$F4 -> 222.05758 | Q4: =AG4*$F4 -> 45.900299 | R4: =P4/$E4*9 -> 11.000816 | S4: =Q4/$E4*9 -> 2.273918 | T4: =AF4-AG4 -> 0.24230713 | U4: =L4/$E4*9 -> 2.8390325 | V4: =(Q4+J4)/$E4 -> 1.0624064 | W4: 0.46146336206896554 | X4: 0.2773803879310345 | Y4: 0.5919540229885057 | Z4: 0.2023481009699661 | AA4: 0.088332685 | AB4: 0.078827301 | AC4: 0.026193010425305842 | AD4: 0.001375516 | AE4: 0.007152451 | AF4: 0.3054437137965822 | AG4: 0.063136587
A5: LAD | B5: Yoshinobu Yamamoto | C5: SP | D5: 26 | E5: 160.67 | F5: 652 | G5: =W5*$D5 -> 12.011786 | H5: =X5*$D5 -> 6.66 | I5: =Y5*$D5 -> 14.166667 | J5: =Z5*$F5 -> 135.51266 | K5: =AA5*$F5 -> 64.709463 | L5: =AB5*$F5 -> 60.474558 | M5: =AC5*$F5 -> 16.179261 | N5: =AD5*$F5 -> 0.49999989 | O5: =AE5*$F5 -> 5.0160662 | P5: =AF5*$F5 -> 174.05888 | Q5: =AG5*$F5 -> 48.02686 | R5: =P5/$E5*9 -> 9.749984 | S5: =Q5/$E5*9 -> 2.6902455 | T5: =AF5-AG5 -> 0.19330065 | U5: =L5/$E5*9 -> 3.3875087 | V5: =(Q5+J5)/$E5 -> 1.1423384 | W5: 0.4619917582417582 | X5: 0.2561538461538461 | Y5: 0.5448717948717948 | Z5: 0.20784149678346364 | AA5: 0.099247643 | AB5: 0.09275239 | AC5: 0.024814817 | AD5: 0.000766871 | AE5: 0.007693353 | AF5: 0.26696147314689755 | AG5: 0.073660828
A6: PHI | B6: Cristopher Sanchez | C6: SP | D6: 30 | E6: 190.33 | F6: 777 | G6: =W6*$D6 -> 12.477453 | H6: =X6*$D6 -> 8.1376875 | I6: =Y6*$D6 -> 17.854167 | J6: =Z6*$F6 -> 172.92555 | K6: =AA6*$F6 -> 72.83968 | L6: =AB6*$F6 -> 68.052825 | M6: =AC6*$F6 -> 16.328832 | N6: =AD6*$F6 -> 0.99999978 | O6: =AE6*$F6 -> 6.223958 | P6: =AF6*$F6 -> 183.46999 | Q6: =AG6*$F6 -> 47.030139 | R6: =P6/$E6*9 -> 8.6756156 | S6: =Q6/$E6*9 -> 2.2238809 | T6: =AF6-AG6 -> 0.17559826 | U6: =L6/$E6*9 -> 3.2179658 | V6: =(Q6+J6)/$E6 -> 1.1556543 | W6: 0.41591508620689654 | X6: 0.27125625 | Y6: 0.5951388888888889 | Z6: 0.22255539992469836 | AA6: 0.093744762 | AB6: 0.087584074 | AC6: 0.021015228 | AD6: 0.001287001 | AE6: 0.008010242 | AF6: 0.2361261132168638 | AG6: 0.060527849642289806
A7: SEA | B7: Bryan Woo | C7: SP | D7: 30 | E7: 185.33 | F7: 741 | G7: =W7*$D7 -> 12.332893 | H7: =X7*$D7 -> 8.449875 | I7: =Y7*$D7 -> 16.885417 | J7: =Z7*$F7 -> 157.62567 | K7: =AA7*$F7 -> 74.431995 | L7: =AB7*$F7 -> 70.282904 | M7: =AC7*$F7 -> 23.844946 | N7: =AD7*$F7 -> 0.96254714 | O7: =AE7*$F7 -> 7.1359248 | P7: =AF7*$F7 -> 188.17819 | Q7: =AG7*$F7 -> 37.111962 | R7: =P7/$E7*9 -> 9.1383137 | S7: =Q7/$E7*9 -> 1.802232 | T7: =AF7-AG7 -> 0.20386805 | U7: =L7/$E7*9 -> 3.4130801 | V7: =(Q7+J7)/$E7 -> 1.0507615 | W7: 0.4110964285714286 | X7: 0.2816625 | Y7: 0.5628472222222222 | Z7: 0.21272019835766143 | AA7: 0.1004480362272818 | AB7: 0.094848723 | AC7: 0.032179414 | AD7: 0.001298984 | AE7: 0.009630128 | AF7: 0.25395166902354027 | AG7: 0.050083619678029045
A8: HOU | B8: Hunter Brown | C8: SP | D8: 30 | E8: 182.67 | F8: 753 | G8: =W8*$D8 -> 12.192097 | H8: =X8*$D8 -> 9.2165806 | I8: =Y8*$D8 -> 16.532258 | J8: =Z8*$F8 -> 156.41368 | K8: =AA8*$F8 -> 75.434012 | L8: =AB8*$F8 -> 65.626076 | M8: =AC8*$F8 -> 19.579342 | N8: =AD8*$F8 -> 1.4889611 | O8: =AE8*$F8 -> 6.9353612 | P8: =AF8*$F8 -> 195.50459 | Q8: =AG8*$F8 -> 60.54853 | R8: =P8/$E8*9 -> 9.6323494 | S8: =Q8/$E8*9 -> 2.9831761 | T8: =AF8-AG8 -> 0.17922451 | U8: =L8/$E8*9 -> 3.2333425 | V8: =(Q8+J8)/$E8 -> 1.1877276 | W8: 0.4064032258064516 | X8: 0.30721935483870966 | Y8: 0.5510752688172043 | Z8: 0.20772068498734197 | AA8: 0.10017797090465749 | AB8: 0.087152823 | AC8: 0.026001782 | AD8: 0.001977372 | AE8: 0.009210307 | AF8: 0.2596342438239594 | AG8: 0.080409735
A9: ATL | B9: Chris Sale | C9: SP | D9: 25 | E9: 155.67 | F9: 631 | G9: =W9*$D9 -> 10.636539 | H9: =X9*$D9 -> 7.0405714 | I9: =Y9*$D9 -> 14.369048 | J9: =Z9*$F9 -> 129.17627 | K9: =AA9*$F9 -> 57.767283 | L9: =AB9*$F9 -> 53.632265 | M9: =AC9*$F9 -> 17.129864 | N9: =AD9*$F9 -> 0.95991254 | O9: =AE9*$F9 -> 8.3679988 | P9: =AF9*$F9 -> 186.65946 | Q9: =AG9*$F9 -> 41.983885 | R9: =P9/$E9*9 -> 10.791644 | S9: =Q9/$E9*9 -> 2.4272819 | T9: =AF9-AG9 -> 0.22927984 | U9: =L9/$E9*9 -> 3.1007284 | V9: =(Q9+J9)/$E9 -> 1.0995064 | W9: 0.4254615584415584 | X9: 0.2816228571428572 | Y9: 0.5747619047619047 | Z9: 0.20471675469740397 | AA9: 0.091548785 | AB9: 0.084995666 | AC9: 0.027147168928802055 | AD9: 0.001521256 | AE9: 0.013261487783917137 | AF9: 0.29581531389472593 | AG9: 0.066535476
A10: SF | B10: Logan Webb | C10: SP | D10: 30 | E10: 196.67 | F10: 809 | G10: =W10*$D10 -> 13.715438 | H10: =X10*$D10 -> 9.448875 | I10: =Y10*$D10 -> 17.697917 | J10: =Z10*$F10 -> 185.71255 | K10: =AA10*$F10 -> 77.833799 | L10: =AB10*$F10 -> 68.347173 | M10: =AC10*$F10 -> 15.811923 | N10: =AD10*$F10 -> 0.98676319 | O10: =AE10*$F10 -> 5.9411051 | P10: =AF10*$F10 -> 186.26835 | Q10: =AG10*$F10 -> 46.151144 | R10: =P10/$E10*9 -> 8.5240004 | S10: =Q10/$E10*9 -> 2.1119657 | T10: =AF10-AG10 -> 0.17319803 | U10: =L10/$E10*9 -> 3.127699 | V10: =(Q10+J10)/$E10 -> 1.178948 | W10: 0.45718125 | X10: 0.31496250000000003 | Y10: 0.5899305555555555 | Z10: 0.2295581638268903 | AA10: 0.096209888 | AB10: 0.084483526 | AC10: 0.019545022799723158 | AD10: 0.001219732 | AE10: 0.007343764 | AF10: 0.23024518094422106 | AG10: 0.057047149
A11: SEA | B11: Logan Gilbert | C11: SP | D11: 28 | E11: 165.67 | F11: 660 | G11: =W11*$D11 -> 10.32989 | H11: =X11*$D11 -> 8.2216552 | I11: =Y11*$D11 -> 14.701149 | J11: =Z11*$F11 -> 137.18241 | K11: =AA11*$F11 -> 64.480349 | L11: =AB11*$F11 -> 61.992826 | M11: =AC11*$F11 -> 21.579338 | N11: =AD11*$F11 -> 0.98672574 | O11: =AE11*$F11 -> 5.5954371 | P11: =AF11*$F11 -> 182.73092 | Q11: =AG11*$F11 -> 37.550063 | R11: =P11/$E11*9 -> 9.926832 | S11: =Q11/$E11*9 -> 2.039902 | T11: =AF11-AG11 -> 0.21997099 | U11: =L11/$E11*9 -> 3.3677518 | V11: =(Q11+J11)/$E11 -> 1.0547019 | W11: 0.36892463054187186 | X11: 0.29363054187192117 | Y11: 0.5250410509031198 | Z11: 0.20785213420468282 | AA11: 0.097697499 | AB11: 0.093928524 | AC11: 0.032695966 | AD11: 0.001495039 | AE11: 0.008477935 | AF11: 0.27686502735538165 | AG11: 0.056894035
A12: NYY | B12: Max Fried | C12: SP | D12: 29 | E12: 180.33 | F12: 743 | G12: =W12*$D12 -> 12.862317 | H12: =X12*$D12 -> 8.1316452 | I12: =Y12*$D12 -> 16.543011 | J12: =Z12*$F12 -> 159.21809 | K12: =AA12*$F12 -> 72.578898 | L12: =AB12*$F12 -> 66.751205 | M12: =AC12*$F12 -> 16.729017 | N12: =AD12*$F12 -> 0.97084912 | O12: =AE12*$F12 -> 6.8602401 | P12: =AF12*$F12 -> 167.17142 | Q12: =AG12*$F12 -> 54.608752 | R12: =P12/$E12*9 -> 8.3432749 | S12: =Q12/$E12*9 -> 2.7254409 | T12: =AF12-AG12 -> 0.15149753 | U12: =L12/$E12*9 -> 3.3314526 | V12: =(Q12+J12)/$E12 -> 1.185753 | W12: 0.44352817 | X12: 0.2804015572858732 | Y12: 0.5704486466444197 | Z12: 0.2142908339244556 | AA12: 0.097683578 | AB12: 0.089840115 | AC12: 0.022515500749074338 | AD12: 0.001306661 | AE12: 0.009233163 | AF12: 0.2249951784351669 | AG12: 0.073497647
A13: CIN | B13: Hunter Greene | C13: SP | D13: 28 | E13: 167.67 | F13: 685 | G13: =W13*$D13 -> 9.7465161 | H13: =X13*$D13 -> 9.3025161 | I13: =Y13*$D13 -> 14.645161 | J13: =Z13*$F13 -> 135.49744 | K13: =AA13*$F13 -> 71.916911 | L13: =AB13*$F13 -> 68.627122 | M13: =AC13*$F13 -> 24.002223 | N13: =AD13*$F13 -> 0.5 | O13: =AE13*$F13 -> 9.2625198 | P13: =AF13*$F13 -> 197.64395 | Q13: =AG13*$F13 -> 53.45398 | R13: =P13/$E13*9 -> 10.608908 | S13: =Q13/$E13*9 -> 2.8692421 | T13: =AF13-AG13 -> 0.21049631 | U13: =L13/$E13*9 -> 3.6836888 | V13: =(Q13+J13)/$E13 -> 1.1269245 | W13: 0.3480898617511521 | X13: 0.33223271889400924 | Y13: 0.5230414746543779 | Z13: 0.1978064877087199 | AA13: 0.10498819160658443 | AB13: 0.10018557913945442 | AC13: 0.035039741 | AD13: 0.000729927 | AE13: 0.013521926693288422 | AF13: 0.28853131369578733 | AG13: 0.078035007
A14: KC | B14: Cole Ragans | C14: SP | D14: 26 | E14: 152.67 | F14: 624 | G14: =W14*$D14 -> 10.131621 | H14: =X14*$D14 -> 8.0149655 | I14: =Y14*$D14 -> 13.603448 | J14: =Z14*$F14 -> 121.04801 | K14: =AA14*$F14 -> 61.325126 | L14: =AB14*$F14 -> 57.53109 | M14: =AC14*$F14 -> 16.202958 | N14: =AD14*$F14 -> 1.4388186 | O14: =AE14*$F14 -> 5.0755524 | P14: =AF14*$F14 -> 188.59274 | Q14: =AG14*$F14 -> 53.953514 | R14: =P14/$E14*9 -> 11.11767 | S14: =Q14/$E14*9 -> 3.1805962 | T14: =AF14-AG14 -> 0.21576799 | U14: =L14/$E14*9 -> 3.3914968 | V14: =(Q14+J14)/$E14 -> 1.1462732 | W14: 0.38967771883289126 | X14: 0.3082679045092839 | Y14: 0.5232095490716181 | Z14: 0.19398719440164605 | AA14: 0.098277445 | AB14: 0.09219726 | AC14: 0.025966279464717648 | AD14: 0.002305799 | AE14: 0.008133898 | AF14: 0.30223194949567844 | AG14: 0.086463964
A15: TEX | B15: Jacob deGrom | C15: SP | D15: 26 | E15: 154.67 | F15: 617 | G15: =W15*$D15 -> 9.944069 | H15: =X15*$D15 -> 7.6819655 | I15: =Y15*$D15 -> 13.62069 | J15: =Z15*$F15 -> 127.38782 | K15: =AA15*$F15 -> 63.776432 | L15: =AB15*$F15 -> 59.723719 | M15: =AC15*$F15 -> 21.525732 | N15: =AD15*$F15 -> 0.50000014 | O15: =AE15*$F15 -> 4.0838409 | P15: =AF15*$F15 -> 168.41653 | Q15: =AG15*$F15 -> 37.169496 | R15: =P15/$E15*9 -> 9.7998886 | S15: =Q15/$E15*9 -> 2.1628335 | T15: =AF15-AG15 -> 0.21271805 | U15: =L15/$E15*9 -> 3.4752277 | V15: =(Q15+J15)/$E15 -> 1.0639252 | W15: 0.38246419098143236 | X15: 0.2954602122015915 | Y15: 0.5238726790450928 | Z15: 0.20646323561754726 | AA15: 0.10336536846142315 | AB15: 0.096796951 | AC15: 0.034887735 | AD15: 0.000810373 | AE15: 0.006618867 | AF15: 0.2729603408095245 | AG15: 0.060242295
A16: MIN | B16: Joe Ryan | C16: SP | D16: 28 | E16: 168 | F16: 680 | G16: =W16*$D16 -> 10.86269 | H16: =X16*$D16 -> 9.5421724 | I16: =Y16*$D16 -> 14.385057 | J16: =Z16*$F16 -> 143.97104 | K16: =AA16*$F16 -> 74.215223 | L16: =AB16*$F16 -> 70.019195 | M16: =AC16*$F16 -> 24.559251 | N16: =AD16*$F16 -> 0.49999992 | O16: =AE16*$F16 -> 7.5288655 | P16: =AF16*$F16 -> 182.60725 | Q16: =AG16*$F16 -> 38.854035 | R16: =P16/$E16*9 -> 9.7825311 | S16: =Q16/$E16*9 -> 2.0814662 | T16: =AF16-AG16 -> 0.21140178 | U16: =L16/$E16*9 -> 3.7510283 | V16: =(Q16+J16)/$E16 -> 1.0882445 | W16: 0.38795320197044336 | X16: 0.34079187192118227 | Y16: 0.51375205 | Z16: 0.21172211968271487 | AA16: 0.10914003454477993 | AB16: 0.10296940468452964 | AC16: 0.036116545211530196 | AD16: 0.000735294 | AE16: 0.011071861 | AF16: 0.2685400683536352 | AG16: 0.057138287
A17: NYM | B17: Freddy Peralta | C17: SP | D17: 29 | E17: 166.67 | F17: 691 | G17: =W17*$D17 -> 11.1888 | H17: =X17*$D17 -> 8.991 | I17: =Y17*$D17 -> 14 | J17: =Z17*$F17 -> 137.11136 | K17: =AA17*$F17 -> 74.903935 | L17: =AB17*$F17 -> 70.533279 | M17: =AC17*$F17 -> 21.779388 | N17: =AD17*$F17 -> 0.5 | O17: =AE17*$F17 -> 7.9284428 | P17: =AF17*$F17 -> 181.3385 | Q17: =AG17*$F17 -> 61.256703 | R17: =P17/$E17*9 -> 9.7920834 | S17: =Q17/$E17*9 -> 3.3077958 | T17: =AF17-AG17 -> 0.17377974 | U17: =L17/$E17*9 -> 3.8087209 | V17: =(Q17+J17)/$E17 -> 1.1901846 | W17: 0.38582068965517247 | X17: 0.3100344827586207 | Y17: 0.48275862068965525 | Z17: 0.19842454101798532 | AA17: 0.10839932738847943 | AB17: 0.10207421043890645 | AC17: 0.031518651 | AD17: 0.000723589 | AE17: 0.011473868025258897 | AF17: 0.2624290945275374 | AG17: 0.088649353
A18: SEA | B18: George Kirby | C18: SP | D18: 28 | E18: 166 | F18: 672 | G18: =W18*$D18 -> 11.070957 | H18: =X18*$D18 -> 9.0017419 | I18: =Y18*$D18 -> 14.795699 | J18: =Z18*$F18 -> 150.43173 | K18: =AA18*$F18 -> 67.728739 | L18: =AB18*$F18 -> 63.989013 | M18: =AC18*$F18 -> 19.899818 | N18: =AD18*$F18 -> 0.50000026 | O18: =AE18*$F18 -> 6.4571351 | P18: =AF18*$F18 -> 160.94139 | Q18: =AG18*$F18 -> 31.960773 | R18: =P18/$E18*9 -> 8.7257382 | S18: =Q18/$E18*9 -> 1.732813 | T18: =AF18-AG18 -> 0.19193545 | U18: =L18/$E18*9 -> 3.4692839 | V18: =(Q18+J18)/$E18 -> 1.09875 | W18: 0.39539132104454683 | X18: 0.32149078341013826 | Y18: 0.5284178187403994 | Z18: 0.2238567452409323 | AA18: 0.10078681385229835 | AB18: 0.095221746 | AC18: 0.029612823990355586 | AD18: 0.000744048 | AE18: 0.009608832 | AF18: 0.23949612228630993 | AG18: 0.047560674
A19: TOR | B19: Dylan Cease | C19: SP | D19: 30 | E19: 175.33 | F19: 728 | G19: =W19*$D19 -> 11.40525 | H19: =X19*$D19 -> 9.448875 | I19: =Y19*$D19 -> 15.09375 | J19: =Z19*$F19 -> 143.54323 | K19: =AA19*$F19 -> 74.421917 | L19: =AB19*$F19 -> 69.161936 | M19: =AC19*$F19 -> 21.306776 | N19: =AD19*$F19 -> 1.469072 | O19: =AE19*$F19 -> 5.5374126 | P19: =AF19*$F19 -> 205.28966 | Q19: =AG19*$F19 -> 65.358763 | R19: =P19/$E19*9 -> 10.537882 | S19: =Q19/$E19*9 -> 3.3549813 | T19: =AF19-AG19 -> 0.19221277 | U19: =L19/$E19*9 -> 3.5502049 | V19: =(Q19+J19)/$E19 -> 1.1914789 | W19: 0.38017500000000004 | X19: 0.31496250000000003 | Y19: 0.5031249999999999 | Z19: 0.19717476 | AA19: 0.10222790792073395 | AB19: 0.09500266 | AC19: 0.029267550096961796 | AD19: 0.002017956 | AE19: 0.007606336 | AF19: 0.2819912877279023 | AG19: 0.08977852
A20: DET | B20: Framber Valdez | C20: SP | D20: 29 | E20: 187 | F20: 780 | G20: =W20*$D20 -> 12.38386 | H20: =X20*$D20 -> 9.4421613 | I20: =Y20*$D20 -> 16.887097 | J20: =Z20*$F20 -> 171.08466 | K20: =AA20*$F20 -> 79.023259 | L20: =AB20*$F20 -> 70.77817 | M20: =AC20*$F20 -> 16.405739 | N20: =AD20*$F20 -> 0.50000028 | O20: =AE20*$F20 -> 8.2637872 | P20: =AF20*$F20 -> 171.8859 | Q20: =AG20*$F20 -> 62.368912 | R20: =P20/$E20*9 -> 8.2725834 | S20: =Q20/$E20*9 -> 3.0017124 | T20: =AF20-AG20 -> 0.14040639 | U20: =L20/$E20*9 -> 3.406436 | V20: =(Q20+J20)/$E20 -> 1.2484148 | W20: 0.4270296625880608 | X20: 0.32559176863181316 | Y20: 0.58231368 | Z20: 0.21933930446297226 | AA20: 0.10131187079514775 | AB20: 0.090741244 | AC20: 0.021032999296548137 | AD20: 0.000641026 | AE20: 0.010594599 | AF20: 0.22036653780194487 | AG20: 0.079960144
A21: BAL | B21: Kyle Bradish | C21: SP | D21: 24 | E21: 134 | F21: 554 | G21: =W21*$D21 -> 8.0688462 | H21: =X21*$D21 -> 7.4540769 | I21: =Y21*$D21 -> 11.448718 | J21: =Z21*$F21 -> 118.08512 | K21: =AA21*$F21 -> 57.746661 | L21: =AB21*$F21 -> 53.074942 | M21: =AC21*$F21 -> 15.095286 | N21: =AD21*$F21 -> 0.49999996 | O21: =AE21*$F21 -> 5.7921495 | P21: =AF21*$F21 -> 140.64855 | Q21: =AG21*$F21 -> 43.540764 | R21: =P21/$E21*9 -> 9.4465446 | S21: =Q21/$E21*9 -> 2.9243796 | T21: =AF21-AG21 -> 0.17528482 | U21: =L21/$E21*9 -> 3.5647349 | V21: =(Q21+J21)/$E21 -> 1.2061633 | W21: 0.33620192307692304 | X21: 0.3105865384615385 | Y21: 0.47702991452991456 | Z21: 0.21315003094937196 | AA21: 0.10423585052031481 | AB21: 0.095803145 | AC21: 0.027247809 | AD21: 0.000902527 | AE21: 0.010455143515142833 | AF21: 0.25387825540541775 | AG21: 0.078593436
A22: SD | B22: Nick Pivetta | C22: SP | D22: 28 | E22: 169 | F22: 691 | G22: =W22*$D22 -> 9.8751724 | H22: =X22*$D22 -> 9.5421724 | I22: =Y22*$D22 -> 14.390805 | J22: =Z22*$F22 -> 146.23959 | K22: =AA22*$F22 -> 77.375707 | L22: =AB22*$F22 -> 73.017062 | M22: =AC22*$F22 -> 26.537271 | N22: =AD22*$F22 -> 0.97524078 | O22: =AE22*$F22 -> 4.8864618 | P22: =AF22*$F22 -> 181.13019 | Q22: =AG22*$F22 -> 49.381296 | R22: =P22/$E22*9 -> 9.6459867 | S22: =Q22/$E22*9 -> 2.6297732 | T22: =AF22-AG22 -> 0.19066411 | U22: =L22/$E22*9 -> 3.8884826 | V22: =(Q22+J22)/$E22 -> 1.15752 | W22: 0.3526847290640394 | X22: 0.34079187192118227 | Y22: 0.5139573070607554 | Z22: 0.2116347193411276 | AA22: 0.1119764216284882 | AB22: 0.10566868568506149 | AC22: 0.038404155 | AD22: 0.001411347 | AE22: 0.00707158 | AF22: 0.2621276338540141 | AG22: 0.071463526
A23: LAD | B23: Blake Snell | C23: SP | D23: 22 | E23: 130 | F23: 538 | G23: =W23*$D23 -> 9.1733571 | H23: =X23*$D23 -> 6.13275 | I23: =Y23*$D23 -> 11.736111 | J23: =Z23*$F23 -> 104.25905 | K23: =AA23*$F23 -> 53.627117 | L23: =AB23*$F23 -> 50.859145 | M23: =AC23*$F23 -> 14.434844 | N23: =AD23*$F23 -> 0.95134217 | O23: =AE23*$F23 -> 3.1875446 | P23: =AF23*$F23 -> 158.43485 | Q23: =AG23*$F23 -> 53.852922 | R23: =P23/$E23*9 -> 10.968567 | S23: =Q23/$E23*9 -> 3.7282792 | T23: =AF23-AG23 -> 0.19439021 | U23: =L23/$E23*9 -> 3.5210177 | V23: =(Q23+J23)/$E23 -> 1.216246 | W23: 0.4169707792207792 | X23: 0.2787613636363636 | Y23: 0.5334595959595959 | Z23: 0.19379006218828887 | AA23: 0.099678656 | AB23: 0.094533727 | AC23: 0.026830565123972548 | AD23: 0.001768294 | AE23: 0.005924804 | AF23: 0.2944885727791291 | AG23: 0.10009836731993856
A24: PHI | B24: Jesus Luzardo | C24: SP | D24: 29 | E24: 175.67 | F24: 720 | G24: =W24*$D24 -> 11.528015 | H24: =X24*$D24 -> 9.1091613 | I24: =Y24*$D24 -> 15.274194 | J24: =Z24*$F24 -> 151.67589 | K24: =AA24*$F24 -> 75.440899 | L24: =AB24*$F24 -> 74.063941 | M24: =AC24*$F24 -> 21.322119 | N24: =AD24*$F24 -> 0.97872336 | O24: =AE24*$F24 -> 5.2201706 | P24: =AF24*$F24 -> 192.79466 | Q24: =AG24*$F24 -> 54.238181 | R24: =P24/$E24*9 -> 9.8773379 | S24: =Q24/$E24*9 -> 2.7787535 | T24: =AF24-AG24 -> 0.19243955 | U24: =L24/$E24*9 -> 3.7944753 | V24: =(Q24+J24)/$E24 -> 1.1721641 | W24: 0.39751775782615606 | X24: 0.31410901001112346 | Y24: 0.5266963292547274 | Z24: 0.2106609640989362 | AA24: 0.10477902691402555 | AB24: 0.1028665852807813 | AC24: 0.029614054480670487 | AD24: 0.001359338 | AE24: 0.007250237 | AF24: 0.2677703612036192 | AG24: 0.075330807
A25: LAD | B25: Shohei Ohtani | C25: SP | D25: 21 | E25: 110 | F25: 447 | G25: =W25*$D25 -> 7.9187038 | H25: =X25*$D25 -> 5.1542609 | I25: =Y25*$D25 -> 9.2971014 | J25: =Z25*$F25 -> 87.938075 | K25: =AA25*$F25 -> 44.475148 | L25: =AB25*$F25 -> 43.064396 | M25: =AC25*$F25 -> 13.322363 | N25: =AD25*$F25 -> 0.4999999 | O25: =AE25*$F25 -> 4.5182565 | P25: =AF25*$F25 -> 131.18252 | Q25: =AG25*$F25 -> 36.062143 | R25: =P25/$E25*9 -> 10.733115 | S25: =Q25/$E25*9 -> 2.950539 | T25: =AF25-AG25 -> 0.21279726 | U25: =L25/$E25*9 -> 3.5234506 | V25: =(Q25+J25)/$E25 -> 1.1272747 | W25: 0.37708113354037265 | X25: 0.2454409937888198 | Y25: 0.44271911663216007 | Z25: 0.19672947522222997 | AA25: 0.099496976 | AB25: 0.096340931 | AC25: 0.029803945014076197 | AD25: 0.001118568 | AE25: 0.010107956431152676 | AF25: 0.29347319347319345 | AG25: 0.080675935
A26: NYM | B26: Nolan McLean | C26: SP | D26: 26 | E26: 152.33 | F26: 643 | G26: =W26*$D26 -> 9.7521429 | H26: =X26*$D26 -> 7.992 | I26: =Y26*$D26 -> 13 | J26: =Z26*$F26 -> 137.03718 | K26: =AA26*$F26 -> 67.887272 | L26: =AB26*$F26 -> 63.989463 | M26: =AC26*$F26 -> 16.144909 | N26: =AD26*$F26 -> 1.0047094 | O26: =AE26*$F26 -> 8.3542424 | P26: =AF26*$F26 -> 144.91886 | Q26: =AG26*$F26 -> 56.151318 | R26: =P26/$E26*9 -> 8.5621332 | S26: =Q26/$E26*9 -> 3.3175465 | T26: =AF26-AG26 -> 0.13805217 | U26: =L26/$E26*9 -> 3.7806418 | V26: =(Q26+J26)/$E26 -> 1.2682236 | W26: 0.37508241758241756 | X26: 0.3073846153846154 | Y26: 0.5 | Z26: 0.21312157968866913 | AA26: 0.10557896080148604 | AB26: 0.09951705 | AC26: 0.025108723 | AD26: 0.001562534 | AE26: 0.012992601 | AF26: 0.22537925424615868 | AG26: 0.087327089
A27: TOR | B27: Kevin Gausman | C27: SP | D27: 29 | E27: 181.67 | F27: 749 | G27: =W27*$D27 -> 10.883499 | H27: =X27*$D27 -> 9.7751613 | I27: =Y27*$D27 -> 15.284946 | J27: =Z27*$F27 -> 167.64051 | K27: =AA27*$F27 -> 84.07787 | L27: =AB27*$F27 -> 76.386265 | M27: =AC27*$F27 -> 24.628819 | N27: =AD27*$F27 -> 0.97828837 | O27: =AE27*$F27 -> 4.2342094 | P27: =AF27*$F27 -> 173.16147 | Q27: =AG27*$F27 -> 52.712037 | R27: =P27/$E27*9 -> 8.5784844 | S27: =Q27/$E27*9 -> 2.6113741 | T27: =AF27-AG27 -> 0.16081367 | U27: =L27/$E27*9 -> 3.7842043 | V27: =(Q27+J27)/$E27 -> 1.2129275 | W27: 0.37529306372159543 | X27: 0.3370745272525028 | Y27: 0.5270671116054876 | Z27: 0.22381910110803904 | AA27: 0.11225349823598861 | AB27: 0.10198433276771504 | AC27: 0.032882268 | AD27: 0.001306126 | AE27: 0.00565315 | AF27: 0.23119021759001923 | AG27: 0.070376551
A28: ATL | B28: Spencer Schwellenbach | C28: SP | D28: 12 | E28: 68.67 | F28: 278 | G28: =W28*$D28 -> 4.8618 | H28: =X28*$D28 -> 3.3966 | I28: =Y28*$D28 -> 6.1333333 | J28: =Z28*$F28 -> 63.319726 | K28: =AA28*$F28 -> 29.329435 | L28: =AB28*$F28 -> 26.399509 | M28: =AC28*$F28 -> 8.1297858 | N28: =AD28*$F28 -> 0.49999996 | O28: =AE28*$F28 -> 2.1030027 | P28: =AF28*$F28 -> 66.988502 | Q28: =AG28*$F28 -> 14.256145 | R28: =P28/$E28*9 -> 8.7796202 | S28: =Q28/$E28*9 -> 1.8684332 | T28: =AF28-AG28 -> 0.18968474 | U28: =L28/$E28*9 -> 3.4599618 | V28: =(Q28+J28)/$E28 -> 1.1296909 | W28: 0.40515 | X28: 0.28305 | Y28: 0.5111111111111112 | Z28: 0.22776879981120107 | AA28: 0.10550156439659525 | AB28: 0.094962262 | AC28: 0.029243833931667428 | AD28: 0.001798561 | AE28: 0.007564758 | AF28: 0.24096583584013753 | AG28: 0.051281098026606624
A29: BOS | B29: Sonny Gray | C29: SP | D29: 28 | E29: 169 | F29: 697 | G29: =W29*$D29 -> 11.070957 | H29: =X29*$D29 -> 9.0017419 | I29: =Y29*$D29 -> 14.327957 | J29: =Z29*$F29 -> 155.85452 | K29: =AA29*$F29 -> 74.470212 | L29: =AB29*$F29 -> 68.771254 | M29: =AC29*$F29 -> 21.120306 | N29: =AD29*$F29 -> 0.96036981 | O29: =AE29*$F29 -> 5.4855852 | P29: =AF29*$F29 -> 172.74039 | Q29: =AG29*$F29 -> 44.8428 | R29: =P29/$E29*9 -> 9.1991924 | S29: =Q29/$E29*9 -> 2.3880781 | T29: =AF29-AG29 -> 0.18349726 | U29: =L29/$E29*9 -> 3.6623745 | V29: =(Q29+J29)/$E29 -> 1.1875581 | W29: 0.39539132104454683 | X29: 0.32149078341013826 | Y29: 0.5117127496159753 | Z29: 0.22360763488844718 | AA29: 0.1068439199498927 | AB29: 0.09866751 | AC29: 0.030301730045454674 | AD29: 0.001377862 | AE29: 0.00787028 | AF29: 0.24783413244095992 | AG29: 0.064336873
A30: TOR | B30: Trey Yesavage | C30: SP | D30: 30 | E30: 136 | F30: 570 | G30: =W30*$D30 -> 7.1991429 | H30: =X30*$D30 -> 7.215 | I30: =Y30*$D30 -> 8.9166667 | J30: =Z30*$F30 -> 113.97829 | K30: =AA30*$F30 -> 59.314302 | L30: =AB30*$F30 -> 58.154264 | M30: =AC30*$F30 -> 17.417395 | N30: =AD30*$F30 -> 0.94049487 | O30: =AE30*$F30 -> 5.4373366 | P30: =AF30*$F30 -> 148.61551 | Q30: =AG30*$F30 -> 53.200944 | R30: =P30/$E30*9 -> 9.8348502 | S30: =Q30/$E30*9 -> 3.5206507 | T30: =AF30-AG30 -> 0.16739398 | U30: =L30/$E30*9 -> 3.8484439 | V30: =(Q30+J30)/$E30 -> 1.2292591 | W30: 0.23997142857142856 | X30: 0.2405 | Y30: 0.2972222222222222 | Z30: 0.19996191501446647 | AA30: 0.10406017848611819 | AB30: 0.10202502399069241 | AC30: 0.030556832687688638 | AD30: 0.001649991 | AE30: 0.009539187 | AF30: 0.26072897153301544 | AG30: 0.09333499
A31: LAD | B31: Tyler Glasnow | C31: SP | D31: 23 | E31: 132.33 | F31: 544 | G31: =W31*$D31 -> 8.3448214 | H31: =X31*$D31 -> 6.229875 | I31: =Y31*$D31 -> 11.555556 | J31: =Z31*$F31 -> 109.91395 | K31: =AA31*$F31 -> 56.527708 | L31: =AB31*$F31 -> 54.464962 | M31: =AC31*$F31 -> 16.886115 | N31: =AD31*$F31 -> 0 | O31: =AE31*$F31 -> 3.5764611 | P31: =AF31*$F31 -> 152.80999 | Q31: =AG31*$F31 -> 47.568351 | R31: =P31/$E31*9 -> 10.392881 | S31: =Q31/$E31*9 -> 3.2352086 | T31: =AF31-AG31 -> 0.19345889 | U31: =L31/$E31*9 -> 3.7042595 | V31: =(Q31+J31)/$E31 -> 1.1900726 | W31: 0.3628183229813664 | X31: 0.27086413043478264 | Y31: 0.50241546 | Z31: 0.20204770328162386 | AA31: 0.10391122785827936 | AB31: 0.10011941486422965 | AC31: 0.031040652 | AD31: 0 | AE31: 0.006574377 | AF31: 0.28090071472806266 | AG31: 0.087441821
A32: MIL | B32: Jacob Misiorowski | C32: SP | D32: 32 | E32: 139.33 | F32: 591 | G32: =W32*$D32 -> 8.9397692 | H32: =X32*$D32 -> 8.658 | I32: =Y32*$D32 -> 9.5 | J32: =Z32*$F32 -> 114.85244 | K32: =AA32*$F32 -> 63.430239 | L32: =AB32*$F32 -> 60.554431 | M32: =AC32*$F32 -> 17.787043 | N32: =AD32*$F32 -> 0.99249999 | O32: =AE32*$F32 -> 8.5879194 | P32: =AF32*$F32 -> 162.21626 | Q32: =AG32*$F32 -> 65.860291 | R32: =P32/$E32*9 -> 10.478335 | S32: =Q32/$E32*9 -> 4.2542354 | T32: =AF32-AG32 -> 0.16303887 | U32: =L32/$E32*9 -> 3.9115042 | V32: =(Q32+J32)/$E32 -> 1.2970123 | W32: 0.2793677884615385 | X32: 0.2705625 | Y32: 0.296875 | Z32: 0.1943357637134886 | AA32: 0.10732696877329273 | AB32: 0.1024609663564247 | AC32: 0.030096519 | AD32: 0.001679357 | AE32: 0.014531166492360236 | AF32: 0.27447760326849496 | AG32: 0.11143873343026463
A33: SEA | B33: Luis Castillo | C33: SP | D33: 29 | E33: 176.67 | F33: 730 | G33: =W33*$D33 -> 10.419677 | H33: =X33*$D33 -> 9.7751613 | I33: =Y33*$D33 -> 14.795699 | J33: =Z33*$F33 -> 161.71717 | K33: =AA33*$F33 -> 80.167704 | L33: =AB33*$F33 -> 73.95672 | M33: =AC33*$F33 -> 24.678412 | N33: =AD33*$F33 -> 0.9783752 | O33: =AE33*$F33 -> 6.8669151 | P33: =AF33*$F33 -> 161.74447 | Q33: =AG33*$F33 -> 49.682424 | R33: =P33/$E33*9 -> 8.2396571 | S33: =Q33/$E33*9 -> 2.5309437 | T33: =AF33-AG33 -> 0.15350965 | U33: =L33/$E33*9 -> 3.7675354 | V33: =(Q33+J33)/$E33 -> 1.1965789 | W33: 0.35929922135706344 | X33: 0.3370745272525028 | Y33: 0.5101965146459028 | Z33: 0.22153037047083884 | AA33: 0.10981877217369035 | AB33: 0.10131057536756169 | AC33: 0.033806044 | AD33: 0.00134024 | AE33: 0.009406733 | AF33: 0.22156776685418744 | AG33: 0.068058115
A34: MIA | B34: Eury Perez | C34: SP | D34: 27 | E34: 143.33 | F34: 588 | G34: =W34*$D34 -> 7.9746181 | H34: =X34*$D34 -> 9.5380714 | I34: =Y34*$D34 -> 11.744048 | J34: =Z34*$F34 -> 120.39186 | K34: =AA34*$F34 -> 65.318513 | L34: =AB34*$F34 -> 64.153494 | M34: =AC34*$F34 -> 20.249011 | N34: =AD34*$F34 -> 0.49999992 | O34: =AE34*$F34 -> 4.8323816 | P34: =AF34*$F34 -> 151.09577 | Q34: =AG34*$F34 -> 46.783249 | R34: =P34/$E34*9 -> 9.4876294 | S34: =Q34/$E34*9 -> 2.9376211 | T34: =AF34-AG34 -> 0.17740225 | U34: =L34/$E34*9 -> 4.0283363 | V34: =(Q34+J34)/$E34 -> 1.1663651 | W34: 0.2953562271062271 | X34: 0.3532619047619047 | Y34: 0.43496472663139335 | Z34: 0.20474805572898286 | AA34: 0.11108590702420623 | AB34: 0.10910458088209299 | AC34: 0.034437093 | AD34: 0.00085034 | AE34: 0.008218336 | AF34: 0.25696559503666105 | AG34: 0.079563348
A35: ATL | B35: Spencer Strider | C35: SP | D35: 26 | E35: 153 | F35: 638 | G35: =W35*$D35 -> 10.540877 | H35: =X35*$D35 -> 8.7769286 | I35: =Y35*$D35 -> 12.797619 | J35: =Z35*$F35 -> 132.13 | K35: =AA35*$F35 -> 69.722046 | L35: =AB35*$F35 -> 64.966092 | M35: =AC35*$F35 -> 20.310442 | N35: =AD35*$F35 -> 0.97329388 | O35: =AE35*$F35 -> 6.5168806 | P35: =AF35*$F35 -> 179.97255 | Q35: =AG35*$F35 -> 52.742838 | R35: =P35/$E35*9 -> 10.586621 | S35: =Q35/$E35*9 -> 3.1025199 | T35: =AF35-AG35 -> 0.19941961 | U35: =L35/$E35*9 -> 3.8215348 | V35: =(Q35+J35)/$E35 -> 1.2083192 | W35: 0.4054183516483516 | X35: 0.33757417582417576 | Y35: 0.4922161172161172 | Z35: 0.20710031118953365 | AA35: 0.10928220325539569 | AB35: 0.10182773024116068 | AC35: 0.031834548293180776 | AD35: 0.001525539 | AE35: 0.010214546461017418 | AF35: 0.28208863752339547 | AG35: 0.082669025
A36: NYY | B36: Cam Schlittler | C36: SP | D36: 23 | E36: 130.67 | F36: 551 | G36: =W36*$D36 -> 7.881 | H36: =X36*$D36 -> 7.992 | I36: =Y36*$D36 -> 10.666667 | J36: =Z36*$F36 -> 118.14533 | K36: =AA36*$F36 -> 60.890077 | L36: =AB36*$F36 -> 57.959085 | M36: =AC36*$F36 -> 16.628463 | N36: =AD36*$F36 -> 0.49999999 | O36: =AE36*$F36 -> 6.0131776 | P36: =AF36*$F36 -> 128.89326 | Q36: =AG36*$F36 -> 49.031642 | R36: =P36/$E36*9 -> 8.8776259 | S36: =Q36/$E36*9 -> 3.3770933 | T36: =AF36-AG36 -> 0.14493942 | U36: =L36/$E36*9 -> 3.991978 | V36: =(Q36+J36)/$E36 -> 1.279383 | W36: 0.3426521739130434 | X36: 0.3474782608695651 | Y36: 0.46376812 | Z36: 0.2144198401631486 | AA36: 0.11050830721402541 | AB36: 0.10518890182556383 | AC36: 0.030178698 | AD36: 0.000907441 | AE36: 0.010913207909887972 | AF36: 0.23392607033573648 | AG36: 0.088986646
A37: CIN | B37: Chase Burns | C37: SP,RP | D37: 29 | E37: 134 | F37: 548 | G37: =W37*$D37 -> 7.6597957 | H37: =X37*$D37 -> 7.8416129 | I37: =Y37*$D37 -> 9.1236559 | J37: =Z37*$F37 -> 114.55061 | K37: =AA37*$F37 -> 54.826075 | L37: =AB37*$F37 -> 54.92049 | M37: =AC37*$F37 -> 18.26018 | N37: =AD37*$F37 -> 1.0279384 | O37: =AE37*$F37 -> 4.3853952 | P37: =AF37*$F37 -> 154.50635 | Q37: =AG37*$F37 -> 41.113817 | R37: =P37/$E37*9 -> 10.377292 | S37: =Q37/$E37*9 -> 2.7613758 | T37: =AF37-AG37 -> 0.20692068 | U37: =L37/$E37*9 -> 3.6886896 | V37: =(Q37+J37)/$E37 -> 1.1616748 | W37: 0.2641308861698183 | X37: 0.27040044493882087 | Y37: 0.3146088246199481 | Z37: 0.20903395596301627 | AA37: 0.10004758215585523 | AB37: 0.10021987150971462 | AC37: 0.033321496784670994 | AD37: 0.0018758 | AE37: 0.008002546 | AF37: 0.28194589301293477 | AG37: 0.075025213
A38: MIL | B38: Brandon Woodruff | C38: SP | D38: 25 | E38: 143.67 | F38: 585 | G38: =W38*$D38 -> 8.8839643 | H38: =X38*$D38 -> 7.6708929 | I38: =Y38*$D38 -> 12.196429 | J38: =Z38*$F38 -> 123.02703 | K38: =AA38*$F38 -> 65.137516 | L38: =AB38*$F38 -> 58.397656 | M38: =AC38*$F38 -> 20.302754 | N38: =AD38*$F38 -> 0 | O38: =AE38*$F38 -> 5.668588 | P38: =AF38*$F38 -> 151.4536 | Q38: =AG38*$F38 -> 38.899047 | R38: =P38/$E38*9 -> 9.4875927 | S38: =Q38/$E38*9 -> 2.4367747 | T38: =AF38-AG38 -> 0.19240095 | U38: =L38/$E38*9 -> 3.658237 | V38: =(Q38+J38)/$E38 -> 1.1270695 | W38: 0.3553585714285714 | X38: 0.3068357142857143 | Y38: 0.4878571428571428 | Z38: 0.2103026219683316 | AA38: 0.1113461806804232 | AB38: 0.099825053 | AC38: 0.034705563 | AD38: 0 | AE38: 0.009689894 | AF38: 0.25889505026421167 | AG38: 0.066494098
A39: SD | B39: Michael King | C39: SP | D39: 27 | E39: 154.67 | F39: 647 | G39: =W39*$D39 -> 9.5576492 | H39: =X39*$D39 -> 8.7613448 | I39: =Y39*$D39 -> 12.793103 | J39: =Z39*$F39 -> 137.14464 | K39: =AA39*$F39 -> 69.031432 | L39: =AB39*$F39 -> 61.864202 | M39: =AC39*$F39 -> 19.596415 | N39: =AD39*$F39 -> 1.460171 | O39: =AE39*$F39 -> 6.78944 | P39: =AF39*$F39 -> 159.54482 | Q39: =AG39*$F39 -> 53.668905 | R39: =P39/$E39*9 -> 9.283658 | S39: =Q39/$E39*9 -> 3.1229078 | T39: =AF39-AG39 -> 0.16364129 | U39: =L39/$E39*9 -> 3.599779 | V39: =(Q39+J39)/$E39 -> 1.2336817 | W39: 0.35398700649675163 | X39: 0.32449425287356326 | Y39: 0.47381864623243936 | Z39: 0.21197007299944948 | AA39: 0.10669463969902568 | AB39: 0.095617004 | AC39: 0.030288122669477918 | AD39: 0.002256833 | AE39: 0.010493724919014671 | AF39: 0.24659168591199587 | AG39: 0.082950394
A40: TEX | B40: Nathan Eovaldi | C40: SP | D40: 25 | E40: 155 | F40: 631 | G40: =W40*$D40 -> 9.2627586 | H40: =X40*$D40 -> 7.9116207 | I40: =Y40*$D40 -> 13.350575 | J40: =Z40*$F40 -> 140.02814 | K40: =AA40*$F40 -> 68.066464 | L40: =AB40*$F40 -> 65.096774 | M40: =AC40*$F40 -> 19.046251 | N40: =AD40*$F40 -> 0.93577363 | O40: =AE40*$F40 -> 6.0056542 | P40: =AF40*$F40 -> 144.20137 | Q40: =AG40*$F40 -> 39.519001 | R40: =P40/$E40*9 -> 8.3729825 | S40: =Q40/$E40*9 -> 2.2946517 | T40: =AF40-AG40 -> 0.16589915 | U40: =L40/$E40*9 -> 3.7798127 | V40: =(Q40+J40)/$E40 -> 1.1583686 | W40: 0.3705103448275862 | X40: 0.3164648275862069 | Y40: 0.5340229885057471 | Z40: 0.22191463608785952 | AA40: 0.10787078344741342 | AB40: 0.10316445897865079 | AC40: 0.030184233 | AD40: 0.001483001 | AE40: 0.009517677 | AF40: 0.22852831391746392 | AG40: 0.062629162
...

Sheet CKBT_Rank
A1: Name | B1: Team | C1: Position | D1: G | E1: IP | F1: Total | G1: TBF | H1: IP+ | I1: W+ | J1: L+ | K1: QS+ | L1: HR+ | M1: HBP+ | N1: ERA+ | O1: WHIP+ | P1: K/9+ | Q1: K-BB%+ | S1: IP | T1: W | U1: L | V1: QS | W1: H | X1: R | Y1: ER | Z1: HR | AA1: IBB | AB1: HBP | AC1: K | AD1: BB | AE1: K/9 | AF1: K-BB% | AG1: ERA | AH1: WHIP
A2: Tarik Skubal | B2: DET | C2: SP | D2: 30 | E2: 192.33 | F2: =H2*1.5+I2+J2+K2*1.5+L2+M2+N2+O2+P2+Q2 -> 19.176213 | G2: 752 | H2: =(S2-S$123)/S$124 -> 1.5359249 | I2: =(T2-T$123)/T$124 -> 2.2937281 | J2: =(U2-U$123)/U$124 -> 0.19179348 | K2: =(V2-V$123)/V$124 -> 1.9859342 | L2: =(Z2-Z$123)/Z$124 -> -0.082135555 | M2: =(AB2-AB$123)/AB$124 -> -0.37408974 | N2: =(AG2-AG$123)/AG$124 -> 3.4572971 | O2: =(AH2-AH$123)/AH$124 -> 3.2119647 | P2: =(AE2-AE$123)/AE$124 -> 2.0623258 | Q2: =(AF2-AF$123)/AF$124 -> 3.1325404 | S2: =(E2-AVERAGE(E$2:E$122))/AVERAGE(E$2:E$122)*100+100 -> 133.25117 | T2: =('2026_Fantasy_Starters'!G2-AVERAGE('2026_Fantasy_Starters'!G$2:'2026_Fantasy_Starters'!G$122))/AVERAGE('2026_Fantasy_Starters'!G$2:'2026_Fantasy_Starters'!G$122)*100+100 -> 156.81609 | U2: =(AVERAGE('2026_Fantasy_Starters'!H$2:'2026_Fantasy_Starters'!H$122)-'2026_Fantasy_Starters'!H2)/AVERAGE('2026_Fantasy_Starters'!H$2:'2026_Fantasy_Starters'!H$122)*100+100 -> 104.37172 | V2: =('2026_Fantasy_Starters'!I2-AVERAGE('2026_Fantasy_Starters'!I$2:'2026_Fantasy_Starters'!I$122))/AVERAGE('2026_Fantasy_Starters'!I$2:'2026_Fantasy_Starters'!I$122)*100+100 -> 167.16394 | W2: =(AVERAGE('2026_Fantasy_Starters'!J$2:'2026_Fantasy_Starters'!J$122)-'2026_Fantasy_Starters'!J2)/AVERAGE('2026_Fantasy_Starters'!J$2:'2026_Fantasy_Starters'!J$122)*100+100 -> 87.638665 | X2: =(AVERAGE('2026_Fantasy_Starters'!K$2:'2026_Fantasy_Starters'!K$122)-'2026_Fantasy_Starters'!K2)/AVERAGE('2026_Fantasy_Starters'!K$2:'2026_Fantasy_Starters'!K$122)*100+100 -> 107.54255 | Y2: =(AVERAGE('2026_Fantasy_Starters'!L$2:'2026_Fantasy_Starters'!L$122)-'2026_Fantasy_Starters'!L2)/AVERAGE('2026_Fantasy_Starters'!L$2:'2026_Fantasy_Starters'!L$122)*100+100 -> 109.60665 | Z2: =(AVERAGE('2026_Fantasy_Starters'!M$2:'2026_Fantasy_Starters'!M$122)-'2026_Fantasy_Starters'!M2)/AVERAGE('2026_Fantasy_Starters'!M$2:'2026_Fantasy_Starters'!M$122)*100+100 -> 97.91157 | AA2: =(AVERAGE('2026_Fantasy_Starters'!N$2:'2026_Fantasy_Starters'!N$122)-'2026_Fantasy_Starters'!N2)/AVERAGE('2026_Fantasy_Starters'!N$2:'2026_Fantasy_Starters'!N$122)*100+100 -> 138.58608 | AB2: =(AVERAGE('2026_Fantasy_Starters'!O$2:'2026_Fantasy_Starters'!O$122)-'2026_Fantasy_Starters'!O2)/AVERAGE('2026_Fantasy_Starters'!O$2:'2026_Fantasy_Starters'!O$122)*100+100 -> 88.403658 | AC2: =('2026_Fantasy_Starters'!P2-AVERAGE('2026_Fantasy_Starters'!P$2:'2026_Fantasy_Starters'!P$122))/AVERAGE('2026_Fantasy_Starters'!P$2:'2026_Fantasy_Starters'!P$122)*100+100 -> 164.54802 | AD2: =(AVERAGE('2026_Fantasy_Starters'!Q$2:'2026_Fantasy_Starters'!Q$122)-'2026_Fantasy_Starters'!Q2)/AVERAGE('2026_Fantasy_Starters'!Q$2:'2026_Fantasy_Starters'!Q$122)*100+100 -> 112.89436 | AE2: =('2026_Fantasy_Starters'!R2-AVERAGE('2026_Fantasy_Starters'!R$2:'2026_Fantasy_Starters'!R$122))/AVERAGE('2026_Fantasy_Starters'!R$2:'2026_Fantasy_Starters'!R$122)*100+100 -> 123.41662 | AF2: =('2026_Fantasy_Starters'!T2-AVERAGE('2026_Fantasy_Starters'!T$2:'2026_Fantasy_Starters'!T$122))/AVERAGE('2026_Fantasy_Starters'!T$2:'2026_Fantasy_Starters'!T$122)*100+100 -> 161.56295 | AG2: =(AVERAGE('2026_Fantasy_Starters'!U$2:'2026_Fantasy_Starters'!U$122)-'2026_Fantasy_Starters'!U2)/AVERAGE('2026_Fantasy_Starters'!U$2:'2026_Fantasy_Starters'!U$122)*100+100 -> 132.46296 | AH2: =(AVERAGE('2026_Fantasy_Starters'!V$2:'2026_Fantasy_Starters'!V$122)-'2026_Fantasy_Starters'!V2)/AVERAGE('2026_Fantasy_Starters'!V$2:'2026_Fantasy_Starters'!V$122)*100+100 -> 120.80923
A3: 1 Garrett Crochet | B3: BOS | C3: SP | D3: 29 | E3: 181.67 | F3: =H3*1.5+I3+J3+K3*1.5+L3+M3+N3+O3+P3+Q3 -> 16.32112 | G3: 727 | H3: =(S3-S$123)/S$124 -> 1.1947757 | I3: =(T3-T$123)/T$124 -> 2.1494081 | J3: =(U3-U$123)/U$124 -> 0.063136077 | K3: =(V3-V$123)/V$124 -> 1.5585098 | L3: =(Z3-Z$123)/Z$124 -> -0.098361187 | M3: =(AB3-AB$123)/AB$124 -> 0.35272204 | N3: =(AG3-AG$123)/AG$124 -> 2.8238553 | O3: =(AH3-AH$123)/AH$124 -> 2.1187522 | P3: =(AE3-AE$123)/AE$124 -> 2.134883 | Q3: =(AF3-AF$123)/AF$124 -> 2.6467961 | S3: =(E3-AVERAGE(E$2:E$122))/AVERAGE(E$2:E$122)*100+100 -> 125.86565 | T3: =('2026_Fantasy_Starters'!G4-AVERAGE('2026_Fantasy_Starters'!G$2:'2026_Fantasy_Starters'!G$122))/AVERAGE('2026_Fantasy_Starters'!G$2:'2026_Fantasy_Starters'!G$122)*100+100 -> 153.24126 | U3: =(AVERAGE('2026_Fantasy_Starters'!H$2:'2026_Fantasy_Starters'!H$122)-'2026_Fantasy_Starters'!H4)/AVERAGE('2026_Fantasy_Starters'!H$2:'2026_Fantasy_Starters'!H$122)*100+100 -> 101.43912 | V3: =('2026_Fantasy_Starters'!I4-AVERAGE('2026_Fantasy_Starters'!I$2:'2026_Fantasy_Starters'!I$122))/AVERAGE('2026_Fantasy_Starters'!I$2:'2026_Fantasy_Starters'!I$122)*100+100 -> 152.70852 | W3: =(AVERAGE('2026_Fantasy_Starters'!J$2:'2026_Fantasy_Starters'!J$122)-'2026_Fantasy_Starters'!J4)/AVERAGE('2026_Fantasy_Starters'!J$2:'2026_Fantasy_Starters'!J$122)*100+100 -> 88.079904 | X3: =(AVERAGE('2026_Fantasy_Starters'!K$2:'2026_Fantasy_Starters'!K$122)-'2026_Fantasy_Starters'!K4)/AVERAGE('2026_Fantasy_Starters'!K$2:'2026_Fantasy_Starters'!K$122)*100+100 -> 103.75329 | Y3: =(AVERAGE('2026_Fantasy_Starters'!L$2:'2026_Fantasy_Starters'!L$122)-'2026_Fantasy_Starters'!L4)/AVERAGE('2026_Fantasy_Starters'!L$2:'2026_Fantasy_Starters'!L$122)*100+100 -> 107.09726 | Z3: =(AVERAGE('2026_Fantasy_Starters'!M$2:'2026_Fantasy_Starters'!M$122)-'2026_Fantasy_Starters'!M4)/AVERAGE('2026_Fantasy_Starters'!M$2:'2026_Fantasy_Starters'!M$122)*100+100 -> 97.499007 | AA3: =(AVERAGE('2026_Fantasy_Starters'!N$2:'2026_Fantasy_Starters'!N$122)-'2026_Fantasy_Starters'!N4)/AVERAGE('2026_Fantasy_Starters'!N$2:'2026_Fantasy_Starters'!N$122)*100+100 -> 77.172214 | AB3: =(AVERAGE('2026_Fantasy_Starters'!O$2:'2026_Fantasy_Starters'!O$122)-'2026_Fantasy_Starters'!O4)/AVERAGE('2026_Fantasy_Starters'!O$2:'2026_Fantasy_Starters'!O$122)*100+100 -> 110.93397 | AC3: =('2026_Fantasy_Starters'!P4-AVERAGE('2026_Fantasy_Starters'!P$2:'2026_Fantasy_Starters'!P$122))/AVERAGE('2026_Fantasy_Starters'!P$2:'2026_Fantasy_Starters'!P$122)*100+100 -> 156.46539 | AD3: =(AVERAGE('2026_Fantasy_Starters'!Q$2:'2026_Fantasy_Starters'!Q$122)-'2026_Fantasy_Starters'!Q4)/AVERAGE('2026_Fantasy_Starters'!Q$2:'2026_Fantasy_Starters'!Q$122)*100+100 -> 99.722322 | AE3: =('2026_Fantasy_Starters'!R4-AVERAGE('2026_Fantasy_Starters'!R$2:'2026_Fantasy_Starters'!R$122))/AVERAGE('2026_Fantasy_Starters'!R$2:'2026_Fantasy_Starters'!R$122)*100+100 -> 124.24047 | AF3: =('2026_Fantasy_Starters'!T4-AVERAGE('2026_Fantasy_Starters'!T$2:'2026_Fantasy_Starters'!T$122))/AVERAGE('2026_Fantasy_Starters'!T$2:'2026_Fantasy_Starters'!T$122)*100+100 -> 152.01675 | AG3: =(AVERAGE('2026_Fantasy_Starters'!U$2:'2026_Fantasy_Starters'!U$122)-'2026_Fantasy_Starters'!U4)/AVERAGE('2026_Fantasy_Starters'!U$2:'2026_Fantasy_Starters'!U$122)*100+100 -> 126.51514 | AH3: =(AVERAGE('2026_Fantasy_Starters'!V$2:'2026_Fantasy_Starters'!V$122)-'2026_Fantasy_Starters'!V4)/AVERAGE('2026_Fantasy_Starters'!V$2:'2026_Fantasy_Starters'!V$122)*100+100 -> 113.72668
A4: Paul Skenes | B4: PIT | C4: SP | D4: 30 | E4: 187.33 | F4: =H4*1.5+I4+J4+K4*1.5+L4+M4+N4+O4+P4+Q4 -> 15.816479 | G4: 745 | H4: =(S4-S$123)/S$124 -> 1.3759112 | I4: =(T4-T$123)/T$124 -> 1.8703894 | J4: =(U4-U$123)/U$124 -> 0.012791875 | K4: =(V4-V$123)/V$124 -> 1.7777018 | L4: =(Z4-Z$123)/Z$124 -> 0.57711087 | M4: =(AB4-AB$123)/AB$124 -> -0.56747188 | N4: =(AG4-AG$123)/AG$124 -> 2.9688442 | O4: =(AH4-AH$123)/AH$124 -> 2.4653306 | P4: =(AE4-AE$123)/AE$124 -> 1.5536776 | Q4: =(AF4-AF$123)/AF$124 -> 2.2053868 | S4: =(E4-AVERAGE(E$2:E$122))/AVERAGE(E$2:E$122)*100+100 -> 129.78704 | T4: =('2026_Fantasy_Starters'!G3-AVERAGE('2026_Fantasy_Starters'!G$2:'2026_Fantasy_Starters'!G$122))/AVERAGE('2026_Fantasy_Starters'!G$2:'2026_Fantasy_Starters'!G$122)*100+100 -> 146.32991 | U4: =(AVERAGE('2026_Fantasy_Starters'!H$2:'2026_Fantasy_Starters'!H$122)-'2026_Fantasy_Starters'!H3)/AVERAGE('2026_Fantasy_Starters'!H$2:'2026_Fantasy_Starters'!H$122)*100+100 -> 100.29158 | V4: =('2026_Fantasy_Starters'!I3-AVERAGE('2026_Fantasy_Starters'!I$2:'2026_Fantasy_Starters'!I$122))/AVERAGE('2026_Fantasy_Starters'!I$2:'2026_Fantasy_Starters'!I$122)*100+100 -> 160.12156 | W4: =(AVERAGE('2026_Fantasy_Starters'!J$2:'2026_Fantasy_Starters'!J$122)-'2026_Fantasy_Starters'!J3)/AVERAGE('2026_Fantasy_Starters'!J$2:'2026_Fantasy_Starters'!J$122)*100+100 -> 87.975028 | X4: =(AVERAGE('2026_Fantasy_Starters'!K$2:'2026_Fantasy_Starters'!K$122)-'2026_Fantasy_Starters'!K3)/AVERAGE('2026_Fantasy_Starters'!K$2:'2026_Fantasy_Starters'!K$122)*100+100 -> 104.73675 | Y4: =(AVERAGE('2026_Fantasy_Starters'!L$2:'2026_Fantasy_Starters'!L$122)-'2026_Fantasy_Starters'!L3)/AVERAGE('2026_Fantasy_Starters'!L$2:'2026_Fantasy_Starters'!L$122)*100+100 -> 105.9776 | Z4: =(AVERAGE('2026_Fantasy_Starters'!M$2:'2026_Fantasy_Starters'!M$122)-'2026_Fantasy_Starters'!M3)/AVERAGE('2026_Fantasy_Starters'!M$2:'2026_Fantasy_Starters'!M$122)*100+100 -> 114.67398 | AA4: =(AVERAGE('2026_Fantasy_Starters'!N$2:'2026_Fantasy_Starters'!N$122)-'2026_Fantasy_Starters'!N3)/AVERAGE('2026_Fantasy_Starters'!N$2:'2026_Fantasy_Starters'!N$122)*100+100 -> 80.375776 | AB4: =(AVERAGE('2026_Fantasy_Starters'!O$2:'2026_Fantasy_Starters'!O$122)-'2026_Fantasy_Starters'!O3)/AVERAGE('2026_Fantasy_Starters'!O$2:'2026_Fantasy_Starters'!O$122)*100+100 -> 82.409039 | AC4: =('2026_Fantasy_Starters'!P3-AVERAGE('2026_Fantasy_Starters'!P$2:'2026_Fantasy_Starters'!P$122))/AVERAGE('2026_Fantasy_Starters'!P$2:'2026_Fantasy_Starters'!P$122)*100+100 -> 152.77022 | AD4: =(AVERAGE('2026_Fantasy_Starters'!Q$2:'2026_Fantasy_Starters'!Q$122)-'2026_Fantasy_Starters'!Q3)/AVERAGE('2026_Fantasy_Starters'!Q$2:'2026_Fantasy_Starters'!Q$122)*100+100 -> 98.202595 | AE4: =('2026_Fantasy_Starters'!R3-AVERAGE('2026_Fantasy_Starters'!R$2:'2026_Fantasy_Starters'!R$122))/AVERAGE('2026_Fantasy_Starters'!R$2:'2026_Fantasy_Starters'!R$122)*100+100 -> 117.64119 | AF4: =('2026_Fantasy_Starters'!T3-AVERAGE('2026_Fantasy_Starters'!T$2:'2026_Fantasy_Starters'!T$122))/AVERAGE('2026_Fantasy_Starters'!T$2:'2026_Fantasy_Starters'!T$122)*100+100 -> 143.34185 | AG4: =(AVERAGE('2026_Fantasy_Starters'!U$2:'2026_Fantasy_Starters'!U$122)-'2026_Fantasy_Starters'!U3)/AVERAGE('2026_Fantasy_Starters'!U$2:'2026_Fantasy_Starters'!U$122)*100+100 -> 127.87654 | AH4: =(AVERAGE('2026_Fantasy_Starters'!V$2:'2026_Fantasy_Starters'!V$122)-'2026_Fantasy_Starters'!V3)/AVERAGE('2026_Fantasy_Starters'!V$2:'2026_Fantasy_Starters'!V$122)*100+100 -> 115.97204
A5: Chris Sale | B5: ATL | C5: SP | D5: 25 | E5: 155.67 | F5: =H5*1.5+I5+J5+K5*1.5+L5+M5+N5+O5+P5+Q5 -> 10.083166 | G5: 631 | H5: =(S5-S$123)/S$124 -> 0.36270469 | I5: =(T5-T$123)/T$124 -> 0.8800167 | J5: =(U5-U$123)/U$124 -> 0.60253823 | K5: =(V5-V$123)/V$124 -> 0.82265086 | L5: =(Z5-Z$123)/Z$124 -> 0.30650423 | M5: =(AB5-AB$123)/AB$124 -> -1.3978727 | N5: =(AG5-AG$123)/AG$124 -> 2.1024605 | O5: =(AH5-AH$123)/AH$124 -> 1.6537292 | P5: =(AE5-AE$123)/AE$124 -> 1.9268294 | Q5: =(AF5-AF$123)/AF$124 -> 2.2309271 | S5: =(E5-AVERAGE(E$2:E$122))/AVERAGE(E$2:E$122)*100+100 -> 107.85218 | T5: =('2026_Fantasy_Starters'!G9-AVERAGE('2026_Fantasy_Starters'!G$2:'2026_Fantasy_Starters'!G$122))/AVERAGE('2026_Fantasy_Starters'!G$2:'2026_Fantasy_Starters'!G$122)*100+100 -> 121.79819 | U5: =(AVERAGE('2026_Fantasy_Starters'!H$2:'2026_Fantasy_Starters'!H$122)-'2026_Fantasy_Starters'!H9)/AVERAGE('2026_Fantasy_Starters'!H$2:'2026_Fantasy_Starters'!H$122)*100+100 -> 113.73418 | V5: =('2026_Fantasy_Starters'!I9-AVERAGE('2026_Fantasy_Starters'!I$2:'2026_Fantasy_Starters'!I$122))/AVERAGE('2026_Fantasy_Starters'!I$2:'2026_Fantasy_Starters'!I$122)*100+100 -> 127.8219 | W5: =(AVERAGE('2026_Fantasy_Starters'!J$2:'2026_Fantasy_Starters'!J$122)-'2026_Fantasy_Starters'!J9)/AVERAGE('2026_Fantasy_Starters'!J$2:'2026_Fantasy_Starters'!J$122)*100+100 -> 101.72178 | X5: =(AVERAGE('2026_Fantasy_Starters'!K$2:'2026_Fantasy_Starters'!K$122)-'2026_Fantasy_Starters'!K9)/AVERAGE('2026_Fantasy_Starters'!K$2:'2026_Fantasy_Starters'!K$122)*100+100 -> 113.42112 | Y5: =(AVERAGE('2026_Fantasy_Starters'!L$2:'2026_Fantasy_Starters'!L$122)-'2026_Fantasy_Starters'!L9)/AVERAGE('2026_Fantasy_Starters'!L$2:'2026_Fantasy_Starters'!L$122)*100+100 -> 113.0552 | Z5: =(AVERAGE('2026_Fantasy_Starters'!M$2:'2026_Fantasy_Starters'!M$122)-'2026_Fantasy_Starters'!M9)/AVERAGE('2026_Fantasy_Starters'!M$2:'2026_Fantasy_Starters'!M$122)*100+100 -> 107.79337 | AA5: =(AVERAGE('2026_Fantasy_Starters'!N$2:'2026_Fantasy_Starters'!N$122)-'2026_Fantasy_Starters'!N9)/AVERAGE('2026_Fantasy_Starters'!N$2:'2026_Fantasy_Starters'!N$122)*100+100 -> 82.096084 | AB5: =(AVERAGE('2026_Fantasy_Starters'!O$2:'2026_Fantasy_Starters'!O$122)-'2026_Fantasy_Starters'!O9)/AVERAGE('2026_Fantasy_Starters'!O$2:'2026_Fantasy_Starters'!O$122)*100+100 -> 56.667588 | AC5: =('2026_Fantasy_Starters'!P9-AVERAGE('2026_Fantasy_Starters'!P$2:'2026_Fantasy_Starters'!P$122))/AVERAGE('2026_Fantasy_Starters'!P$2:'2026_Fantasy_Starters'!P$122)*100+100 -> 131.5233 | AD5: =(AVERAGE('2026_Fantasy_Starters'!Q$2:'2026_Fantasy_Starters'!Q$122)-'2026_Fantasy_Starters'!Q9)/AVERAGE('2026_Fantasy_Starters'!Q$2:'2026_Fantasy_Starters'!Q$122)*100+100 -> 108.27845 | AE5: =('2026_Fantasy_Starters'!R9-AVERAGE('2026_Fantasy_Starters'!R$2:'2026_Fantasy_Starters'!R$122))/AVERAGE('2026_Fantasy_Starters'!R$2:'2026_Fantasy_Starters'!R$122)*100+100 -> 121.87813 | AF5: =('2026_Fantasy_Starters'!T9-AVERAGE('2026_Fantasy_Starters'!T$2:'2026_Fantasy_Starters'!T$122))/AVERAGE('2026_Fantasy_Starters'!T$2:'2026_Fantasy_Starters'!T$122)*100+100 -> 143.84379 | AG5: =(AVERAGE('2026_Fantasy_Starters'!U$2:'2026_Fantasy_Starters'!U$122)-'2026_Fantasy_Starters'!U9)/AVERAGE('2026_Fantasy_Starters'!U$2:'2026_Fantasy_Starters'!U$122)*100+100 -> 119.74146 | AH5: =(AVERAGE('2026_Fantasy_Starters'!V$2:'2026_Fantasy_Starters'!V$122)-'2026_Fantasy_Starters'!V9)/AVERAGE('2026_Fantasy_Starters'!V$2:'2026_Fantasy_Starters'!V$122)*100+100 -> 110.71395
A6: Logan Webb | B6: SF | C6: SP | D6: 30 | E6: 196.67 | F6: =H6*1.5+I6+J6+K6*1.5+L6+M6+N6+O6+P6+Q6 -> 9.9975935 | G6: 809 | H6: =(S6-S$123)/S$124 -> 1.6748167 | I6: =(T6-T$123)/T$124 -> 2.3033494 | J6: =(U6-U$123)/U$124 -> -0.69202694 | K6: =(V6-V$123)/V$124 -> 1.6982447 | L6: =(Z6-Z$123)/Z$124 -> 0.58551126 | M6: =(AB6-AB$123)/AB$124 -> -0.056874117 | N6: =(AG6-AG$123)/AG$124 -> 2.028113 | O6: =(AH6-AH$123)/AH$124 -> 0.65798304 | P6: =(AE6-AE$123)/AE$124 -> -0.32868676 | Q6: =(AF6-AF$123)/AF$124 -> 0.44063237 | S6: =(E6-AVERAGE(E$2:E$122))/AVERAGE(E$2:E$122)*100+100 -> 136.25803 | T6: =('2026_Fantasy_Starters'!G10-AVERAGE('2026_Fantasy_Starters'!G$2:'2026_Fantasy_Starters'!G$122))/AVERAGE('2026_Fantasy_Starters'!G$2:'2026_Fantasy_Starters'!G$122)*100+100 -> 157.05441 | U6: =(AVERAGE('2026_Fantasy_Starters'!H$2:'2026_Fantasy_Starters'!H$122)-'2026_Fantasy_Starters'!H10)/AVERAGE('2026_Fantasy_Starters'!H$2:'2026_Fantasy_Starters'!H$122)*100+100 -> 84.226025 | V6: =('2026_Fantasy_Starters'!I10-AVERAGE('2026_Fantasy_Starters'!I$2:'2026_Fantasy_Starters'!I$122))/AVERAGE('2026_Fantasy_Starters'!I$2:'2026_Fantasy_Starters'!I$122)*100+100 -> 157.43433 | W6: =(AVERAGE('2026_Fantasy_Starters'!J$2:'2026_Fantasy_Starters'!J$122)-'2026_Fantasy_Starters'!J10)/AVERAGE('2026_Fantasy_Starters'!J$2:'2026_Fantasy_Starters'!J$122)*100+100 -> 58.708579 | X6: =(AVERAGE('2026_Fantasy_Starters'!K$2:'2026_Fantasy_Starters'!K$122)-'2026_Fantasy_Starters'!K10)/AVERAGE('2026_Fantasy_Starters'!K$2:'2026_Fantasy_Starters'!K$122)*100+100 -> 83.346369 | Y6: =(AVERAGE('2026_Fantasy_Starters'!L$2:'2026_Fantasy_Starters'!L$122)-'2026_Fantasy_Starters'!L10)/AVERAGE('2026_Fantasy_Starters'!L$2:'2026_Fantasy_Starters'!L$122)*100+100 -> 89.200445 | Z6: =(AVERAGE('2026_Fantasy_Starters'!M$2:'2026_Fantasy_Starters'!M$122)-'2026_Fantasy_Starters'!M10)/AVERAGE('2026_Fantasy_Starters'!M$2:'2026_Fantasy_Starters'!M$122)*100+100 -> 114.88758 | AA6: =(AVERAGE('2026_Fantasy_Starters'!N$2:'2026_Fantasy_Starters'!N$122)-'2026_Fantasy_Starters'!N10)/AVERAGE('2026_Fantasy_Starters'!N$2:'2026_Fantasy_Starters'!N$122)*100+100 -> 78.798078 | AB6: =(AVERAGE('2026_Fantasy_Starters'!O$2:'2026_Fantasy_Starters'!O$122)-'2026_Fantasy_Starters'!O10)/AVERAGE('2026_Fantasy_Starters'!O$2:'2026_Fantasy_Starters'!O$122)*100+100 -> 98.236969 | AC6: =('2026_Fantasy_Starters'!P10-AVERAGE('2026_Fantasy_Starters'!P$2:'2026_Fantasy_Starters'!P$122))/AVERAGE('2026_Fantasy_Starters'!P$2:'2026_Fantasy_Starters'!P$122)*100+100 -> 131.24771 | AD6: =(AVERAGE('2026_Fantasy_Starters'!Q$2:'2026_Fantasy_Starters'!Q$122)-'2026_Fantasy_Starters'!Q10)/AVERAGE('2026_Fantasy_Starters'!Q$2:'2026_Fantasy_Starters'!Q$122)*100+100 -> 99.174306 | AE6: =('2026_Fantasy_Starters'!R10-AVERAGE('2026_Fantasy_Starters'!R$2:'2026_Fantasy_Starters'!R$122))/AVERAGE('2026_Fantasy_Starters'!R$2:'2026_Fantasy_Starters'!R$122)*100+100 -> 96.267935 | AF6: =('2026_Fantasy_Starters'!T10-AVERAGE('2026_Fantasy_Starters'!T$2:'2026_Fantasy_Starters'!T$122))/AVERAGE('2026_Fantasy_Starters'!T$2:'2026_Fantasy_Starters'!T$122)*100+100 -> 108.65963 | AG6: =(AVERAGE('2026_Fantasy_Starters'!U$2:'2026_Fantasy_Starters'!U$122)-'2026_Fantasy_Starters'!U10)/AVERAGE('2026_Fantasy_Starters'!U$2:'2026_Fantasy_Starters'!U$122)*100+100 -> 119.04336 | AH6: =(AVERAGE('2026_Fantasy_Starters'!V$2:'2026_Fantasy_Starters'!V$122)-'2026_Fantasy_Starters'!V10)/AVERAGE('2026_Fantasy_Starters'!V$2:'2026_Fantasy_Starters'!V$122)*100+100 -> 104.26285
A7: 2 Cristopher Sanchez | B7: PHI | C7: SP | D7: 30 | E7: 190.33 | F7: =H7*1.5+I7+J7+K7*1.5+L7+M7+N7+O7+P7+Q7 -> 9.8922547 | G7: 777 | H7: =(S7-S$123)/S$124 -> 1.4719194 | I7: =(T7-T$123)/T$124 -> 1.7310459 | J7: =(U7-U$123)/U$124 -> 0.012791875 | K7: =(V7-V$123)/V$124 -> 1.7393432 | L7: =(Z7-Z$123)/Z$124 -> 0.47608204 | M7: =(AB7-AB$123)/AB$124 -> -0.21316667 | N7: =(AG7-AG$123)/AG$124 -> 1.7792821 | O7: =(AH7-AH$123)/AH$124 -> 0.94995319 | P7: =(AE7-AE$123)/AE$124 -> -0.17788244 | Q7: =(AF7-AF$123)/AF$124 -> 0.51725476 | S7: =(E7-AVERAGE(E$2:E$122))/AVERAGE(E$2:E$122)*100+100 -> 131.86552 | T7: =('2026_Fantasy_Starters'!G6-AVERAGE('2026_Fantasy_Starters'!G$2:'2026_Fantasy_Starters'!G$122))/AVERAGE('2026_Fantasy_Starters'!G$2:'2026_Fantasy_Starters'!G$122)*100+100 -> 142.87834 | U7: =(AVERAGE('2026_Fantasy_Starters'!H$2:'2026_Fantasy_Starters'!H$122)-'2026_Fantasy_Starters'!H6)/AVERAGE('2026_Fantasy_Starters'!H$2:'2026_Fantasy_Starters'!H$122)*100+100 -> 100.29158 | V7: =('2026_Fantasy_Starters'!I6-AVERAGE('2026_Fantasy_Starters'!I$2:'2026_Fantasy_Starters'!I$122))/AVERAGE('2026_Fantasy_Starters'!I$2:'2026_Fantasy_Starters'!I$122)*100+100 -> 158.82428 | W7: =(AVERAGE('2026_Fantasy_Starters'!J$2:'2026_Fantasy_Starters'!J$122)-'2026_Fantasy_Starters'!J6)/AVERAGE('2026_Fantasy_Starters'!J$2:'2026_Fantasy_Starters'!J$122)*100+100 -> 68.437025 | X7: =(AVERAGE('2026_Fantasy_Starters'!K$2:'2026_Fantasy_Starters'!K$122)-'2026_Fantasy_Starters'!K6)/AVERAGE('2026_Fantasy_Starters'!K$2:'2026_Fantasy_Starters'!K$122)*100+100 -> 90.831319 | Y7: =(AVERAGE('2026_Fantasy_Starters'!L$2:'2026_Fantasy_Starters'!L$122)-'2026_Fantasy_Starters'!L6)/AVERAGE('2026_Fantasy_Starters'!L$2:'2026_Fantasy_Starters'!L$122)*100+100 -> 89.67762 | Z7: =(AVERAGE('2026_Fantasy_Starters'!M$2:'2026_Fantasy_Starters'!M$122)-'2026_Fantasy_Starters'!M6)/AVERAGE('2026_Fantasy_Starters'!M$2:'2026_Fantasy_Starters'!M$122)*100+100 -> 112.10516 | AA7: =(AVERAGE('2026_Fantasy_Starters'!N$2:'2026_Fantasy_Starters'!N$122)-'2026_Fantasy_Starters'!N6)/AVERAGE('2026_Fantasy_Starters'!N$2:'2026_Fantasy_Starters'!N$122)*100+100 -> 77.172257 | AB7: =(AVERAGE('2026_Fantasy_Starters'!O$2:'2026_Fantasy_Starters'!O$122)-'2026_Fantasy_Starters'!O6)/AVERAGE('2026_Fantasy_Starters'!O$2:'2026_Fantasy_Starters'!O$122)*100+100 -> 93.392084 | AC7: =('2026_Fantasy_Starters'!P6-AVERAGE('2026_Fantasy_Starters'!P$2:'2026_Fantasy_Starters'!P$122))/AVERAGE('2026_Fantasy_Starters'!P$2:'2026_Fantasy_Starters'!P$122)*100+100 -> 129.27594 | AD7: =(AVERAGE('2026_Fantasy_Starters'!Q$2:'2026_Fantasy_Starters'!Q$122)-'2026_Fantasy_Starters'!Q6)/AVERAGE('2026_Fantasy_Starters'!Q$2:'2026_Fantasy_Starters'!Q$122)*100+100 -> 97.253977 | AE7: =('2026_Fantasy_Starters'!R6-AVERAGE('2026_Fantasy_Starters'!R$2:'2026_Fantasy_Starters'!R$122))/AVERAGE('2026_Fantasy_Starters'!R$2:'2026_Fantasy_Starters'!R$122)*100+100 -> 97.980239 | AF7: =('2026_Fantasy_Starters'!T6-AVERAGE('2026_Fantasy_Starters'!T$2:'2026_Fantasy_Starters'!T$122))/AVERAGE('2026_Fantasy_Starters'!T$2:'2026_Fantasy_Starters'!T$122)*100+100 -> 110.16546 | AG7: =(AVERAGE('2026_Fantasy_Starters'!U$2:'2026_Fantasy_Starters'!U$122)-'2026_Fantasy_Starters'!U6)/AVERAGE('2026_Fantasy_Starters'!U$2:'2026_Fantasy_Starters'!U$122)*100+100 -> 116.70692 | AH7: =(AVERAGE('2026_Fantasy_Starters'!V$2:'2026_Fantasy_Starters'!V$122)-'2026_Fantasy_Starters'!V6)/AVERAGE('2026_Fantasy_Starters'!V$2:'2026_Fantasy_Starters'!V$122)*100+100 -> 106.15442
A8: Yoshinobu Yamamoto | B8: LAD | C8: SP | D8: 26 | E8: 160.67 | F8: =H8*1.5+I8+J8+K8*1.5+L8+M8+N8+O8+P8+Q8 -> 9.6249837 | G8: 652 | H8: =(S8-S$123)/S$124 -> 0.52271836 | I8: =(T8-T$123)/T$124 -> 1.5157745 | J8: =(U8-U$123)/U$124 -> 0.80711149 | K8: =(V8-V$123)/V$124 -> 0.76941851 | L8: =(Z8-Z$123)/Z$124 -> 0.50774621 | M8: =(AB8-AB$123)/AB$124 -> 0.45426319 | N8: =(AG8-AG$123)/AG$124 -> 1.3119177 | O8: =(AH8-AH$123)/AH$124 -> 1.1168586 | P8: =(AE8-AE$123)/AE$124 -> 0.8907404 | Q8: =(AF8-AF$123)/AF$124 -> 1.0823664 | S8: =(E8-AVERAGE(E$2:E$122))/AVERAGE(E$2:E$122)*100+100 -> 111.31631 | T8: =('2026_Fantasy_Starters'!G5-AVERAGE('2026_Fantasy_Starters'!G$2:'2026_Fantasy_Starters'!G$122))/AVERAGE('2026_Fantasy_Starters'!G$2:'2026_Fantasy_Starters'!G$122)*100+100 -> 137.54603 | U8: =(AVERAGE('2026_Fantasy_Starters'!H$2:'2026_Fantasy_Starters'!H$122)-'2026_Fantasy_Starters'!H5)/AVERAGE('2026_Fantasy_Starters'!H$2:'2026_Fantasy_Starters'!H$122)*100+100 -> 118.3972 | V8: =('2026_Fantasy_Starters'!I5-AVERAGE('2026_Fantasy_Starters'!I$2:'2026_Fantasy_Starters'!I$122))/AVERAGE('2026_Fantasy_Starters'!I$2:'2026_Fantasy_Starters'!I$122)*100+100 -> 126.0216 | W8: =(AVERAGE('2026_Fantasy_Starters'!J$2:'2026_Fantasy_Starters'!J$122)-'2026_Fantasy_Starters'!J5)/AVERAGE('2026_Fantasy_Starters'!J$2:'2026_Fantasy_Starters'!J$122)*100+100 -> 96.901016 | X8: =(AVERAGE('2026_Fantasy_Starters'!K$2:'2026_Fantasy_Starters'!K$122)-'2026_Fantasy_Starters'!K5)/AVERAGE('2026_Fantasy_Starters'!K$2:'2026_Fantasy_Starters'!K$122)*100+100 -> 103.01651 | Y8: =(AVERAGE('2026_Fantasy_Starters'!L$2:'2026_Fantasy_Starters'!L$122)-'2026_Fantasy_Starters'!L5)/AVERAGE('2026_Fantasy_Starters'!L$2:'2026_Fantasy_Starters'!L$122)*100+100 -> 101.96297 | Z8: =(AVERAGE('2026_Fantasy_Starters'!M$2:'2026_Fantasy_Starters'!M$122)-'2026_Fantasy_Starters'!M5)/AVERAGE('2026_Fantasy_Starters'!M$2:'2026_Fantasy_Starters'!M$122)*100+100 -> 112.91027 | AA8: =(AVERAGE('2026_Fantasy_Starters'!N$2:'2026_Fantasy_Starters'!N$122)-'2026_Fantasy_Starters'!N5)/AVERAGE('2026_Fantasy_Starters'!N$2:'2026_Fantasy_Starters'!N$122)*100+100 -> 138.58613 | AB8: =(AVERAGE('2026_Fantasy_Starters'!O$2:'2026_Fantasy_Starters'!O$122)-'2026_Fantasy_Starters'!O5)/AVERAGE('2026_Fantasy_Starters'!O$2:'2026_Fantasy_Starters'!O$122)*100+100 -> 114.08162 | AC8: =('2026_Fantasy_Starters'!P5-AVERAGE('2026_Fantasy_Starters'!P$2:'2026_Fantasy_Starters'!P$122))/AVERAGE('2026_Fantasy_Starters'!P$2:'2026_Fantasy_Starters'!P$122)*100+100 -> 122.64472 | AD8: =(AVERAGE('2026_Fantasy_Starters'!Q$2:'2026_Fantasy_Starters'!Q$122)-'2026_Fantasy_Starters'!Q5)/AVERAGE('2026_Fantasy_Starters'!Q$2:'2026_Fantasy_Starters'!Q$122)*100+100 -> 95.076457 | AE8: =('2026_Fantasy_Starters'!R5-AVERAGE('2026_Fantasy_Starters'!R$2:'2026_Fantasy_Starters'!R$122))/AVERAGE('2026_Fantasy_Starters'!R$2:'2026_Fantasy_Starters'!R$122)*100+100 -> 110.11389 | AF8: =('2026_Fantasy_Starters'!T5-AVERAGE('2026_Fantasy_Starters'!T$2:'2026_Fantasy_Starters'!T$122))/AVERAGE('2026_Fantasy_Starters'!T$2:'2026_Fantasy_Starters'!T$122)*100+100 -> 121.27145 | AG8: =(AVERAGE('2026_Fantasy_Starters'!U$2:'2026_Fantasy_Starters'!U$122)-'2026_Fantasy_Starters'!U5)/AVERAGE('2026_Fantasy_Starters'!U$2:'2026_Fantasy_Starters'!U$122)*100+100 -> 112.31851 | AH8: =(AVERAGE('2026_Fantasy_Starters'!V$2:'2026_Fantasy_Starters'!V$122)-'2026_Fantasy_Starters'!V5)/AVERAGE('2026_Fantasy_Starters'!V$2:'2026_Fantasy_Starters'!V$122)*100+100 -> 107.23575
